Workbook

Sheet Resumen de tablas
A1: PULSO | Costos y rentabilidad: compare planes y revise el resultado del escenario de 12 meses.
A3: 1. Costo mensual por gimnasio y equilibrio de cada plan
A4: Plan | B4: Mensualidad CRC | C4: Variable base CRC | D4: Contribución CRC | E4: Gimnasios mínimos | F4: Costo total al mínimo CRC | G4: Resultado al mínimo CRC
A5: ='Estructura de Precios'!A9 -> Starter | B5: ='Estructura de Precios'!B9 -> 15000 | C5: ='Estructura de Precios'!C9 -> 1216.2295 | D5: =B5-C5 -> 13783.77 | E5: ='Estructura de Precios'!E9 -> 9 | F5: ='Estructura de Precios'!E40 -> 125193.61 | G5: ='Estructura de Precios'!E17 -> 9806.3896
A6: ='Estructura de Precios'!A10 -> Pro Gym | B6: ='Estructura de Precios'!B10 -> 25000 | C6: ='Estructura de Precios'!C10 -> 1485.4895 | D6: =B6-C6 -> 23514.51 | E6: ='Estructura de Precios'!E10 -> 5 | F6: ='Estructura de Precios'!E41 -> 121674.99 | G6: ='Estructura de Precios'!E18 -> 3325.0077
A7: ='Estructura de Precios'!A11 -> Premium | B7: ='Estructura de Precios'!B11 -> 45000 | C7: ='Estructura de Precios'!C11 -> 13193.719 | D7: =B7-C7 -> 31806.281 | E7: ='Estructura de Precios'!E11 -> 4 | F7: ='Estructura de Precios'!E42 -> 177022.42 | G7: ='Estructura de Precios'!E19 -> 2977.5792
A8: ='Estructura de Precios'!A12 -> Enterprise | B8: ='Estructura de Precios'!B12 -> 70000 | C8: ='Estructura de Precios'!C12 -> 18885.798 | D8: =B8-C8 -> 51114.202 | E8: ='Estructura de Precios'!E12 -> 3 | F8: ='Estructura de Precios'!E43 -> 180904.94 | G8: ='Estructura de Precios'!E20 -> 29095.061
A9: Variable base: correo, IA, cobros, soporte y recursos dedicados. Contribución = mensualidad − variable base; todavía debe cubrir los costos comunes y excedentes de nube. | J9: 0
A10: Cada mínimo supone vender solo ese plan: cubre el fijo común completo y sus excedentes de nube. Los mínimos no se suman. No incluyen la inversión inicial ni prueban capacidad técnica.
A11: El costo total al mínimo corresponde a todos los gimnasios de ese plan: variables + fijo común + excedentes de nube. No es un costo unitario.
A12: 2. Resultado anual del escenario de cartera
A13: Indicador | B13: Valor
A14: Suscripciones e instalaciones cobradas | B14: ='PPTO Vtas Servicios'!O24 -> 2780000
A15: Variables de servicio | B15: =SUM('PPTO Vtas Servicios'!O29:O32) -> 169085.66
A16: Comunes anuales + campaña inicial | B16: =Costeo!B29 -> 1448654.4
A17: Excedentes y escalamiento de nube | B17: =SUM(Costeo!D138:D149) -> 102500
A18: Costo de instalaciones | B18: =SUM('PPTO Vtas Servicios'!O33:O34)+'PPTO Vtas Servicios'!O36 -> 264980.36
A19: Desarrollo inicial | B19: =Costeo!E90 -> 198735.27
A20: Costo anual total | B20: =SUM(B15:B19) -> 2183955.6
A21: Resultado anual | B21: =B14-B20 -> 596044.36
A22: Margen anual | B22: =IFERROR(B21/B14,0) -> 0.21440445
A23: Liquidez inicial mínima | B23: =MAX(40000,SUM('PPTO Vtas Servicios'!C37:C37)-SUM('PPTO Vtas Servicios'!C24:C24)-((16*1+24+SUM('PPTO Vtas Servicios'!C7:C7)*Costeo!$B$43+SUM('PPTO Vtas Servicios'!C8:C8)*Costeo!$C$43+SUM('PPTO Vtas Servicios'!C9:C9)*Costeo!$D$43+SUM('PPTO Vtas Servicios'!C10:C10)*Costeo!$E$43)*Costeo!$B$50+SUM('PPTO Vtas Servicios'!C33:C34)+SUM('PPTO Vtas Servicios'!C36:C36)+Costeo!$E$90),SUM('PPTO Vtas Servicios'!C37:D37)-SUM('PPTO Vtas Servicios'!C24:D24)-((16*2+24+SUM('PPTO Vtas Servicios'!C7:D7)*Costeo!$B$43+SUM('PPTO Vtas Servicios'!C8:D8)*Costeo!$C$43+SUM('PPTO Vtas Servicios'!C9:D9)*Costeo!$D$43+SUM('PPTO Vtas Servicios'!C10:D10)*Costeo!$E$43)*Costeo!$B$50+SUM('PPTO Vtas Servicios'!C33:D34)+SUM('PPTO Vtas Servicios'!C36:D36)+Costeo!$E$90),SUM('PPTO Vtas Servicios'!C37:E37)-SUM('PPTO Vtas Servicios'!C24:E24)-((16*3+24+SUM('PPTO Vtas Servicios'!C7:E7)*Costeo!$B$43+SUM('PPTO Vtas Servicios'!C8:E8)*Costeo!$C$43+SUM('PPTO Vtas Servicios'!C9:E9)*Costeo!$D$43+SUM('PPTO Vtas Servicios'!C10:E10)*Costeo!$E$43)*Costeo!$B$50+SUM('PPTO Vtas Servicios'!C33:E34)+SUM('PPTO Vtas Servicios'!C36:E36)+Costeo!$E$90),SUM('PPTO Vtas Servicios'!C37:F37)-SUM('PPTO Vtas Servicios'!C24:F24)-((16*4+24+SUM('PPTO Vtas Servicios'!C7:F7)*Costeo!$B$43+SUM('PPTO Vtas Servicios'!C8:F8)*Costeo!$C$43+SUM('PPTO Vtas Servicios'!C9:F9)*Costeo!$D$43+SUM('PPTO Vtas Servicios'!C10:F10)*Costeo!$E$43)*Costeo!$B$50+SUM('PPTO Vtas Servicios'!C33:F34)+SUM('PPTO Vtas Servicios'!C36:F36)+Costeo!$E$90),SUM('PPTO Vtas Servicios'!C37:G37)-SUM('PPTO Vtas Servicios'!C24:G24)-((16*5+24+SUM('PPTO Vtas Servicios'!C7:G7)*Costeo!$B$43+SUM('PPTO Vtas Servicios'!C8:G8)*Costeo!$C$43+SUM('PPTO Vtas Servicios'!C9:G9)*Costeo!$D$43+SUM('PPTO Vtas Servicios'!C10:G10)*Costeo!$E$43)*Costeo!$B$50+SUM('PPTO Vtas Servicios'!C33:G34)+SUM('PPTO Vtas Servicios'!C36:G36)+Costeo!$E$90),SUM('PPTO Vtas Servicios'!C37:H37)-SUM('PPTO Vtas Servicios'!C24:H24)-((16*6+24+SUM('PPTO Vtas Servicios'!C7:H7)*Costeo!$B$43+SUM('PPTO Vtas Servicios'!C8:H8)*Costeo!$C$43+SUM('PPTO Vtas Servicios'!C9:H9)*Costeo!$D$43+SUM('PPTO Vtas Servicios'!C10:H10)*Costeo!$E$43)*Costeo!$B$50+SUM('PPTO Vtas Servicios'!C33:H34)+SUM('PPTO Vtas Servicios'!C36:H36)+Costeo!$E$90),SUM('PPTO Vtas Servicios'!C37:I37)-SUM('PPTO Vtas Servicios'!C24:I24)-((16*7+24+SUM('PPTO Vtas Servicios'!C7:I7)*Costeo!$B$43+SUM('PPTO Vtas Servicios'!C8:I8)*Costeo!$C$43+SUM('PPTO Vtas Servicios'!C9:I9)*Costeo!$D$43+SUM('PPTO Vtas Servicios'!C10:I10)*Costeo!$E$43)*Costeo!$B$50+SUM('PPTO Vtas Servicios'!C33:I34)+SUM('PPTO Vtas Servicios'!C36:I36)+Costeo!$E$90),SUM('PPTO Vtas Servicios'!C37:J37)-SUM('PPTO Vtas Servicios'!C24:J24)-((16*8+24+SUM('PPTO Vtas Servicios'!C7:J7)*Costeo!$B$43+SUM('PPTO Vtas Servicios'!C8:J8)*Costeo!$C$43+SUM('PPTO Vtas Servicios'!C9:J9)*Costeo!$D$43+SUM('PPTO Vtas Servicios'!C10:J10)*Costeo!$E$43)*Costeo!$B$50+SUM('PPTO Vtas Servicios'!C33:J34)+SUM('PPTO Vtas Servicios'!C36:J36)+Costeo!$E$90),SUM('PPTO Vtas Servicios'!C37:K37)-SUM('PPTO Vtas Servicios'!C24:K24)-((16*9+24+SUM('PPTO Vtas Servicios'!C7:K7)*Costeo!$B$43+SUM('PPTO Vtas Servicios'!C8:K8)*Costeo!$C$43+SUM('PPTO Vtas Servicios'!C9:K9)*Costeo!$D$43+SUM('PPTO Vtas Servicios'!C10:K10)*Costeo!$E$43)*Costeo!$B$50+SUM('PPTO Vtas Servicios'!C33:K34)+SUM('PPTO Vtas Servicios'!C36:K36)+Costeo!$E$90),SUM('PPTO Vtas Servicios'!C37:L37)-SUM('PPTO Vtas Servicios'!C24:L24)-((16*10+24+SUM('PPTO Vtas Servicios'!C7:L7)*Costeo!$B$43+SUM('PPTO Vtas Servicios'!C8:L8)*Costeo!$C$43+SUM('PPTO Vtas Servicios'!C9:L9)*Costeo!$D$43+SUM('PPTO Vtas Servicios'!C10:L10)*Costeo!$E$43)*Costeo!$B$50+SUM('PPTO Vtas Servicios'!C33:L34)+SUM('PPTO Vtas Servicios'!C36:L36)+Costeo!$E$90),SUM('PPTO Vtas Servicios'!C37:M37)-SUM('PPTO Vtas Servicios'!C24:M24)-((16*11+24+SUM('PPTO Vtas Servicios'!C7:M7)*Costeo!$B$43+SUM('PPTO Vtas Servicios'!C8:M8)*Costeo!$C$43+SUM('PPTO Vtas Servicios'!C9:M9)*Costeo!$D$43+SUM('PPTO Vtas Servicios'!C10:M10)*Costeo!$E$43)*Costeo!$B$50+SUM('PPTO Vtas Servicios'!C33:M34)+SUM('PPTO Vtas Servicios'!C36:M36)+Costeo!$E$90),SUM('PPTO Vtas Servicios'!C37:N37)-SUM('PPTO Vtas Servicios'!C24:N24)-((16*12+24+SUM('PPTO Vtas Servicios'!C7:N7)*Costeo!$B$43+SUM('PPTO Vtas Servicios'!C8:N8)*Costeo!$C$43+SUM('PPTO Vtas Servicios'!C9:N9)*Costeo!$D$43+SUM('PPTO Vtas Servicios'!C10:N10)*Costeo!$E$43)*Costeo!$B$50+SUM('PPTO Vtas Servicios'!C33:N34)+SUM('PPTO Vtas Servicios'!C36:N36)+Costeo!$E$90)) -> 40000
A24: Mes de recuperación acumulada | B24: ='Estructura de Precios'!B32 -> 8
A25: Trabajo propio sin pago: incluido en costo económico, excluido de caja. Liquidez mínima: ₡40 000 de viáticos antes de cobrar, o déficit mensual si es mayor. Renta 0 condicionada a formalización MYPE.
A27: 3. Instalación: costo interno, cobro y recuperación
A28: Servicio | B28: Costo interno CRC | C28: Cobro inicial CRC | D28: Absorbe Pulso CRC | E28: Aporte inicial CRC
A29: Básica · Starter / Pro | B29: =Costeo!B22 -> 16561.272 | C29: =Costeo!B23 -> 0 | D29: =MAX(0,B29-C29) -> 16561.272 | E29: =C29-B29 -> -16561.272
A30: Premium | B30: =Costeo!D22 -> 37262.863 | C30: =Costeo!D23 -> 129000 | D30: =MAX(0,B30-C30) -> 0 | E30: =C30-B30 -> 91737.137
A31: Enterprise | B31: =Costeo!E22 -> 74525.726 | C31: =Costeo!E23 -> 258000 | D31: =MAX(0,B31-C31) -> 0 | E31: =C31-B31 -> 183474.27
A32: Instalación básica absorbida como trabajo propio. Premium y Enterprise se cobran a ₡129 000 / ₡258 000; costos y márgenes recalculados con referencia MTSS.
A34: 4. Seguimiento mensual: ingresos, costos y recuperación
A35: Mes | B35: Gimnasios activos | C35: Ingresos CRC | D35: Costos totales CRC | E35: Resultado CRC | F35: Acumulado CRC | G35: Margen
A36: 1 | B36: =SUM('PPTO Vtas Servicios'!C7:C10) -> 5 | C36: ='PPTO Vtas Servicios'!C24 -> 115000 | D36: ='PPTO Vtas Servicios'!C37 -> 480631.18 | E36: =C36-D36 -> -365631.18 | F36: =SUM($E$36:E36) -> -365631.18 | G36: =IFERROR(E36/C36,0) -> -3.1794016
A37: 2 | B37: =SUM('PPTO Vtas Servicios'!D7:D10) -> 6 | C37: ='PPTO Vtas Servicios'!D24 -> 140000 | D37: ='PPTO Vtas Servicios'!D37 -> 139452.49 | E37: =C37-D37 -> 547.50588 | F37: =SUM($E$36:E37) -> -365083.67 | G37: =IFERROR(E37/C37,0) -> 0.0039107563
A38: 3 | B38: =SUM('PPTO Vtas Servicios'!E7:E10) -> 7 | C38: ='PPTO Vtas Servicios'!E24 -> 165000 | D38: ='PPTO Vtas Servicios'!E37 -> 140937.98 | E38: =C38-D38 -> 24062.016 | F38: =SUM($E$36:E38) -> -341021.66 | G38: =IFERROR(E38/C38,0) -> 0.1458304
A39: 4 | B39: =SUM('PPTO Vtas Servicios'!F7:F10) -> 8 | C39: ='PPTO Vtas Servicios'!F24 -> 190000 | D39: ='PPTO Vtas Servicios'!F37 -> 152423.47 | E39: =C39-D39 -> 37576.527 | F39: =SUM($E$36:E39) -> -303445.13 | G39: =IFERROR(E39/C39,0) -> 0.19777119
A40: 5 | B40: =SUM('PPTO Vtas Servicios'!G7:G10) -> 9 | C40: ='PPTO Vtas Servicios'!G24 -> 215000 | D40: ='PPTO Vtas Servicios'!G37 -> 153908.96 | E40: =C40-D40 -> 61091.037 | F40: =SUM($E$36:E40) -> -242354.09 | G40: =IFERROR(E40/C40,0) -> 0.28414436
A41: 6 | B41: =SUM('PPTO Vtas Servicios'!H7:H10) -> 9 | C41: ='PPTO Vtas Servicios'!H24 -> 215000 | D41: ='PPTO Vtas Servicios'!H37 -> 153908.96 | E41: =C41-D41 -> 61091.037 | F41: =SUM($E$36:E41) -> -181263.06 | G41: =IFERROR(E41/C41,0) -> 0.28414436
A42: 7 | B42: =SUM('PPTO Vtas Servicios'!I7:I10) -> 10 | C42: ='PPTO Vtas Servicios'!I24 -> 240000 | D42: ='PPTO Vtas Servicios'!I37 -> 155394.45 | E42: =C42-D42 -> 84605.548 | F42: =SUM($E$36:E42) -> -96657.507 | G42: =IFERROR(E42/C42,0) -> 0.35252312
A43: 8 | B43: =SUM('PPTO Vtas Servicios'!J7:J10) -> 11 | C43: ='PPTO Vtas Servicios'!J24 -> 265000 | D43: ='PPTO Vtas Servicios'!J37 -> 159379.94 | E43: =C43-D43 -> 105620.06 | F43: =SUM($E$36:E43) -> 8962.5508 | G43: =IFERROR(E43/C43,0) -> 0.39856626
...

Sheet Gráficas
A1: PULSO | Lectura visual: costo por plan, equilibrio y recuperación del escenario.
A3: Mensualidad vs. variable base: la diferencia debe cubrir el gasto común.
A25: Equilibrio operativo: cada plan cubre el fijo completo. No incluye instalación ni desarrollo inicial.
A49: Acumulado negativo = inversión aún no recuperada. Incluye instalación absorbida y desarrollo inicial.
A51: Consulte Resumen de tablas para cifras exactas. Todos los gráficos se vinculan a sus fórmulas.

Sheet PPTO Vtas Productos
A1: CATÁLOGO · Costos internos a referencia MTSS y precios comerciales conservados. Las instalaciones avanzadas muestran margen efectivo; no son cotizaciones nuevas.
A2: PULSO
A3: Precios editables en C; las otras hojas los referencian. Costos internos ≠ precios de venta.
A4: Concepto | B4: Costo interno CRC | C4: Precio de venta CRC | D4: Aplicación
A5: Starter mensual | B5: =Costeo!B12 -> 1216.2295 | C5: 15000 | D5: 80 miembros, 1 sede; base compartida.
A6: Pro Gym mensual | B6: =Costeo!C12 -> 1485.4895 | C6: 25000 | D6: 200 miembros, 1 sede; compartida; marca y subdominio.
A7: Premium mensual dedicado | B7: =Costeo!D12 -> 13193.719 | C7: 45000 | D7: 500 miembros, 1 sede; Micro dedicado y API propia.
A8: Enterprise mensual · 2 sedes | B8: =Costeo!E12 -> 18885.798 | C8: 70000 | D8: 1 000 miembros, 2 sedes; Small dedicado y 2h soporte.
A9: Instalación básica | B9: =Costeo!B22 -> 16561.272 | C9: 0 | D9: Única; la asume Pulso
A10: Instalación premium | B10: =Costeo!D22 -> 37262.863 | C10: 129000 | D10: 18 h; precio comercial conservado; margen efectivo actualizado.
A11: Operación fija plataforma | B11: =Costeo!B28 -> 114247.54 | C11: No se vende | D11: Fijos comunes; presupuesto agrega desarrollo en mes 1.
A12: Instalación Enterprise · 2 sedes | B12: =Costeo!E22 -> 74525.726 | C12: 258000 | D12: 36 h; incluye segunda sede; precio comercial conservado.

Sheet Costeo
A1: COSTEO · Compara costos y precios por plan. Proyección anual con proveedores Pro, alcance definido y tarifas públicas; los volúmenes son estimaciones de diseño.
A2: CRC antes de impuestos. No se usan reservas genéricas: cada importe deriva de alcance, tarifa, horas o consumo proyectado.
A3: 1 · COSTO VARIABLE Y PRECIO | por gimnasio / mes
A4: Concepto | B4: Starter | C4: Pro Gym | D4: Premium dedicado | E4: Enterprise · 2 sedes
A5: Excedentes de nube asignados | B5: =IF($E$138>0,$D$138*B36/$E$138,0) -> 0 | C5: =IF($E$138>0,$D$138*C36/$E$138,0) -> 0 | D5: =IF($E$138>0,$D$138*D36/$E$138,0) -> 0 | E5: =IF($E$138>0,$D$138*E36/$E$138,0) -> 0
A6: Correos transaccionales | B6: =B125 -> 14.75 | C6: =C125 -> 34.41 | D6: =D125 -> 83.56 | E6: =E125 -> 165.48
A7: Chat IA y comisión de cobro | B7: =B127+B128 -> 166.4 | C7: =C127+C128 -> 416 | D7: =D127+D128 -> 1040 | E7: =E127+E128 -> 2080
A8: Proyecto dedicado Supabase | B8: =B44*$B$51 -> 0 | C8: =C44*$B$51 -> 0 | D8: =D44*$B$51 -> 5000 | E8: =E44*$B$51 -> 7500
A9: Dominio API dedicado | B9: =B45*$B$70*$B$51 -> 0 | C9: =C45*$B$70*$B$51 -> 0 | D9: =D45*$B$70*$B$51 -> 5000 | E9: =E45*$B$70*$B$51 -> 5000
A10: Total componentes | B10: =SUM(B5:B9) -> 181.15 | C10: =SUM(C5:C9) -> 450.41 | D10: =SUM(D5:D9) -> 11123.56 | E10: =SUM(E5:E9) -> 14745.48
A11: Soporte técnico mensual | B11: =B43*$B$50 -> 1035.0795 | C11: =C43*$B$50 -> 1035.0795 | D11: =D43*$B$50 -> 2070.159 | E11: =E43*$B$50 -> 4140.3181
A12: COSTO VARIABLE UNITARIO | B12: =B10+B11 -> 1216.2295 | C12: =C10+C11 -> 1485.4895 | D12: =D10+D11 -> 13193.719 | E12: =E10+E11 -> 18885.798
A13: PRECIO DE SUSCRIPCIÓN | B13: ='PPTO Vtas Productos'!C5 -> 15000 | C13: ='PPTO Vtas Productos'!C6 -> 25000 | D13: ='PPTO Vtas Productos'!C7 -> 45000 | E13: ='PPTO Vtas Productos'!C8 -> 70000
A14: APORTE ANTES DE FIJOS | B14: =B13-B12 -> 13783.77 | C14: =C13-C12 -> 23514.51 | D14: =D13-D12 -> 31806.281 | E14: =E13-E12 -> 51114.202
A15: Margen: aporte / precio | B15: =IF(B13>0,B14/B13,0) -> 0.91891803 | C15: =IF(C13>0,C14/C13,0) -> 0.94058042 | D15: =IF(D13>0,D14/D13,0) -> 0.70680624 | E15: =IF(E13>0,E14/E13,0) -> 0.73020288
A16: Recargo: aporte / costo | B16: =IF(B12>0,B14/B12,0) -> 11.333198 | C16: =IF(C12>0,C14/C12,0) -> 15.829469 | D16: =IF(D12>0,D14/D12,0) -> 2.4107138 | E16: =IF(E12>0,E14/E12,0) -> 2.7064888
A17: Nube: cuotas compartidas descontadas una sola vez; asignación según miembros. Cada mes se recalcula con los gimnasios del escenario.
A19: 2 · INSTALACIÓN | costo y cobro únicos por alta
A20: Concepto | B20: Starter | C20: Pro Gym | D20: Premium | E20: Enterprise
A21: Horas de instalación | B21: =B87 -> 8 | C21: =B87 -> 8 | D21: =C87 -> 18 | E21: =D87 -> 36
A22: Costo interno de instalación | B22: =B21*$B$50 -> 16561.272 | C22: =C21*$B$50 -> 16561.272 | D22: =D21*$B$50 -> 37262.863 | E22: =E21*$B$50 -> 74525.726
A23: Cobro único proyectado | B23: =0 -> 0 | C23: =0 -> 0 | D23: ='PPTO Vtas Productos'!C10 -> 129000 | E23: ='PPTO Vtas Productos'!C12 -> 258000
A24: Costo asumido por Pulso | B24: =MAX(0,B22-B23) -> 16561.272 | C24: =MAX(0,C22-C23) -> 16561.272 | D24: =MAX(0,D22-D23) -> 0 | E24: =MAX(0,E22-E23) -> 0
A25: Básica sin cobro. Instalación avanzada: costo de horas ÷ (1 − margen objetivo), redondeado hacia arriba a ₡1 000.
A27: 3 · PLATAFORMA Y DESARROLLO | no multiplicar por gimnasio
A28: Fijo operativo mensual | B28: =SUM(E94:E106) -> 114247.54 | C28: Incluye Redis, worker y espacio Render Pro.
A29: Costo común anual + captación inicial | B29: =B28*12+(3*2*2000+2*4000+8000+2*2*3000-C103)+(6*3*2-2*3*2)*B50 -> 1448654.4 | C29: Referencia de 12 meses; no sumar otra vez.
A30: ="Desarrollo común: "&TEXT(E90,"₡ #,##0")&" una vez en mes 1; se incluye en costos y recuperación. Separado de las instalaciones." -> Desarrollo común: ₡ 198,735 una vez en mes 1; se incluye en costos y recuperación. Separado de las instalaciones.
A31: Cobro por transferencia; Pulso no procesa cuotas de miembros. Comisión de pasarela = 0 por alcance. No incluye IVA ni impuesto sobre utilidades.
A34: ALCANCE POR PLAN | decisiones de presupuesto
A35: Métrica | B35: Starter | C35: Pro Gym | D35: Premium | E35: Enterprise
A36: Miembros máximos | B36: 80 | C36: 200 | D36: 500 | E36: 1000
A37: Sedes | B37: 1 | C37: 1 | D37: 1 | E37: 2
A38: Sesiones por miembro / mes | B38: 12 | C38: 12 | D38: 12 | E38: 12
A39: Solicitudes API por sesión | B39: 20 | C39: 20 | D39: 20 | E39: 20
A40: Sobrecarga administrativa | B40: 0.2 | C40: 0.2 | D40: 0.2 | E40: 0.2
A41: Archivos: cuota GB por gimnasio | B41: 1 | C41: 3 | D41: 8 | E41: 16
A42: Correos por miembro / mes | B42: 2 | C42: 2 | D42: 2 | E42: 2
A43: Soporte horas / mes | B43: 0.5 | C43: 0.5 | D43: 1 | E43: 2
A44: Proyecto dedicado USD / mes | B44: 0 | C44: 0 | D44: 10 | E44: 15
...

Sheet PPTO Vtas Servicios
A1: VENTAS · Cartera mensual, altas, ingresos y costos. Incluye nube por consumo y desarrollo común en mes 1; modificar cantidades cambia el escenario.
A2: ='PPTO Vtas Productos'!A2 -> PULSO
A3: Meta: 1 Starter +4 Pro al inicio; 1 alta Pro/mes; 1 baja en meses 6 y 10. Instalaciones y desarrollo se reconocen al incurrir.
C4: Mes 1 | D4: Mes 2 | E4: Mes 3 | F4: Mes 4 | G4: Mes 5 | H4: Mes 6 | I4: Mes 7 | J4: Mes 8 | K4: Mes 9 | L4: Mes 10 | M4: Mes 11 | N4: Mes 12 | O4: TOTAL
B5: Precio mensual o único
A6: CANTIDADES MENSUALES POR CONCEPTO
A7: ='PPTO Vtas Productos'!A5 -> Starter mensual | B7: ='PPTO Vtas Productos'!C5 -> 15000 | C7: 1 | D7: 1 | E7: 1 | F7: 1 | G7: 1 | H7: 1 | I7: 1 | J7: 1 | K7: 1 | L7: 1 | M7: 1 | N7: 1 | O7: =SUM(C7:N7) -> 12
A8: ='PPTO Vtas Productos'!A6 -> Pro Gym mensual | B8: ='PPTO Vtas Productos'!C6 -> 25000 | C8: 4 | D8: 5 | E8: 6 | F8: 7 | G8: 8 | H8: 8 | I8: 9 | J8: 10 | K8: 11 | L8: 11 | M8: 12 | N8: 13 | O8: =SUM(C8:N8) -> 104
A9: ='PPTO Vtas Productos'!A7 -> Premium mensual dedicado | B9: ='PPTO Vtas Productos'!C7 -> 45000 | C9: 0 | D9: 0 | E9: 0 | F9: 0 | G9: 0 | H9: 0 | I9: 0 | J9: 0 | K9: 0 | L9: 0 | M9: 0 | N9: 0 | O9: =SUM(C9:N9) -> 0
A10: ='PPTO Vtas Productos'!A8 -> Enterprise mensual · 2 sedes | B10: ='PPTO Vtas Productos'!C8 -> 70000 | C10: 0 | D10: 0 | E10: 0 | F10: 0 | G10: 0 | H10: 0 | I10: 0 | J10: 0 | K10: 0 | L10: 0 | M10: 0 | N10: 0 | O10: =SUM(C10:N10) -> 0
A11: ='PPTO Vtas Productos'!A9 -> Instalación básica | B11: ='PPTO Vtas Productos'!C9 -> 0 | C11: 5 | D11: 1 | E11: 1 | F11: 1 | G11: 1 | H11: 1 | I11: 1 | J11: 1 | K11: 1 | L11: 1 | M11: 1 | N11: 1 | O11: =SUM(C11:N11) -> 16
A12: ='PPTO Vtas Productos'!A10 -> Instalación premium | B12: ='PPTO Vtas Productos'!C10 -> 129000 | C12: 0 | D12: 0 | E12: 0 | F12: 0 | G12: 0 | H12: 0 | I12: 0 | J12: 0 | K12: 0 | L12: 0 | M12: 0 | N12: 0 | O12: =SUM(C12:N12) -> 0
A13: ='PPTO Vtas Productos'!A11 -> Operación fija plataforma | B13: 0 | C13: 1 | D13: 1 | E13: 1 | F13: 1 | G13: 1 | H13: 1 | I13: 1 | J13: 1 | K13: 1 | L13: 1 | M13: 1 | N13: 1 | O13: =SUM(C13:N13) -> 12
A14: ='PPTO Vtas Productos'!A12 -> Instalación Enterprise · 2 sedes | B14: ='PPTO Vtas Productos'!C12 -> 258000 | C14: 0 | D14: 0 | E14: 0 | F14: 0 | G14: 0 | H14: 0 | I14: 0 | J14: 0 | K14: 0 | L14: 0 | M14: 0 | N14: 0 | O14: =SUM(C14:N14) -> 0
A15: INGRESOS POR CONCEPTO | B15: Precio Und | C15: =C4 -> Mes 1 | D15: =D4 -> Mes 2 | E15: =E4 -> Mes 3 | F15: =F4 -> Mes 4 | G15: =G4 -> Mes 5 | H15: =H4 -> Mes 6 | I15: =I4 -> Mes 7 | J15: =J4 -> Mes 8 | ... N15: =N4 -> Mes 12 | O15: TOTAL
A16: =A7 -> Starter mensual | B16: =B7 -> 15000 | C16: =C7*$B16 -> 15000 | D16: =D7*$B16 -> 15000 | E16: =E7*$B16 -> 15000 | F16: =F7*$B16 -> 15000 | G16: =G7*$B16 -> 15000 | H16: =H7*$B16 -> 15000 | I16: =I7*$B16 -> 15000 | J16: =J7*$B16 -> 15000 | ... N16: =N7*$B16 -> 15000 | O16: =SUM(C16:N16) -> 180000
A17: =A8 -> Pro Gym mensual | B17: =B8 -> 25000 | C17: =C8*$B17 -> 100000 | D17: =D8*$B17 -> 125000 | E17: =E8*$B17 -> 150000 | F17: =F8*$B17 -> 175000 | G17: =G8*$B17 -> 200000 | H17: =H8*$B17 -> 200000 | I17: =I8*$B17 -> 225000 | J17: =J8*$B17 -> 250000 | ... N17: =N8*$B17 -> 325000 | O17: =SUM(C17:N17) -> 2600000
A18: =A9 -> Premium mensual dedicado | B18: =B9 -> 45000 | C18: =C9*$B18 -> 0 | D18: =D9*$B18 -> 0 | E18: =E9*$B18 -> 0 | F18: =F9*$B18 -> 0 | G18: =G9*$B18 -> 0 | H18: =H9*$B18 -> 0 | I18: =I9*$B18 -> 0 | J18: =J9*$B18 -> 0 | ... N18: =N9*$B18 -> 0 | O18: =SUM(C18:N18) -> 0
A19: =A10 -> Enterprise mensual · 2 sedes | B19: =B10 -> 70000 | C19: =C10*$B19 -> 0 | D19: =D10*$B19 -> 0 | E19: =E10*$B19 -> 0 | F19: =F10*$B19 -> 0 | G19: =G10*$B19 -> 0 | H19: =H10*$B19 -> 0 | I19: =I10*$B19 -> 0 | J19: =J10*$B19 -> 0 | ... N19: =N10*$B19 -> 0 | O19: =SUM(C19:N19) -> 0
A20: =A11 -> Instalación básica | B20: =B11 -> 0 | C20: =C11*$B20 -> 0 | D20: =D11*$B20 -> 0 | E20: =E11*$B20 -> 0 | F20: =F11*$B20 -> 0 | G20: =G11*$B20 -> 0 | H20: =H11*$B20 -> 0 | I20: =I11*$B20 -> 0 | J20: =J11*$B20 -> 0 | ... N20: =N11*$B20 -> 0 | O20: =SUM(C20:N20) -> 0
A21: =A12 -> Instalación premium | B21: =B12 -> 129000 | C21: =C12*$B21 -> 0 | D21: =D12*$B21 -> 0 | E21: =E12*$B21 -> 0 | F21: =F12*$B21 -> 0 | G21: =G12*$B21 -> 0 | H21: =H12*$B21 -> 0 | I21: =I12*$B21 -> 0 | J21: =J12*$B21 -> 0 | ... N21: =N12*$B21 -> 0 | O21: =SUM(C21:N21) -> 0
A22: =A13 -> Operación fija plataforma | B22: =B13 -> 0 | C22: =C13*$B22 -> 0 | D22: =D13*$B22 -> 0 | E22: =E13*$B22 -> 0 | F22: =F13*$B22 -> 0 | G22: =G13*$B22 -> 0 | H22: =H13*$B22 -> 0 | I22: =I13*$B22 -> 0 | J22: =J13*$B22 -> 0 | ... N22: =N13*$B22 -> 0 | O22: =SUM(C22:N22) -> 0
A23: =A14 -> Instalación Enterprise · 2 sedes | B23: =B14 -> 258000 | C23: =C14*$B23 -> 0 | D23: =D14*$B23 -> 0 | E23: =E14*$B23 -> 0 | F23: =F14*$B23 -> 0 | G23: =G14*$B23 -> 0 | H23: =H14*$B23 -> 0 | I23: =I14*$B23 -> 0 | J23: =J14*$B23 -> 0 | ... N23: =N14*$B23 -> 0 | O23: =SUM(C23:N23) -> 0
A24: TOTAL INGRESOS VENTAS | C24: =SUM(C16:C23) -> 115000 | D24: =SUM(D16:D23) -> 140000 | E24: =SUM(E16:E23) -> 165000 | F24: =SUM(F16:F23) -> 190000 | G24: =SUM(G16:G23) -> 215000 | H24: =SUM(H16:H23) -> 215000 | I24: =SUM(I16:I23) -> 240000 | J24: =SUM(J16:J23) -> 265000 | ... N24: =SUM(N16:N23) -> 340000 | O24: =SUM(C24:N24) -> 2780000
A25: COSTOS VARIABLES, INSTALACIÓN Y FIJOS | C25: =C37 -> 480631.18 | D25: =D37 -> 139452.49 | E25: =E37 -> 140937.98 | F25: =F37 -> 152423.47 | G25: =G37 -> 153908.96 | H25: =H37 -> 153908.96 | I25: =I37 -> 155394.45 | J25: =J37 -> 159379.94 | ... O25: =O37 -> 2183955.6
A26: RESULTADO ANTES DE IMPUESTOS | C26: =IF(OR(AND(C12>0,$B$12<=0),AND(C14>0,$B$14<=0)),"Cotizar instalaciones",C24-C37) -> -365631.18 | D26: =IF(OR(AND(D12>0,$B$12<=0),AND(D14>0,$B$14<=0)),"Cotizar instalaciones",D24-D37) -> 547.50588 | E26: =IF(OR(AND(E12>0,$B$12<=0),AND(E14>0,$B$14<=0)),"Cotizar instalaciones",E24-E37) -> 24062.016 | F26: =IF(OR(AND(F12>0,$B$12<=0),AND(F14>0,$B$14<=0)),"Cotizar instalaciones",F24-F37) -> 37576.527 | G26: =IF(OR(AND(G12>0,$B$12<=0),AND(G14>0,$B$14<=0)),"Cotizar instalaciones",G24-G37) -> 61091.037 | H26: =IF(OR(AND(H12>0,$B$12<=0),AND(H14>0,$B$14<=0)),"Cotizar instalaciones",H24-H37) -> 61091.037 | I26: =IF(OR(AND(I12>0,$B$12<=0),AND(I14>0,$B$14<=0)),"Cotizar instalaciones",I24-I37) -> 84605.548 | J26: =IF(OR(AND(J12>0,$B$12<=0),AND(J14>0,$B$14<=0)),"Cotizar instalaciones",J24-J37) -> 105620.06 | ... O26: =IF(OR(AND(O12>0,$B$12<=0),AND(O14>0,$B$14<=0)),"Cotizar instalaciones",O24-O37) -> 596044.36
A27: RESULTADO / INGRESOS | C27: =IF(ISNUMBER(C26),IF(C24>0,C26/C24,""),"Cotizar instalaciones") -> -3.1794016 | D27: =IF(ISNUMBER(D26),IF(D24>0,D26/D24,""),"Cotizar instalaciones") -> 0.0039107563 | E27: =IF(ISNUMBER(E26),IF(E24>0,E26/E24,""),"Cotizar instalaciones") -> 0.1458304 | F27: =IF(ISNUMBER(F26),IF(F24>0,F26/F24,""),"Cotizar instalaciones") -> 0.19777119 | G27: =IF(ISNUMBER(G26),IF(G24>0,G26/G24,""),"Cotizar instalaciones") -> 0.28414436 | H27: =IF(ISNUMBER(H26),IF(H24>0,H26/H24,""),"Cotizar instalaciones") -> 0.28414436 | I27: =IF(ISNUMBER(I26),IF(I24>0,I26/I24,""),"Cotizar instalaciones") -> 0.35252312 | J27: =IF(ISNUMBER(J26),IF(J24>0,J26/J24,""),"Cotizar instalaciones") -> 0.39856626 | ... O27: =IF(ISNUMBER(O26),IF(O24>0,O26/O24,""),"Cotizar instalaciones") -> 0.21440445
A28: COSTOS POR CONCEPTO | B28: Costos / Und | C28: =C15 -> Mes 1 | D28: =D15 -> Mes 2 | E28: =E15 -> Mes 3 | F28: =F15 -> Mes 4 | G28: =G15 -> Mes 5 | H28: =H15 -> Mes 6 | I28: =I15 -> Mes 7 | J28: =J15 -> Mes 8 | ... N28: =N15 -> Mes 12 | O28: TOTAL
A29: =A7 -> Starter mensual | B29: =Costeo!B12 -> 1216.2295 | C29: =C7*Costeo!$B$129 -> 1216.2295 | D29: =D7*Costeo!$B$129 -> 1216.2295 | E29: =E7*Costeo!$B$129 -> 1216.2295 | F29: =F7*Costeo!$B$129 -> 1216.2295 | G29: =G7*Costeo!$B$129 -> 1216.2295 | H29: =H7*Costeo!$B$129 -> 1216.2295 | I29: =I7*Costeo!$B$129 -> 1216.2295 | J29: =J7*Costeo!$B$129 -> 1216.2295 | ... N29: =N7*Costeo!$B$129 -> 1216.2295 | O29: =SUM(C29:N29) -> 14594.754
A30: =A8 -> Pro Gym mensual | B30: =Costeo!C12 -> 1485.4895 | C30: =C8*Costeo!$C$129 -> 5941.9581 | D30: =D8*Costeo!$C$129 -> 7427.4476 | E30: =E8*Costeo!$C$129 -> 8912.9371 | F30: =F8*Costeo!$C$129 -> 10398.427 | G30: =G8*Costeo!$C$129 -> 11883.916 | H30: =H8*Costeo!$C$129 -> 11883.916 | I30: =I8*Costeo!$C$129 -> 13369.406 | J30: =J8*Costeo!$C$129 -> 14854.895 | ... N30: =N8*Costeo!$C$129 -> 19311.364 | O30: =SUM(C30:N30) -> 154490.91
A31: =A9 -> Premium mensual dedicado | B31: =Costeo!D12 -> 13193.719 | C31: =C9*Costeo!$D$129 -> 0 | D31: =D9*Costeo!$D$129 -> 0 | E31: =E9*Costeo!$D$129 -> 0 | F31: =F9*Costeo!$D$129 -> 0 | G31: =G9*Costeo!$D$129 -> 0 | H31: =H9*Costeo!$D$129 -> 0 | I31: =I9*Costeo!$D$129 -> 0 | J31: =J9*Costeo!$D$129 -> 0 | ... N31: =N9*Costeo!$D$129 -> 0 | O31: =SUM(C31:N31) -> 0
A32: =A10 -> Enterprise mensual · 2 sedes | B32: =Costeo!E12 -> 18885.798 | C32: =C10*Costeo!$E$129 -> 0 | D32: =D10*Costeo!$E$129 -> 0 | E32: =E10*Costeo!$E$129 -> 0 | F32: =F10*Costeo!$E$129 -> 0 | G32: =G10*Costeo!$E$129 -> 0 | H32: =H10*Costeo!$E$129 -> 0 | I32: =I10*Costeo!$E$129 -> 0 | J32: =J10*Costeo!$E$129 -> 0 | ... N32: =N10*Costeo!$E$129 -> 0 | O32: =SUM(C32:N32) -> 0
A33: =A11 -> Instalación básica | B33: =Costeo!B22 -> 16561.272 | C33: =$B33*C11 -> 82806.362 | D33: =$B33*D11 -> 16561.272 | E33: =$B33*E11 -> 16561.272 | F33: =$B33*F11 -> 16561.272 | G33: =$B33*G11 -> 16561.272 | H33: =$B33*H11 -> 16561.272 | I33: =$B33*I11 -> 16561.272 | J33: =$B33*J11 -> 16561.272 | ... N33: =$B33*N11 -> 16561.272 | O33: =SUM(C33:N33) -> 264980.36
A34: =A12 -> Instalación premium | B34: =Costeo!D22 -> 37262.863 | C34: =$B34*C12 -> 0 | D34: =$B34*D12 -> 0 | E34: =$B34*E12 -> 0 | F34: =$B34*F12 -> 0 | G34: =$B34*G12 -> 0 | H34: =$B34*H12 -> 0 | I34: =$B34*I12 -> 0 | J34: =$B34*J12 -> 0 | ... N34: =$B34*N12 -> 0 | O34: =SUM(C34:N34) -> 0
A35: Plataforma: fijos + excedentes + arranque | B35: =Costeo!B28 -> 114247.54 | C35: =Costeo!$B$28*C13+Costeo!D138+Costeo!$E$90+(3*2*2000+2*4000+8000+2*2*3000-Costeo!$C$103)+(6*3*2-2*3*2)*Costeo!$B$50 -> 390666.63 | D35: =Costeo!$B$28*D13+Costeo!D139 -> 114247.54 | E35: =Costeo!$B$28*E13+Costeo!D140 -> 114247.54 | F35: =Costeo!$B$28*F13+Costeo!D141 -> 124247.54 | G35: =Costeo!$B$28*G13+Costeo!D142 -> 124247.54 | H35: =Costeo!$B$28*H13+Costeo!D143 -> 124247.54 | I35: =Costeo!$B$28*I13+Costeo!D144 -> 124247.54 | J35: =Costeo!$B$28*J13+Costeo!D145 -> 126747.54 | K35: =Costeo!$B$28*K13+Costeo!D146 -> 126747.54 | L35: =Costeo!$B$28*L13+Costeo!D147 -> 126747.54 | M35: =Costeo!$B$28*M13+Costeo!D148 -> 126747.54 | N35: =Costeo!$B$28*N13+Costeo!D149 -> 126747.54 | O35: =SUM(C35:N35) -> 1749889.6
A36: =A14 -> Instalación Enterprise · 2 sedes | B36: =Costeo!E22 -> 74525.726 | C36: =$B36*C14 -> 0 | D36: =$B36*D14 -> 0 | E36: =$B36*E14 -> 0 | F36: =$B36*F14 -> 0 | G36: =$B36*G14 -> 0 | H36: =$B36*H14 -> 0 | I36: =$B36*I14 -> 0 | J36: =$B36*J14 -> 0 | ... N36: =$B36*N14 -> 0 | O36: =SUM(C36:N36) -> 0
A37: TOTAL COSTOS PRESUPUESTADOS | C37: =SUM(C29:C36) -> 480631.18 | D37: =SUM(D29:D36) -> 139452.49 | E37: =SUM(E29:E36) -> 140937.98 | F37: =SUM(F29:F36) -> 152423.47 | G37: =SUM(G29:G36) -> 153908.96 | H37: =SUM(H29:H36) -> 153908.96 | I37: =SUM(I29:I36) -> 155394.45 | J37: =SUM(J29:J36) -> 159379.94 | ... N37: =SUM(N29:N36) -> 163836.41 | O37: =SUM(C37:N37) -> 2183955.6

Sheet Estructura de Precios
A1: COSTOS Y EQUILIBRIO · Compara planes exclusivos: mínimo de gimnasios para cubrir operación. Incluye costos variables, fijos y escalones de infraestructura.
A2: Proyección con los alcances definidos. Cada fila supone vender sólo ese plan; la cartera mixta se consulta en el detalle.
A3: 1 · COSTO COMÚN DE PULSO | se paga una sola vez
A4: Fijo operativo mensual | B4: =Costeo!B28 -> 114247.54
A5: Costos comunes actualizados: proveedores + viáticos recurrentes + trabajo de mantenimiento y captación. Mes 1 incorpora campaña inicial adicional.
A7: 2 · COMPARACIÓN POR PLAN | CRC por gimnasio / mes
A8: Plan | B8: Precio mensual | C8: Costo variable base | D8: Aporte antes de fijos y excedentes | E8: Gimnasios mínimos
A9: Starter | B9: ='PPTO Vtas Productos'!C5 -> 15000 | C9: =Costeo!B129 -> 1216.2295 | D9: =B9-C9 -> 13783.77 | E9: =IF(MIN(B52:B176)<1000000000,MIN(B52:B176),"Fuera de alcance") -> 9
A10: Pro Gym | B10: ='PPTO Vtas Productos'!C6 -> 25000 | C10: =Costeo!C129 -> 1485.4895 | D10: =B10-C10 -> 23514.51 | E10: =IF(MIN(C52:C176)<1000000000,MIN(C52:C176),"Fuera de alcance") -> 5
A11: Premium | B11: ='PPTO Vtas Productos'!C7 -> 45000 | C11: =Costeo!D129 -> 13193.719 | D11: =B11-C11 -> 31806.281 | E11: =IF(MIN(D52:D176)<1000000000,MIN(D52:D176),"Fuera de alcance") -> 4
A12: Enterprise | B12: ='PPTO Vtas Productos'!C8 -> 70000 | C12: =Costeo!E129 -> 18885.798 | D12: =B12-C12 -> 51114.202 | E12: =IF(MIN(E52:E176)<1000000000,MIN(E52:E176),"Fuera de alcance") -> 3
A13: Costo variable base: soporte, correos, IA y proyectos dedicados. El mínimo incorpora también los incrementos de nube del escenario.
A15: 3 · COMPROBACIÓN | un gimnasio menos frente al mínimo
A16: Plan | B16: Gimnasios: uno menos | C16: Resultado mensual con uno menos | D16: Gimnasios: mínimo | E16: Resultado mensual al mínimo
A17: Starter | B17: =IF(ISNUMBER(E9),E9-1,0) -> 8 | C17: =IF(ISNUMBER(E9),(B17)*$D$9-$B$4-((ROUND((MAX(0,(B17*Costeo!$B$117+0*Costeo!$C$117+0*Costeo!$D$117+0*Costeo!$E$117)-100)*Costeo!$B$53+MAX(0,(B17*Costeo!$B$118+0*Costeo!$C$118+0*Costeo!$D$118+0*Costeo!$E$118)-250)*Costeo!$B$52+(MAX(0,ROUNDUP(((B17*Costeo!$B$116+0*Costeo!$C$116)+(0*Costeo!$D$116+0*Costeo!$E$116)*0.05)*2,0)-8)+(B17*Costeo!$B$131+0*Costeo!$C$131+0*Costeo!$D$131+0*Costeo!$E$131))*Costeo!$B$54+IF((B17*Costeo!$B$36+0*Costeo!$C$36)<=2000,10,IF((B17*Costeo!$B$36+0*Costeo!$C$36)<=5000,15,IF((B17*Costeo!$B$36+0*Costeo!$C$36)<=10000,60,110)))-10)*Costeo!$B$51,2))+(ROUND((MAX(0,(B17*Costeo!$B$130+0*Costeo!$C$130+0*Costeo!$D$130+0*Costeo!$E$130)+20*2*2*Costeo!$B$69+30*(1/3600*Costeo!$B$55+5/3600*Costeo!$B$56)-Costeo!$B$58)+IF(AND((B17*Costeo!$B$120+0*Costeo!$C$120+0*Costeo!$D$120+0*Costeo!$E$120)<=1000000,(B17*Costeo!$B$119+0*Costeo!$C$119+0*Costeo!$D$119+0*Costeo!$E$119)<=1000),0,IF((B17*Costeo!$B$120+0*Costeo!$C$120+0*Costeo!$D$120+0*Costeo!$E$120)<=10000000,20,IF((B17*Costeo!$B$120+0*Costeo!$C$120+0*Costeo!$D$120+0*Costeo!$E$120)<=50000000,100,300)))+MAX(0,ROUNDUP((B17*Costeo!$B$36+0*Costeo!$C$36+0*Costeo!$D$36+0*Costeo!$E$36)/5000,0)-1)*Costeo!$B$62+IF((B17*Costeo!$B$36+0*Costeo!$C$36+0*Costeo!$D$36+0*Costeo!$E$36)>5000,32-Costeo!$B$61,0))*Costeo!$B$51,2))),"Fuera de alcance") -> -3977.3808 | D17: =E9 -> 9 | E17: =IF(ISNUMBER(E9),(D17)*$D$9-$B$4-((ROUND((MAX(0,(D17*Costeo!$B$117+0*Costeo!$C$117+0*Costeo!$D$117+0*Costeo!$E$117)-100)*Costeo!$B$53+MAX(0,(D17*Costeo!$B$118+0*Costeo!$C$118+0*Costeo!$D$118+0*Costeo!$E$118)-250)*Costeo!$B$52+(MAX(0,ROUNDUP(((D17*Costeo!$B$116+0*Costeo!$C$116)+(0*Costeo!$D$116+0*Costeo!$E$116)*0.05)*2,0)-8)+(D17*Costeo!$B$131+0*Costeo!$C$131+0*Costeo!$D$131+0*Costeo!$E$131))*Costeo!$B$54+IF((D17*Costeo!$B$36+0*Costeo!$C$36)<=2000,10,IF((D17*Costeo!$B$36+0*Costeo!$C$36)<=5000,15,IF((D17*Costeo!$B$36+0*Costeo!$C$36)<=10000,60,110)))-10)*Costeo!$B$51,2))+(ROUND((MAX(0,(D17*Costeo!$B$130+0*Costeo!$C$130+0*Costeo!$D$130+0*Costeo!$E$130)+20*2*2*Costeo!$B$69+30*(1/3600*Costeo!$B$55+5/3600*Costeo!$B$56)-Costeo!$B$58)+IF(AND((D17*Costeo!$B$120+0*Costeo!$C$120+0*Costeo!$D$120+0*Costeo!$E$120)<=1000000,(D17*Costeo!$B$119+0*Costeo!$C$119+0*Costeo!$D$119+0*Costeo!$E$119)<=1000),0,IF((D17*Costeo!$B$120+0*Costeo!$C$120+0*Costeo!$D$120+0*Costeo!$E$120)<=10000000,20,IF((D17*Costeo!$B$120+0*Costeo!$C$120+0*Costeo!$D$120+0*Costeo!$E$120)<=50000000,100,300)))+MAX(0,ROUNDUP((D17*Costeo!$B$36+0*Costeo!$C$36+0*Costeo!$D$36+0*Costeo!$E$36)/5000,0)-1)*Costeo!$B$62+IF((D17*Costeo!$B$36+0*Costeo!$C$36+0*Costeo!$D$36+0*Costeo!$E$36)>5000,32-Costeo!$B$61,0))*Costeo!$B$51,2))),"Fuera de alcance") -> 9806.3896
A18: Pro Gym | B18: =IF(ISNUMBER(E10),E10-1,0) -> 4 | C18: =IF(ISNUMBER(E10),(B18)*$D$10-$B$4-((ROUND((MAX(0,(0*Costeo!$B$117+B18*Costeo!$C$117+0*Costeo!$D$117+0*Costeo!$E$117)-100)*Costeo!$B$53+MAX(0,(0*Costeo!$B$118+B18*Costeo!$C$118+0*Costeo!$D$118+0*Costeo!$E$118)-250)*Costeo!$B$52+(MAX(0,ROUNDUP(((0*Costeo!$B$116+B18*Costeo!$C$116)+(0*Costeo!$D$116+0*Costeo!$E$116)*0.05)*2,0)-8)+(0*Costeo!$B$131+B18*Costeo!$C$131+0*Costeo!$D$131+0*Costeo!$E$131))*Costeo!$B$54+IF((0*Costeo!$B$36+B18*Costeo!$C$36)<=2000,10,IF((0*Costeo!$B$36+B18*Costeo!$C$36)<=5000,15,IF((0*Costeo!$B$36+B18*Costeo!$C$36)<=10000,60,110)))-10)*Costeo!$B$51,2))+(ROUND((MAX(0,(0*Costeo!$B$130+B18*Costeo!$C$130+0*Costeo!$D$130+0*Costeo!$E$130)+20*2*2*Costeo!$B$69+30*(1/3600*Costeo!$B$55+5/3600*Costeo!$B$56)-Costeo!$B$58)+IF(AND((0*Costeo!$B$120+B18*Costeo!$C$120+0*Costeo!$D$120+0*Costeo!$E$120)<=1000000,(0*Costeo!$B$119+B18*Costeo!$C$119+0*Costeo!$D$119+0*Costeo!$E$119)<=1000),0,IF((0*Costeo!$B$120+B18*Costeo!$C$120+0*Costeo!$D$120+0*Costeo!$E$120)<=10000000,20,IF((0*Costeo!$B$120+B18*Costeo!$C$120+0*Costeo!$D$120+0*Costeo!$E$120)<=50000000,100,300)))+MAX(0,ROUNDUP((0*Costeo!$B$36+B18*Costeo!$C$36+0*Costeo!$D$36+0*Costeo!$E$36)/5000,0)-1)*Costeo!$B$62+IF((0*Costeo!$B$36+B18*Costeo!$C$36+0*Costeo!$D$36+0*Costeo!$E$36)>5000,32-Costeo!$B$61,0))*Costeo!$B$51,2))),"Fuera de alcance") -> -20189.503 | D18: =E10 -> 5 | E18: =IF(ISNUMBER(E10),(D18)*$D$10-$B$4-((ROUND((MAX(0,(0*Costeo!$B$117+D18*Costeo!$C$117+0*Costeo!$D$117+0*Costeo!$E$117)-100)*Costeo!$B$53+MAX(0,(0*Costeo!$B$118+D18*Costeo!$C$118+0*Costeo!$D$118+0*Costeo!$E$118)-250)*Costeo!$B$52+(MAX(0,ROUNDUP(((0*Costeo!$B$116+D18*Costeo!$C$116)+(0*Costeo!$D$116+0*Costeo!$E$116)*0.05)*2,0)-8)+(0*Costeo!$B$131+D18*Costeo!$C$131+0*Costeo!$D$131+0*Costeo!$E$131))*Costeo!$B$54+IF((0*Costeo!$B$36+D18*Costeo!$C$36)<=2000,10,IF((0*Costeo!$B$36+D18*Costeo!$C$36)<=5000,15,IF((0*Costeo!$B$36+D18*Costeo!$C$36)<=10000,60,110)))-10)*Costeo!$B$51,2))+(ROUND((MAX(0,(0*Costeo!$B$130+D18*Costeo!$C$130+0*Costeo!$D$130+0*Costeo!$E$130)+20*2*2*Costeo!$B$69+30*(1/3600*Costeo!$B$55+5/3600*Costeo!$B$56)-Costeo!$B$58)+IF(AND((0*Costeo!$B$120+D18*Costeo!$C$120+0*Costeo!$D$120+0*Costeo!$E$120)<=1000000,(0*Costeo!$B$119+D18*Costeo!$C$119+0*Costeo!$D$119+0*Costeo!$E$119)<=1000),0,IF((0*Costeo!$B$120+D18*Costeo!$C$120+0*Costeo!$D$120+0*Costeo!$E$120)<=10000000,20,IF((0*Costeo!$B$120+D18*Costeo!$C$120+0*Costeo!$D$120+0*Costeo!$E$120)<=50000000,100,300)))+MAX(0,ROUNDUP((0*Costeo!$B$36+D18*Costeo!$C$36+0*Costeo!$D$36+0*Costeo!$E$36)/5000,0)-1)*Costeo!$B$62+IF((0*Costeo!$B$36+D18*Costeo!$C$36+0*Costeo!$D$36+0*Costeo!$E$36)>5000,32-Costeo!$B$61,0))*Costeo!$B$51,2))),"Fuera de alcance") -> 3325.0077
A19: Premium | B19: =IF(ISNUMBER(E11),E11-1,0) -> 3 | C19: =IF(ISNUMBER(E11),(B19)*$D$11-$B$4-((ROUND((MAX(0,(0*Costeo!$B$117+0*Costeo!$C$117+B19*Costeo!$D$117+0*Costeo!$E$117)-100)*Costeo!$B$53+MAX(0,(0*Costeo!$B$118+0*Costeo!$C$118+B19*Costeo!$D$118+0*Costeo!$E$118)-250)*Costeo!$B$52+(MAX(0,ROUNDUP(((0*Costeo!$B$116+0*Costeo!$C$116)+(B19*Costeo!$D$116+0*Costeo!$E$116)*0.05)*2,0)-8)+(0*Costeo!$B$131+0*Costeo!$C$131+B19*Costeo!$D$131+0*Costeo!$E$131))*Costeo!$B$54+IF((0*Costeo!$B$36+0*Costeo!$C$36)<=2000,10,IF((0*Costeo!$B$36+0*Costeo!$C$36)<=5000,15,IF((0*Costeo!$B$36+0*Costeo!$C$36)<=10000,60,110)))-10)*Costeo!$B$51,2))+(ROUND((MAX(0,(0*Costeo!$B$130+0*Costeo!$C$130+B19*Costeo!$D$130+0*Costeo!$E$130)+20*2*2*Costeo!$B$69+30*(1/3600*Costeo!$B$55+5/3600*Costeo!$B$56)-Costeo!$B$58)+IF(AND((0*Costeo!$B$120+0*Costeo!$C$120+B19*Costeo!$D$120+0*Costeo!$E$120)<=1000000,(0*Costeo!$B$119+0*Costeo!$C$119+B19*Costeo!$D$119+0*Costeo!$E$119)<=1000),0,IF((0*Costeo!$B$120+0*Costeo!$C$120+B19*Costeo!$D$120+0*Costeo!$E$120)<=10000000,20,IF((0*Costeo!$B$120+0*Costeo!$C$120+B19*Costeo!$D$120+0*Costeo!$E$120)<=50000000,100,300)))+MAX(0,ROUNDUP((0*Costeo!$B$36+0*Costeo!$C$36+B19*Costeo!$D$36+0*Costeo!$E$36)/5000,0)-1)*Costeo!$B$62+IF((0*Costeo!$B$36+0*Costeo!$C$36+B19*Costeo!$D$36+0*Costeo!$E$36)>5000,32-Costeo!$B$61,0))*Costeo!$B$51,2))),"Fuera de alcance") -> -28828.702 | D19: =E11 -> 4 | E19: =IF(ISNUMBER(E11),(D19)*$D$11-$B$4-((ROUND((MAX(0,(0*Costeo!$B$117+0*Costeo!$C$117+D19*Costeo!$D$117+0*Costeo!$E$117)-100)*Costeo!$B$53+MAX(0,(0*Costeo!$B$118+0*Costeo!$C$118+D19*Costeo!$D$118+0*Costeo!$E$118)-250)*Costeo!$B$52+(MAX(0,ROUNDUP(((0*Costeo!$B$116+0*Costeo!$C$116)+(D19*Costeo!$D$116+0*Costeo!$E$116)*0.05)*2,0)-8)+(0*Costeo!$B$131+0*Costeo!$C$131+D19*Costeo!$D$131+0*Costeo!$E$131))*Costeo!$B$54+IF((0*Costeo!$B$36+0*Costeo!$C$36)<=2000,10,IF((0*Costeo!$B$36+0*Costeo!$C$36)<=5000,15,IF((0*Costeo!$B$36+0*Costeo!$C$36)<=10000,60,110)))-10)*Costeo!$B$51,2))+(ROUND((MAX(0,(0*Costeo!$B$130+0*Costeo!$C$130+D19*Costeo!$D$130+0*Costeo!$E$130)+20*2*2*Costeo!$B$69+30*(1/3600*Costeo!$B$55+5/3600*Costeo!$B$56)-Costeo!$B$58)+IF(AND((0*Costeo!$B$120+0*Costeo!$C$120+D19*Costeo!$D$120+0*Costeo!$E$120)<=1000000,(0*Costeo!$B$119+0*Costeo!$C$119+D19*Costeo!$D$119+0*Costeo!$E$119)<=1000),0,IF((0*Costeo!$B$120+0*Costeo!$C$120+D19*Costeo!$D$120+0*Costeo!$E$120)<=10000000,20,IF((0*Costeo!$B$120+0*Costeo!$C$120+D19*Costeo!$D$120+0*Costeo!$E$120)<=50000000,100,300)))+MAX(0,ROUNDUP((0*Costeo!$B$36+0*Costeo!$C$36+D19*Costeo!$D$36+0*Costeo!$E$36)/5000,0)-1)*Costeo!$B$62+IF((0*Costeo!$B$36+0*Costeo!$C$36+D19*Costeo!$D$36+0*Costeo!$E$36)>5000,32-Costeo!$B$61,0))*Costeo!$B$51,2))),"Fuera de alcance") -> 2977.5792
A20: Enterprise | B20: =IF(ISNUMBER(E12),E12-1,0) -> 2 | C20: =IF(ISNUMBER(E12),(B20)*$D$12-$B$4-((ROUND((MAX(0,(0*Costeo!$B$117+0*Costeo!$C$117+0*Costeo!$D$117+B20*Costeo!$E$117)-100)*Costeo!$B$53+MAX(0,(0*Costeo!$B$118+0*Costeo!$C$118+0*Costeo!$D$118+B20*Costeo!$E$118)-250)*Costeo!$B$52+(MAX(0,ROUNDUP(((0*Costeo!$B$116+0*Costeo!$C$116)+(0*Costeo!$D$116+B20*Costeo!$E$116)*0.05)*2,0)-8)+(0*Costeo!$B$131+0*Costeo!$C$131+0*Costeo!$D$131+B20*Costeo!$E$131))*Costeo!$B$54+IF((0*Costeo!$B$36+0*Costeo!$C$36)<=2000,10,IF((0*Costeo!$B$36+0*Costeo!$C$36)<=5000,15,IF((0*Costeo!$B$36+0*Costeo!$C$36)<=10000,60,110)))-10)*Costeo!$B$51,2))+(ROUND((MAX(0,(0*Costeo!$B$130+0*Costeo!$C$130+0*Costeo!$D$130+B20*Costeo!$E$130)+20*2*2*Costeo!$B$69+30*(1/3600*Costeo!$B$55+5/3600*Costeo!$B$56)-Costeo!$B$58)+IF(AND((0*Costeo!$B$120+0*Costeo!$C$120+0*Costeo!$D$120+B20*Costeo!$E$120)<=1000000,(0*Costeo!$B$119+0*Costeo!$C$119+0*Costeo!$D$119+B20*Costeo!$E$119)<=1000),0,IF((0*Costeo!$B$120+0*Costeo!$C$120+0*Costeo!$D$120+B20*Costeo!$E$120)<=10000000,20,IF((0*Costeo!$B$120+0*Costeo!$C$120+0*Costeo!$D$120+B20*Costeo!$E$120)<=50000000,100,300)))+MAX(0,ROUNDUP((0*Costeo!$B$36+0*Costeo!$C$36+0*Costeo!$D$36+B20*Costeo!$E$36)/5000,0)-1)*Costeo!$B$62+IF((0*Costeo!$B$36+0*Costeo!$C$36+0*Costeo!$D$36+B20*Costeo!$E$36)>5000,32-Costeo!$B$61,0))*Costeo!$B$51,2))),"Fuera de alcance") -> -22019.141 | D20: =E12 -> 3 | E20: =IF(ISNUMBER(E12),(D20)*$D$12-$B$4-((ROUND((MAX(0,(0*Costeo!$B$117+0*Costeo!$C$117+0*Costeo!$D$117+D20*Costeo!$E$117)-100)*Costeo!$B$53+MAX(0,(0*Costeo!$B$118+0*Costeo!$C$118+0*Costeo!$D$118+D20*Costeo!$E$118)-250)*Costeo!$B$52+(MAX(0,ROUNDUP(((0*Costeo!$B$116+0*Costeo!$C$116)+(0*Costeo!$D$116+D20*Costeo!$E$116)*0.05)*2,0)-8)+(0*Costeo!$B$131+0*Costeo!$C$131+0*Costeo!$D$131+D20*Costeo!$E$131))*Costeo!$B$54+IF((0*Costeo!$B$36+0*Costeo!$C$36)<=2000,10,IF((0*Costeo!$B$36+0*Costeo!$C$36)<=5000,15,IF((0*Costeo!$B$36+0*Costeo!$C$36)<=10000,60,110)))-10)*Costeo!$B$51,2))+(ROUND((MAX(0,(0*Costeo!$B$130+0*Costeo!$C$130+0*Costeo!$D$130+D20*Costeo!$E$130)+20*2*2*Costeo!$B$69+30*(1/3600*Costeo!$B$55+5/3600*Costeo!$B$56)-Costeo!$B$58)+IF(AND((0*Costeo!$B$120+0*Costeo!$C$120+0*Costeo!$D$120+D20*Costeo!$E$120)<=1000000,(0*Costeo!$B$119+0*Costeo!$C$119+0*Costeo!$D$119+D20*Costeo!$E$119)<=1000),0,IF((0*Costeo!$B$120+0*Costeo!$C$120+0*Costeo!$D$120+D20*Costeo!$E$120)<=10000000,20,IF((0*Costeo!$B$120+0*Costeo!$C$120+0*Costeo!$D$120+D20*Costeo!$E$120)<=50000000,100,300)))+MAX(0,ROUNDUP((0*Costeo!$B$36+0*Costeo!$C$36+0*Costeo!$D$36+D20*Costeo!$E$36)/5000,0)-1)*Costeo!$B$62+IF((0*Costeo!$B$36+0*Costeo!$C$36+0*Costeo!$D$36+D20*Costeo!$E$36)>5000,32-Costeo!$B$61,0))*Costeo!$B$51,2))),"Fuera de alcance") -> 29095.061
A22: Resultado mensual = ingresos − costos variables − fijo común − incrementos de infraestructura.
A23: Cubrir la operación no recupera instalaciones ni desarrollo. Estos mínimos son antes de impuestos y no garantizan demanda ni capacidad técnica.
A24: Ver alcance, fórmulas y recuperación de la cartera mixta ↓
A27: DETALLE · CARTERA MIXTA E INVERSIÓN DEL ESCENARIO
A28: Gimnasios al inicio | B28: =SUM('PPTO Vtas Servicios'!C7:C10) -> 5 | C28: Un Starter y cuatro Pro en el escenario actual.
A29: Costo básico por alta | B29: =Costeo!B22 -> 16561.272 | C29: Lo asume Pulso; no es ingreso.
A30: Ingresos año 1 | B30: ='PPTO Vtas Servicios'!O24 -> 2780000 | C30: Dependen de las altas y bajas proyectadas.
A31: Resultado económico año 1 | B31: ='PPTO Vtas Servicios'!O26 -> 596044.36 | C31: Incluye desarrollo e instalaciones; antes de impuestos.
A32: Mes de recuperación | B32: =IF(MIN(Costeo!E184:E195)=999,"No recupera en 12 meses",MIN(Costeo!E184:E195)) -> 8 | C32: Primer acumulado económico no negativo.
A33: Déficit económico máximo | B33: =MAX(0,-MIN(Costeo!D184:D195)) -> 365631.18 | C33: Incluye tiempo propio; no equivale a efectivo necesario.
A34: Desarrollo común, único | B34: =Costeo!E90 -> 198735.27 | C34: Inversión reconocida en mes 1.
A35: Altas básicas durante el año | B35: =SUM('PPTO Vtas Servicios'!C11:N11) -> 16 | C35: No confundir altas con gimnasios activos.
A36: Costo de altas básicas | B36: ='PPTO Vtas Servicios'!O33 -> 264980.36 | C36: Cantidad de altas × costo de instalación.
A38: DETALLE · COSTO TOTAL AL ALCANZAR EL MÍNIMO
A39: Plan | B39: Ingresos mensuales | C39: Variables base totales | D39: Nube adicional | E39: Costo total con fijos
A40: Starter | B40: =IF(ISNUMBER($E$9),$E$9*B9,"Fuera de alcance") -> 135000 | C40: =IF(ISNUMBER($E$9),$E$9*C9,"Fuera de alcance") -> 10946.066 | D40: =IF(ISNUMBER($E$9),(ROUND((MAX(0,($E$9*Costeo!$B$117+0*Costeo!$C$117+0*Costeo!$D$117+0*Costeo!$E$117)-100)*Costeo!$B$53+MAX(0,($E$9*Costeo!$B$118+0*Costeo!$C$118+0*Costeo!$D$118+0*Costeo!$E$118)-250)*Costeo!$B$52+(MAX(0,ROUNDUP((($E$9*Costeo!$B$116+0*Costeo!$C$116)+(0*Costeo!$D$116+0*Costeo!$E$116)*0.05)*2,0)-8)+($E$9*Costeo!$B$131+0*Costeo!$C$131+0*Costeo!$D$131+0*Costeo!$E$131))*Costeo!$B$54+IF(($E$9*Costeo!$B$36+0*Costeo!$C$36)<=2000,10,IF(($E$9*Costeo!$B$36+0*Costeo!$C$36)<=5000,15,IF(($E$9*Costeo!$B$36+0*Costeo!$C$36)<=10000,60,110)))-10)*Costeo!$B$51,2))+(ROUND((MAX(0,($E$9*Costeo!$B$130+0*Costeo!$C$130+0*Costeo!$D$130+0*Costeo!$E$130)+20*2*2*Costeo!$B$69+30*(1/3600*Costeo!$B$55+5/3600*Costeo!$B$56)-Costeo!$B$58)+IF(AND(($E$9*Costeo!$B$120+0*Costeo!$C$120+0*Costeo!$D$120+0*Costeo!$E$120)<=1000000,($E$9*Costeo!$B$119+0*Costeo!$C$119+0*Costeo!$D$119+0*Costeo!$E$119)<=1000),0,IF(($E$9*Costeo!$B$120+0*Costeo!$C$120+0*Costeo!$D$120+0*Costeo!$E$120)<=10000000,20,IF(($E$9*Costeo!$B$120+0*Costeo!$C$120+0*Costeo!$D$120+0*Costeo!$E$120)<=50000000,100,300)))+MAX(0,ROUNDUP(($E$9*Costeo!$B$36+0*Costeo!$C$36+0*Costeo!$D$36+0*Costeo!$E$36)/5000,0)-1)*Costeo!$B$62+IF(($E$9*Costeo!$B$36+0*Costeo!$C$36+0*Costeo!$D$36+0*Costeo!$E$36)>5000,32-Costeo!$B$61,0))*Costeo!$B$51,2)),"Fuera de alcance") -> 0 | E40: =IF(ISNUMBER($E$9),C40+D40+$B$4,"Fuera de alcance") -> 125193.61
A41: Pro Gym | B41: =IF(ISNUMBER($E$10),$E$10*B10,"Fuera de alcance") -> 125000 | C41: =IF(ISNUMBER($E$10),$E$10*C10,"Fuera de alcance") -> 7427.4476 | D41: =IF(ISNUMBER($E$10),(ROUND((MAX(0,(0*Costeo!$B$117+$E$10*Costeo!$C$117+0*Costeo!$D$117+0*Costeo!$E$117)-100)*Costeo!$B$53+MAX(0,(0*Costeo!$B$118+$E$10*Costeo!$C$118+0*Costeo!$D$118+0*Costeo!$E$118)-250)*Costeo!$B$52+(MAX(0,ROUNDUP(((0*Costeo!$B$116+$E$10*Costeo!$C$116)+(0*Costeo!$D$116+0*Costeo!$E$116)*0.05)*2,0)-8)+(0*Costeo!$B$131+$E$10*Costeo!$C$131+0*Costeo!$D$131+0*Costeo!$E$131))*Costeo!$B$54+IF((0*Costeo!$B$36+$E$10*Costeo!$C$36)<=2000,10,IF((0*Costeo!$B$36+$E$10*Costeo!$C$36)<=5000,15,IF((0*Costeo!$B$36+$E$10*Costeo!$C$36)<=10000,60,110)))-10)*Costeo!$B$51,2))+(ROUND((MAX(0,(0*Costeo!$B$130+$E$10*Costeo!$C$130+0*Costeo!$D$130+0*Costeo!$E$130)+20*2*2*Costeo!$B$69+30*(1/3600*Costeo!$B$55+5/3600*Costeo!$B$56)-Costeo!$B$58)+IF(AND((0*Costeo!$B$120+$E$10*Costeo!$C$120+0*Costeo!$D$120+0*Costeo!$E$120)<=1000000,(0*Costeo!$B$119+$E$10*Costeo!$C$119+0*Costeo!$D$119+0*Costeo!$E$119)<=1000),0,IF((0*Costeo!$B$120+$E$10*Costeo!$C$120+0*Costeo!$D$120+0*Costeo!$E$120)<=10000000,20,IF((0*Costeo!$B$120+$E$10*Costeo!$C$120+0*Costeo!$D$120+0*Costeo!$E$120)<=50000000,100,300)))+MAX(0,ROUNDUP((0*Costeo!$B$36+$E$10*Costeo!$C$36+0*Costeo!$D$36+0*Costeo!$E$36)/5000,0)-1)*Costeo!$B$62+IF((0*Costeo!$B$36+$E$10*Costeo!$C$36+0*Costeo!$D$36+0*Costeo!$E$36)>5000,32-Costeo!$B$61,0))*Costeo!$B$51,2)),"Fuera de alcance") -> 0 | E41: =IF(ISNUMBER($E$10),C41+D41+$B$4,"Fuera de alcance") -> 121674.99
A42: Premium | B42: =IF(ISNUMBER($E$11),$E$11*B11,"Fuera de alcance") -> 180000 | C42: =IF(ISNUMBER($E$11),$E$11*C11,"Fuera de alcance") -> 52774.876 | D42: =IF(ISNUMBER($E$11),(ROUND((MAX(0,(0*Costeo!$B$117+0*Costeo!$C$117+$E$11*Costeo!$D$117+0*Costeo!$E$117)-100)*Costeo!$B$53+MAX(0,(0*Costeo!$B$118+0*Costeo!$C$118+$E$11*Costeo!$D$118+0*Costeo!$E$118)-250)*Costeo!$B$52+(MAX(0,ROUNDUP(((0*Costeo!$B$116+0*Costeo!$C$116)+($E$11*Costeo!$D$116+0*Costeo!$E$116)*0.05)*2,0)-8)+(0*Costeo!$B$131+0*Costeo!$C$131+$E$11*Costeo!$D$131+0*Costeo!$E$131))*Costeo!$B$54+IF((0*Costeo!$B$36+0*Costeo!$C$36)<=2000,10,IF((0*Costeo!$B$36+0*Costeo!$C$36)<=5000,15,IF((0*Costeo!$B$36+0*Costeo!$C$36)<=10000,60,110)))-10)*Costeo!$B$51,2))+(ROUND((MAX(0,(0*Costeo!$B$130+0*Costeo!$C$130+$E$11*Costeo!$D$130+0*Costeo!$E$130)+20*2*2*Costeo!$B$69+30*(1/3600*Costeo!$B$55+5/3600*Costeo!$B$56)-Costeo!$B$58)+IF(AND((0*Costeo!$B$120+0*Costeo!$C$120+$E$11*Costeo!$D$120+0*Costeo!$E$120)<=1000000,(0*Costeo!$B$119+0*Costeo!$C$119+$E$11*Costeo!$D$119+0*Costeo!$E$119)<=1000),0,IF((0*Costeo!$B$120+0*Costeo!$C$120+$E$11*Costeo!$D$120+0*Costeo!$E$120)<=10000000,20,IF((0*Costeo!$B$120+0*Costeo!$C$120+$E$11*Costeo!$D$120+0*Costeo!$E$120)<=50000000,100,300)))+MAX(0,ROUNDUP((0*Costeo!$B$36+0*Costeo!$C$36+$E$11*Costeo!$D$36+0*Costeo!$E$36)/5000,0)-1)*Costeo!$B$62+IF((0*Costeo!$B$36+0*Costeo!$C$36+$E$11*Costeo!$D$36+0*Costeo!$E$36)>5000,32-Costeo!$B$61,0))*Costeo!$B$51,2)),"Fuera de alcance") -> 10000 | E42: =IF(ISNUMBER($E$11),C42+D42+$B$4,"Fuera de alcance") -> 177022.42
A43: Enterprise | B43: =IF(ISNUMBER($E$12),$E$12*B12,"Fuera de alcance") -> 210000 | C43: =IF(ISNUMBER($E$12),$E$12*C12,"Fuera de alcance") -> 56657.394 | D43: =IF(ISNUMBER($E$12),(ROUND((MAX(0,(0*Costeo!$B$117+0*Costeo!$C$117+0*Costeo!$D$117+$E$12*Costeo!$E$117)-100)*Costeo!$B$53+MAX(0,(0*Costeo!$B$118+0*Costeo!$C$118+0*Costeo!$D$118+$E$12*Costeo!$E$118)-250)*Costeo!$B$52+(MAX(0,ROUNDUP(((0*Costeo!$B$116+0*Costeo!$C$116)+(0*Costeo!$D$116+$E$12*Costeo!$E$116)*0.05)*2,0)-8)+(0*Costeo!$B$131+0*Costeo!$C$131+0*Costeo!$D$131+$E$12*Costeo!$E$131))*Costeo!$B$54+IF((0*Costeo!$B$36+0*Costeo!$C$36)<=2000,10,IF((0*Costeo!$B$36+0*Costeo!$C$36)<=5000,15,IF((0*Costeo!$B$36+0*Costeo!$C$36)<=10000,60,110)))-10)*Costeo!$B$51,2))+(ROUND((MAX(0,(0*Costeo!$B$130+0*Costeo!$C$130+0*Costeo!$D$130+$E$12*Costeo!$E$130)+20*2*2*Costeo!$B$69+30*(1/3600*Costeo!$B$55+5/3600*Costeo!$B$56)-Costeo!$B$58)+IF(AND((0*Costeo!$B$120+0*Costeo!$C$120+0*Costeo!$D$120+$E$12*Costeo!$E$120)<=1000000,(0*Costeo!$B$119+0*Costeo!$C$119+0*Costeo!$D$119+$E$12*Costeo!$E$119)<=1000),0,IF((0*Costeo!$B$120+0*Costeo!$C$120+0*Costeo!$D$120+$E$12*Costeo!$E$120)<=10000000,20,IF((0*Costeo!$B$120+0*Costeo!$C$120+0*Costeo!$D$120+$E$12*Costeo!$E$120)<=50000000,100,300)))+MAX(0,ROUNDUP((0*Costeo!$B$36+0*Costeo!$C$36+0*Costeo!$D$36+$E$12*Costeo!$E$36)/5000,0)-1)*Costeo!$B$62+IF((0*Costeo!$B$36+0*Costeo!$C$36+0*Costeo!$D$36+$E$12*Costeo!$E$36)>5000,32-Costeo!$B$61,0))*Costeo!$B$51,2)),"Fuera de alcance") -> 10000 | E43: =IF(ISNUMBER($E$12),C43+D43+$B$4,"Fuera de alcance") -> 180904.94
A45: Método: se prueba cada cantidad desde 1 gimnasio hasta 10 000 miembros agregados; el primer resultado no negativo es el mínimo. No se reparte el fijo como si fuera variable.
A46: Fuentes y supuestos: Costeo contiene tarifas oficiales y decisiones de dimensionamiento. Abrir el vínculo para revisar su alcance.
A50: CÁLCULO DE LOS MÍNIMOS | desplegar con +
...
