Workbook

Sheet PPTO Vtas Productos
A1: CATÁLOGO PULSO
A2: PULSO
A3: CRC · precios mensuales o únicos
A4: Concepto | B4: Precio de venta CRC
A5: Starter mensual | B5: 15000
A6: Pro Gym mensual | B6: 25000
A7: Premium mensual dedicado | B7: 45000
A8: Enterprise mensual desde | B8: 70000
A9: Instalación básica | B9: 0
A10: Instalación premium | B10: ='PPTO Vtas Servicios'!B12 -> 0
A11: Operación fija plataforma | B11: 0
A12: Instalación Enterprise | B12: ='PPTO Vtas Servicios'!B14 -> 0

Sheet Costeo
A1: COSTEO DE SUSCRIPCIÓN E INSTALACIÓN
A2: ='PPTO Vtas Productos'!A2 -> PULSO
A3: Guía: nota de A1
A4: ='PPTO Vtas Productos'!A5 -> Starter mensual
A5: COSTOS DIRECTOS DEL SERVICIO
A6: Componente | B6: Costo base CRC | C6: Unidades base | D6: Unidades utilizadas | E6: Costo directo CRC
A7: Reserva consumo nube | B7: 750 | C7: 1 | D7: 1 | E7: =IFERROR(B7/C7*D7,0) -> 750
A8: Reserva mensajería | B8: 750 | C8: 1 | D8: 1 | E8: =IFERROR(B8/C8*D8,0) -> 750
A9: Reserva comisiones | B9: 750 | C9: 1 | D9: 1 | E9: =IFERROR(B9/C9*D9,0) -> 750
A10: TOTAL COMPONENTES DIRECTOS | E10: =SUM(E7:E9) -> 2250
A11: TRABAJO TÉCNICO DIRECTO
A12: Actividad técnica | B12: Costo bloque horas CRC | C12: Horas del bloque | D12: Horas del servicio | E12: Costo técnico CRC
A13: Soporte mensual por gimnasio | B13: 5000 | C13: 1 | D13: 0.5 | E13: =IFERROR(B13/C13*D13,0) -> 2500
A14: Costo del trabajo técnico | E14: =SUM(E13:E13) -> 2500
A15: COSTO DIRECTO POR SERVICIO | E15: =E10+E14 -> 4750
A16: PRECIO MENSUAL | E16: ='PPTO Vtas Productos'!B5 -> 15000
A17: CONTRIBUCIÓN ANTES DE FIJOS | E17: =E16-E15 -> 10250
A18: RECARGO SOBRE COSTO DIRECTO | E18: =IF(E16>0,E17/E15,"") -> 2.1578947
A19: ='PPTO Vtas Productos'!A6 -> Pro Gym mensual
A20: COSTOS DIRECTOS DEL SERVICIO
A21: Componente | B21: Costo base CRC | C21: Unidades base | D21: Unidades utilizadas | E21: Costo directo CRC
A22: Reserva consumo nube | B22: 750 | C22: 1 | D22: 1 | E22: =IFERROR(B22/C22*D22,0) -> 750
A23: Reserva mensajería | B23: 750 | C23: 1 | D23: 1 | E23: =IFERROR(B23/C23*D23,0) -> 750
A24: Reserva comisiones | B24: 750 | C24: 1 | D24: 1 | E24: =IFERROR(B24/C24*D24,0) -> 750
A25: TOTAL COMPONENTES DIRECTOS | E25: =SUM(E22:E24) -> 2250
A26: TRABAJO TÉCNICO DIRECTO
A27: Actividad técnica | B27: Costo bloque horas CRC | C27: Horas del bloque | D27: Horas del servicio | E27: Costo técnico CRC
A28: Soporte mensual por gimnasio | B28: 5000 | C28: 1 | D28: 0.5 | E28: =IFERROR(B28/C28*D28,0) -> 2500
A29: Costo del trabajo técnico | E29: =SUM(E28:E28) -> 2500
A30: COSTO DIRECTO POR SERVICIO | E30: =E25+E29 -> 4750
A31: PRECIO MENSUAL | E31: ='PPTO Vtas Productos'!B6 -> 25000
A32: CONTRIBUCIÓN ANTES DE FIJOS | E32: =E31-E30 -> 20250
A33: RECARGO SOBRE COSTO DIRECTO | E33: =IF(E31>0,E32/E30,"") -> 4.2631579
A34: ='PPTO Vtas Productos'!A7 -> Premium mensual dedicado
A35: COSTOS DIRECTOS DEL SERVICIO
A36: Componente | B36: Costo base CRC | C36: Unidades base | D36: Unidades utilizadas | E36: Costo directo CRC
A37: Base dedicada Supabase | B37: 5000 | C37: 1 | D37: 1 | E37: =IFERROR(B37/C37*D37,0) -> 5000
A38: Dominio API adicional | B38: 5000 | C38: 1 | D38: 1 | E38: =IFERROR(B38/C38*D38,0) -> 5000
A39: Reserva consumo nube | B39: 750 | C39: 1 | D39: 1 | E39: =IFERROR(B39/C39*D39,0) -> 750
A40: Reserva mensajería | B40: 750 | C40: 1 | D40: 1 | E40: =IFERROR(B40/C40*D40,0) -> 750
...

Sheet PPTO Vtas Servicios
A1: PRESUPUESTO DE VENTAS SERVICIOS
A2: ='PPTO Vtas Productos'!A2 -> PULSO
A3: Escenario: 1 Starter + 3 Pro Gym; altas al mes 1; instalación básica incluida.
C4: Mes 1 | D4: Mes 2 | E4: Mes 3 | F4: Mes 4 | G4: Mes 5 | H4: Mes 6 | I4: Mes 7 | J4: Mes 8 | K4: Mes 9 | L4: Mes 10 | M4: Mes 11 | N4: Mes 12 | O4: TOTAL
B5: Precio mensual o único
A6: CANTIDADES MENSUALES POR CONCEPTO
A7: Starter mensual | B7: ='PPTO Vtas Productos'!B5 -> 15000 | C7: 1 | D7: 1 | E7: 1 | F7: 1 | G7: 1 | H7: 1 | I7: 1 | J7: 1 | K7: 1 | L7: 1 | M7: 1 | N7: 1 | O7: =SUM(C7:N7) -> 12
A8: Pro Gym mensual | B8: ='PPTO Vtas Productos'!B6 -> 25000 | C8: 3 | D8: 3 | E8: 3 | F8: 3 | G8: 3 | H8: 3 | I8: 3 | J8: 3 | K8: 3 | L8: 3 | M8: 3 | N8: 3 | O8: =SUM(C8:N8) -> 36
A9: Premium mensual dedicado | B9: ='PPTO Vtas Productos'!B7 -> 45000 | C9: 0 | D9: 0 | E9: 0 | F9: 0 | G9: 0 | H9: 0 | I9: 0 | J9: 0 | K9: 0 | L9: 0 | M9: 0 | N9: 0 | O9: =SUM(C9:N9) -> 0
A10: Enterprise mensual desde | B10: ='PPTO Vtas Productos'!B8 -> 70000 | C10: 0 | D10: 0 | E10: 0 | F10: 0 | G10: 0 | H10: 0 | I10: 0 | J10: 0 | K10: 0 | L10: 0 | M10: 0 | N10: 0 | O10: =SUM(C10:N10) -> 0
A11: Instalación básica | B11: 0 | C11: 4 | D11: 0 | E11: 0 | F11: 0 | G11: 0 | H11: 0 | I11: 0 | J11: 0 | K11: 0 | L11: 0 | M11: 0 | N11: 0 | O11: =SUM(C11:N11) -> 4
A12: Instalación Premium cotizada | B12: 0 | C12: 0 | D12: 0 | E12: 0 | F12: 0 | G12: 0 | H12: 0 | I12: 0 | J12: 0 | K12: 0 | L12: 0 | M12: 0 | N12: 0 | O12: =SUM(C12:N12) -> 0
A13: Operación fija plataforma | B13: 0 | C13: 1 | D13: 1 | E13: 1 | F13: 1 | G13: 1 | H13: 1 | I13: 1 | J13: 1 | K13: 1 | L13: 1 | M13: 1 | N13: 1 | O13: =SUM(C13:N13) -> 12
A14: Instalación Enterprise cotizada | B14: 0 | C14: 0 | D14: 0 | E14: 0 | F14: 0 | G14: 0 | H14: 0 | I14: 0 | J14: 0 | K14: 0 | L14: 0 | M14: 0 | N14: 0 | O14: =SUM(C14:N14) -> 0
A15: INGRESOS POR CONCEPTO | B15: Precio Und | C15: =C4 -> Mes 1 | D15: =D4 -> Mes 2 | E15: =E4 -> Mes 3 | F15: =F4 -> Mes 4 | G15: =G4 -> Mes 5 | H15: =H4 -> Mes 6 | I15: =I4 -> Mes 7 | J15: =J4 -> Mes 8 | ... N15: =N4 -> Mes 12 | O15: TOTAL
A16: =A7 -> Starter mensual | B16: =B7 -> 15000 | C16: =C7*$B16 -> 15000 | D16: =D7*$B16 -> 15000 | E16: =E7*$B16 -> 15000 | F16: =F7*$B16 -> 15000 | G16: =G7*$B16 -> 15000 | H16: =H7*$B16 -> 15000 | I16: =I7*$B16 -> 15000 | J16: =J7*$B16 -> 15000 | ... N16: =N7*$B16 -> 15000 | O16: =SUM(C16:N16) -> 180000
A17: =A8 -> Pro Gym mensual | B17: =B8 -> 25000 | C17: =C8*$B17 -> 75000 | D17: =D8*$B17 -> 75000 | E17: =E8*$B17 -> 75000 | F17: =F8*$B17 -> 75000 | G17: =G8*$B17 -> 75000 | H17: =H8*$B17 -> 75000 | I17: =I8*$B17 -> 75000 | J17: =J8*$B17 -> 75000 | ... N17: =N8*$B17 -> 75000 | O17: =SUM(C17:N17) -> 900000
A18: =A9 -> Premium mensual dedicado | B18: =B9 -> 45000 | C18: =C9*$B18 -> 0 | D18: =D9*$B18 -> 0 | E18: =E9*$B18 -> 0 | F18: =F9*$B18 -> 0 | G18: =G9*$B18 -> 0 | H18: =H9*$B18 -> 0 | I18: =I9*$B18 -> 0 | J18: =J9*$B18 -> 0 | ... N18: =N9*$B18 -> 0 | O18: =SUM(C18:N18) -> 0
A19: =A10 -> Enterprise mensual desde | B19: =B10 -> 70000 | C19: =C10*$B19 -> 0 | D19: =D10*$B19 -> 0 | E19: =E10*$B19 -> 0 | F19: =F10*$B19 -> 0 | G19: =G10*$B19 -> 0 | H19: =H10*$B19 -> 0 | I19: =I10*$B19 -> 0 | J19: =J10*$B19 -> 0 | ... N19: =N10*$B19 -> 0 | O19: =SUM(C19:N19) -> 0
A20: =A11 -> Instalación básica | B20: =B11 -> 0 | C20: =C11*$B20 -> 0 | D20: =D11*$B20 -> 0 | E20: =E11*$B20 -> 0 | F20: =F11*$B20 -> 0 | G20: =G11*$B20 -> 0 | H20: =H11*$B20 -> 0 | I20: =I11*$B20 -> 0 | J20: =J11*$B20 -> 0 | ... N20: =N11*$B20 -> 0 | O20: =SUM(C20:N20) -> 0
A21: =A12 -> Instalación Premium cotizada | B21: =B12 -> 0 | C21: =C12*$B21 -> 0 | D21: =D12*$B21 -> 0 | E21: =E12*$B21 -> 0 | F21: =F12*$B21 -> 0 | G21: =G12*$B21 -> 0 | H21: =H12*$B21 -> 0 | I21: =I12*$B21 -> 0 | J21: =J12*$B21 -> 0 | ... N21: =N12*$B21 -> 0 | O21: =SUM(C21:N21) -> 0
A22: =A13 -> Operación fija plataforma | B22: =B13 -> 0 | C22: =C13*$B22 -> 0 | D22: =D13*$B22 -> 0 | E22: =E13*$B22 -> 0 | F22: =F13*$B22 -> 0 | G22: =G13*$B22 -> 0 | H22: =H13*$B22 -> 0 | I22: =I13*$B22 -> 0 | J22: =J13*$B22 -> 0 | ... N22: =N13*$B22 -> 0 | O22: =SUM(C22:N22) -> 0
A23: =A14 -> Instalación Enterprise cotizada | B23: =B14 -> 0 | C23: =C14*$B23 -> 0 | D23: =D14*$B23 -> 0 | E23: =E14*$B23 -> 0 | F23: =F14*$B23 -> 0 | G23: =G14*$B23 -> 0 | H23: =H14*$B23 -> 0 | I23: =I14*$B23 -> 0 | J23: =J14*$B23 -> 0 | ... N23: =N14*$B23 -> 0 | O23: =SUM(C23:N23) -> 0
A24: TOTAL INGRESOS VENTAS | C24: =SUM(C16:C23) -> 90000 | D24: =SUM(D16:D23) -> 90000 | E24: =SUM(E16:E23) -> 90000 | F24: =SUM(F16:F23) -> 90000 | G24: =SUM(G16:G23) -> 90000 | H24: =SUM(H16:H23) -> 90000 | I24: =SUM(I16:I23) -> 90000 | J24: =SUM(J16:J23) -> 90000 | ... N24: =SUM(N16:N23) -> 90000 | O24: =SUM(C24:N24) -> 1080000
A25: COSTOS VARIABLES, INSTALACIÓN Y FIJOS | C25: =C37 -> 240125 | D25: =D37 -> 80125 | E25: =E37 -> 80125 | F25: =F37 -> 80125 | G25: =G37 -> 80125 | H25: =H37 -> 80125 | I25: =I37 -> 80125 | J25: =J37 -> 80125 | ... O25: =O37 -> 1121500
A26: RESULTADO ANTES DE IMPUESTOS | C26: =IF(OR(AND(C12>0,$B$12<=0),AND(C14>0,$B$14<=0)),"Cotizar instalaciones",C24-C37) -> -150125 | D26: =IF(OR(AND(D12>0,$B$12<=0),AND(D14>0,$B$14<=0)),"Cotizar instalaciones",D24-D37) -> 9875 | E26: =IF(OR(AND(E12>0,$B$12<=0),AND(E14>0,$B$14<=0)),"Cotizar instalaciones",E24-E37) -> 9875 | F26: =IF(OR(AND(F12>0,$B$12<=0),AND(F14>0,$B$14<=0)),"Cotizar instalaciones",F24-F37) -> 9875 | G26: =IF(OR(AND(G12>0,$B$12<=0),AND(G14>0,$B$14<=0)),"Cotizar instalaciones",G24-G37) -> 9875 | H26: =IF(OR(AND(H12>0,$B$12<=0),AND(H14>0,$B$14<=0)),"Cotizar instalaciones",H24-H37) -> 9875 | I26: =IF(OR(AND(I12>0,$B$12<=0),AND(I14>0,$B$14<=0)),"Cotizar instalaciones",I24-I37) -> 9875 | J26: =IF(OR(AND(J12>0,$B$12<=0),AND(J14>0,$B$14<=0)),"Cotizar instalaciones",J24-J37) -> 9875 | ... O26: =IF(OR(AND(O12>0,$B$12<=0),AND(O14>0,$B$14<=0)),"Cotizar instalaciones",O24-O37) -> -41500
A27: RESULTADO / INGRESOS | C27: =IF(ISNUMBER(C26),IF(C24>0,C26/C24,""),"Cotizar instalaciones") -> -1.6680556 | D27: =IF(ISNUMBER(D26),IF(D24>0,D26/D24,""),"Cotizar instalaciones") -> 0.10972222 | E27: =IF(ISNUMBER(E26),IF(E24>0,E26/E24,""),"Cotizar instalaciones") -> 0.10972222 | F27: =IF(ISNUMBER(F26),IF(F24>0,F26/F24,""),"Cotizar instalaciones") -> 0.10972222 | G27: =IF(ISNUMBER(G26),IF(G24>0,G26/G24,""),"Cotizar instalaciones") -> 0.10972222 | H27: =IF(ISNUMBER(H26),IF(H24>0,H26/H24,""),"Cotizar instalaciones") -> 0.10972222 | I27: =IF(ISNUMBER(I26),IF(I24>0,I26/I24,""),"Cotizar instalaciones") -> 0.10972222 | J27: =IF(ISNUMBER(J26),IF(J24>0,J26/J24,""),"Cotizar instalaciones") -> 0.10972222 | ... O27: =IF(ISNUMBER(O26),IF(O24>0,O26/O24,""),"Cotizar instalaciones") -> -0.038425926
A28: COSTOS POR CONCEPTO | B28: Costos / Und | C28: =C15 -> Mes 1 | D28: =D15 -> Mes 2 | E28: =E15 -> Mes 3 | F28: =F15 -> Mes 4 | G28: =G15 -> Mes 5 | H28: =H15 -> Mes 6 | I28: =I15 -> Mes 7 | J28: =J15 -> Mes 8 | ... N28: =N15 -> Mes 12 | O28: TOTAL
A29: =A7 -> Starter mensual | B29: =Costeo!E15 -> 4750 | C29: =$B29*C7 -> 4750 | D29: =$B29*D7 -> 4750 | E29: =$B29*E7 -> 4750 | F29: =$B29*F7 -> 4750 | G29: =$B29*G7 -> 4750 | H29: =$B29*H7 -> 4750 | I29: =$B29*I7 -> 4750 | J29: =$B29*J7 -> 4750 | ... N29: =$B29*N7 -> 4750 | O29: =SUM(C29:N29) -> 57000
A30: =A8 -> Pro Gym mensual | B30: =Costeo!E30 -> 4750 | C30: =$B30*C8 -> 14250 | D30: =$B30*D8 -> 14250 | E30: =$B30*E8 -> 14250 | F30: =$B30*F8 -> 14250 | G30: =$B30*G8 -> 14250 | H30: =$B30*H8 -> 14250 | I30: =$B30*I8 -> 14250 | J30: =$B30*J8 -> 14250 | ... N30: =$B30*N8 -> 14250 | O30: =SUM(C30:N30) -> 171000
A31: =A9 -> Premium mensual dedicado | B31: =Costeo!E47 -> 17250 | C31: =$B31*C9 -> 0 | D31: =$B31*D9 -> 0 | E31: =$B31*E9 -> 0 | F31: =$B31*F9 -> 0 | G31: =$B31*G9 -> 0 | H31: =$B31*H9 -> 0 | I31: =$B31*I9 -> 0 | J31: =$B31*J9 -> 0 | ... N31: =$B31*N9 -> 0 | O31: =SUM(C31:N31) -> 0
A32: =A10 -> Enterprise mensual desde | B32: =Costeo!E64 -> 17250 | C32: =$B32*C10 -> 0 | D32: =$B32*D10 -> 0 | E32: =$B32*E10 -> 0 | F32: =$B32*F10 -> 0 | G32: =$B32*G10 -> 0 | H32: =$B32*H10 -> 0 | I32: =$B32*I10 -> 0 | J32: =$B32*J10 -> 0 | ... N32: =$B32*N10 -> 0 | O32: =SUM(C32:N32) -> 0
A33: =A11 -> Instalación básica | B33: =Costeo!E77 -> 40000 | C33: =$B33*C11 -> 160000 | D33: =$B33*D11 -> 0 | E33: =$B33*E11 -> 0 | F33: =$B33*F11 -> 0 | G33: =$B33*G11 -> 0 | H33: =$B33*H11 -> 0 | I33: =$B33*I11 -> 0 | J33: =$B33*J11 -> 0 | ... N33: =$B33*N11 -> 0 | O33: =SUM(C33:N33) -> 160000
A34: =A12 -> Instalación Premium cotizada | B34: =Costeo!E89 -> 90000 | C34: =$B34*C12 -> 0 | D34: =$B34*D12 -> 0 | E34: =$B34*E12 -> 0 | F34: =$B34*F12 -> 0 | G34: =$B34*G12 -> 0 | H34: =$B34*H12 -> 0 | I34: =$B34*I12 -> 0 | J34: =$B34*J12 -> 0 | ... N34: =$B34*N12 -> 0 | O34: =SUM(C34:N34) -> 0
A35: =A13 -> Operación fija plataforma | B35: =Costeo!E107 -> 61125 | C35: =$B35*C13 -> 61125 | D35: =$B35*D13 -> 61125 | E35: =$B35*E13 -> 61125 | F35: =$B35*F13 -> 61125 | G35: =$B35*G13 -> 61125 | H35: =$B35*H13 -> 61125 | I35: =$B35*I13 -> 61125 | J35: =$B35*J13 -> 61125 | ... N35: =$B35*N13 -> 61125 | O35: =SUM(C35:N35) -> 733500
A36: =A14 -> Instalación Enterprise cotizada | B36: =Costeo!E117 -> 90000 | C36: =$B36*C14 -> 0 | D36: =$B36*D14 -> 0 | E36: =$B36*E14 -> 0 | F36: =$B36*F14 -> 0 | G36: =$B36*G14 -> 0 | H36: =$B36*H14 -> 0 | I36: =$B36*I14 -> 0 | J36: =$B36*J14 -> 0 | ... N36: =$B36*N14 -> 0 | O36: =SUM(C36:N36) -> 0
A37: TOTAL COSTOS PRESUPUESTADOS | B37: =SUM(B29:B36) -> 325125 | C37: =SUM(C29:C36) -> 240125 | D37: =SUM(D29:D36) -> 80125 | E37: =SUM(E29:E36) -> 80125 | F37: =SUM(F29:F36) -> 80125 | G37: =SUM(G29:G36) -> 80125 | H37: =SUM(H29:H36) -> 80125 | I37: =SUM(I29:I36) -> 80125 | ... N37: =SUM(N29:N36) -> 80125 | O37: =SUM(C37:N37) -> 1121500

Sheet Estructura de Precios
A1: ANALISIS DE RENTABILIDAD
A2: ='PPTO Vtas Productos'!A2 -> PULSO
A3: Lee la guía, los planes y el resumen. Equilibrio mensual no es recuperación inicial.
A4: GUÍA DE LECTURA Y COSTO PROMEDIO
A5: PPTO Vtas Productos | B5: Catálogo y precios | D5: Precio instalación Premium | E5: =IF('PPTO Vtas Servicios'!B12>0,'PPTO Vtas Servicios'!B12,"Por cotizar") -> Por cotizar
A6: Costeo | B6: Componentes y horas | D6: Precio instalación Enterprise | E6: =IF('PPTO Vtas Servicios'!B14>0,'PPTO Vtas Servicios'!B14,"Por cotizar") -> Por cotizar
A7: PPTO Vtas Servicios | B7: Proyección mensual | D7: Costo avanzado de referencia | E7: =Costeo!E89 -> 90000
A8: Estructura de Precios | B8: Márgenes y recuperación
A9: Análisis de Competencia | B9: Tarifas y fuentes
A10: Rentabilidad | B10: Resultado anual
A11: Altas básicas del escenario | B11: =SUM('PPTO Vtas Servicios'!C11:N11) -> 4
A12: Costo básico promedio | B12: =IF(B11>0,B26/B11,"") -> 40000
A13: Resultado mensual por gimnasio | B13: =IF(B20>0,B25/B20,"") -> 2468.75
A14: Recuperación total (meses) | B14: =B29 -> 17
A15: Plan | B15: Costo directo CRC | C15: Precio mensual CRC | D15: Aporte antes de fijos | E15: Margen sobre precio | F15: Fijos plataforma/mes | G15: Gimnasios para equilibrio | H15: Costo interno instalación | I15: Meses sin fijos (referencia) | J15: Gimnasios del escenario | K15: Aporte mensual escenario | L15: Instalación básica absorbida | M15: Participación en gimnasios
A16: ='PPTO Vtas Servicios'!A7 -> Starter mensual | B16: ='PPTO Vtas Servicios'!B29 -> 4750 | C16: ='PPTO Vtas Servicios'!B7 -> 15000 | D16: =C16-B16 -> 10250 | E16: =IF(C16>0,D16/C16,"") -> 0.68333333 | F16: =Costeo!$E$107 -> 61125 | G16: =IF(D16>0,ROUNDUP(F16/D16,0),"") -> 6 | H16: =Costeo!E77 -> 40000 | I16: =IF(D16>0,ROUNDUP(H16/D16,0),"") -> 4 | J16: ='PPTO Vtas Servicios'!C7 -> 1 | K16: =D16*J16 -> 10250 | L16: =H16*J16 -> 40000 | M16: =IF(SUM($J$16:$J$19)>0,J16/SUM($J$16:$J$19),"") -> 0.25
A17: ='PPTO Vtas Servicios'!A8 -> Pro Gym mensual | B17: ='PPTO Vtas Servicios'!B30 -> 4750 | C17: ='PPTO Vtas Servicios'!B8 -> 25000 | D17: =C17-B17 -> 20250 | E17: =IF(C17>0,D17/C17,"") -> 0.81 | F17: =Costeo!$E$107 -> 61125 | G17: =IF(D17>0,ROUNDUP(F17/D17,0),"") -> 4 | H17: =Costeo!E77 -> 40000 | I17: =IF(D17>0,ROUNDUP(H17/D17,0),"") -> 2 | J17: ='PPTO Vtas Servicios'!C8 -> 3 | K17: =D17*J17 -> 60750 | L17: =H17*J17 -> 120000 | M17: =IF(SUM($J$16:$J$19)>0,J17/SUM($J$16:$J$19),"") -> 0.75
A18: ='PPTO Vtas Servicios'!A9 -> Premium mensual dedicado | B18: ='PPTO Vtas Servicios'!B31 -> 17250 | C18: ='PPTO Vtas Servicios'!B9 -> 45000 | D18: =C18-B18 -> 27750 | E18: =IF(C18>0,D18/C18,"") -> 0.61666667 | F18: =Costeo!$E$107 -> 61125 | G18: =IF(D18>0,ROUNDUP(F18/D18,0),"") -> 3 | H18: =Costeo!E89 -> 90000 | I18: ="Cobro aparte" -> Cobro aparte | J18: ='PPTO Vtas Servicios'!C9 -> 0 | K18: =D18*J18 -> 0 | L18: 0 | M18: =IF(SUM($J$16:$J$19)>0,J18/SUM($J$16:$J$19),"") -> 0
A19: ='PPTO Vtas Servicios'!A10 -> Enterprise mensual desde | B19: ='PPTO Vtas Servicios'!B32 -> 17250 | C19: ='PPTO Vtas Servicios'!B10 -> 70000 | D19: =C19-B19 -> 52750 | E19: =IF(C19>0,D19/C19,"") -> 0.75357143 | F19: =Costeo!$E$107 -> 61125 | G19: =IF(D19>0,ROUNDUP(F19/D19,0),"") -> 2 | H19: =Costeo!E117 -> 90000 | I19: ="Cobro aparte" -> Cobro aparte | J19: ='PPTO Vtas Servicios'!C10 -> 0 | K19: =D19*J19 -> 0 | L19: 0 | M19: =IF(SUM($J$16:$J$19)>0,J19/SUM($J$16:$J$19),"") -> 0
A20: Gimnasios al inicio | B20: =SUM(J16:J19) -> 4
A21: Ingresos mensuales | B21: =SUMPRODUCT(C16:C19,J16:J19) -> 90000
A22: Costos variables mensuales | B22: =SUMPRODUCT(B16:B19,J16:J19) -> 19000
A23: Aporte mensual antes de fijos | B23: =B21-B22 -> 71000
A24: Fijos mensuales | B24: =Costeo!E107 -> 61125
A25: Resultado mensual recurrente | B25: =B23-B24 -> 9875
A26: Instalaciones absorbidas | B26: =SUM(L16:L17) -> 160000
A27: Resultado primer mes | B27: ='PPTO Vtas Servicios'!C26 -> -150125
A28: Resultado año 1 | B28: =IF(OR(AND(SUM('PPTO Vtas Servicios'!C12:N12)>0,'PPTO Vtas Servicios'!B12<=0),AND(SUM('PPTO Vtas Servicios'!C14:N14)>0,'PPTO Vtas Servicios'!B14<=0)),"Cotizar instalaciones",'PPTO Vtas Servicios'!O26) -> -41500
A29: Recuperación neta (meses) | B29: =IF(ISNUMBER(B28),IF(AND(MAX('PPTO Vtas Servicios'!C7:N7)=MIN('PPTO Vtas Servicios'!C7:N7),MAX('PPTO Vtas Servicios'!C8:N8)=MIN('PPTO Vtas Servicios'!C8:N8),MAX('PPTO Vtas Servicios'!C9:N9)=MIN('PPTO Vtas Servicios'!C9:N9),MAX('PPTO Vtas Servicios'!C10:N10)=MIN('PPTO Vtas Servicios'!C10:N10),SUM('PPTO Vtas Servicios'!D11:N12,'PPTO Vtas Servicios'!D14:N14)=0),IF(B25>0,ROUNDUP(MAX(0,('PPTO Vtas Servicios'!O33+'PPTO Vtas Servicios'!O34+'PPTO Vtas Servicios'!O36-'PPTO Vtas Servicios'!O20-'PPTO Vtas Servicios'!O21-'PPTO Vtas Servicios'!O23))/B25,0),"No recupera"),"Cartera variable"),"Cotizar instalaciones") -> 17
A30: Acumulado antes de recuperación | B30: =IF(ISNUMBER(B29),IF(B29>0,(B29-1)*B25-('PPTO Vtas Servicios'!O33+'PPTO Vtas Servicios'!O34+'PPTO Vtas Servicios'!O36-'PPTO Vtas Servicios'!O20-'PPTO Vtas Servicios'!O21-'PPTO Vtas Servicios'!O23),"No requiere espera"),"") -> -2000
A31: Acumulado al recuperar | B31: =IF(ISNUMBER(B29),IF(B29>0,B29*B25-('PPTO Vtas Servicios'!O33+'PPTO Vtas Servicios'!O34+'PPTO Vtas Servicios'!O36-'PPTO Vtas Servicios'!O20-'PPTO Vtas Servicios'!O21-'PPTO Vtas Servicios'!O23),"No requiere espera"),"") -> 7875
A32: Saldo acumulado mes 12 | B32: =B28 -> -41500
A33: Pérdida inicial por financiar | B33: =IF(ISNUMBER(B27),MAX(0,-B27),"Cotizar instalaciones") -> 150125
A34: ESCENARIO HIPOTÉTICO, NO VENTAS CONFIRMADAS

Sheet Análisis de Competencia
A1: COMPARACIÓN DE TARIFAS PUBLICADAS
A2: PULSO
A3: Consulta 11/09/2026 · CRC/USD 500 presupuestado · Aforo comparable; funciones distintas.
A4: Plan Pulso | B4: Pulso CRC/mes | C4: Gymdesk CRC/mes | D4: Diferencia / Pulso | E4: GymMaster CRC/mes | F4: Diferencia / Pulso
A5: ='PPTO Vtas Servicios'!A7 -> Starter mensual | B5: ='PPTO Vtas Servicios'!B7 -> 15000 | C5: =100*500 -> 50000 | D5: =IF(ISNUMBER(C5),C5/B5-1,"Sin tarifa pública") -> 2.3333333 | E5: =89*500 -> 44500 | F5: =IF(ISNUMBER(E5),E5/B5-1,"Sin tarifa pública") -> 1.9666667
A6: ='PPTO Vtas Servicios'!A8 -> Pro Gym mensual | B6: ='PPTO Vtas Servicios'!B8 -> 25000 | C6: =150*500 -> 75000 | D6: =IF(ISNUMBER(C6),C6/B6-1,"Sin tarifa pública") -> 2 | E6: =129*500 -> 64500 | F6: =IF(ISNUMBER(E6),E6/B6-1,"Sin tarifa pública") -> 1.58
A7: ='PPTO Vtas Servicios'!A9 -> Premium mensual dedicado | B7: ='PPTO Vtas Servicios'!B9 -> 45000 | C7: Por cotizar | D7: =IF(ISNUMBER(C7),C7/B7-1,"Sin tarifa pública") -> Sin tarifa pública | E7: =209*500 -> 104500 | F7: =IF(ISNUMBER(E7),E7/B7-1,"Sin tarifa pública") -> 1.3222222
A8: ='PPTO Vtas Servicios'!A10 -> Enterprise mensual desde | B8: ='PPTO Vtas Servicios'!B10 -> 70000 | C8: Por cotizar | D8: =IF(ISNUMBER(C8),C8/B8-1,"Sin tarifa pública") -> Sin tarifa pública | E8: Por cotizar | F8: =IF(ISNUMBER(E8),E8/B8-1,"Sin tarifa pública") -> Sin tarifa pública

Sheet Rentabilidad
A1: ANALISIS DE RENTABILIDAD
A2: ='PPTO Vtas Productos'!A2 -> PULSO
A3: Año 1: ingresos menos variables, instalaciones y fijos. Antes de impuestos.
B4: Cantidad anual por concepto | C4: Precio Venta | D4: Costo Venta | E4: Aporte/costo unitario | F4: Monto Total Venta | G4: Mezcla Ventas | H4: Monto Total Costo | I4: Mezcla Costos | J4: Resultado anual CRC | K4: Resultado / ingresos | L4: Aporte al resultado positivo
A5: ='PPTO Vtas Servicios'!A7 -> Starter mensual | B5: ='PPTO Vtas Servicios'!O7 -> 12 | C5: ='PPTO Vtas Servicios'!B7 -> 15000 | D5: ='PPTO Vtas Servicios'!B29 -> 4750 | E5: =C5-D5 -> 10250 | F5: ='PPTO Vtas Servicios'!O16 -> 180000 | G5: =IF(F$14>0,F5/F$14,0) -> 0.16666667 | H5: ='PPTO Vtas Servicios'!O29 -> 57000 | I5: =IF(H$14>0,H5/H$14,0) -> 0.050824788 | J5: =F5-H5 -> 123000 | K5: =IF(F5>0,J5/F5,"No aplica") -> 0.68333333 | L5: =IF(ISNUMBER($J$14),IF($J$14>0,J5/$J$14,"No aplica"),"Cotizar") -> No aplica
A6: ='PPTO Vtas Servicios'!A8 -> Pro Gym mensual | B6: ='PPTO Vtas Servicios'!O8 -> 36 | C6: ='PPTO Vtas Servicios'!B8 -> 25000 | D6: ='PPTO Vtas Servicios'!B30 -> 4750 | E6: =C6-D6 -> 20250 | F6: ='PPTO Vtas Servicios'!O17 -> 900000 | G6: =IF(F$14>0,F6/F$14,0) -> 0.83333333 | H6: ='PPTO Vtas Servicios'!O30 -> 171000 | I6: =IF(H$14>0,H6/H$14,0) -> 0.15247436 | J6: =F6-H6 -> 729000 | K6: =IF(F6>0,J6/F6,"No aplica") -> 0.81 | L6: =IF(ISNUMBER($J$14),IF($J$14>0,J6/$J$14,"No aplica"),"Cotizar") -> No aplica
A7: ='PPTO Vtas Servicios'!A9 -> Premium mensual dedicado | B7: ='PPTO Vtas Servicios'!O9 -> 0 | C7: ='PPTO Vtas Servicios'!B9 -> 45000 | D7: ='PPTO Vtas Servicios'!B31 -> 17250 | E7: =C7-D7 -> 27750 | F7: ='PPTO Vtas Servicios'!O18 -> 0 | G7: =IF(F$14>0,F7/F$14,0) -> 0 | H7: ='PPTO Vtas Servicios'!O31 -> 0 | I7: =IF(H$14>0,H7/H$14,0) -> 0 | J7: =F7-H7 -> 0 | K7: =IF(F7>0,J7/F7,"No aplica") -> No aplica | L7: =IF(ISNUMBER($J$14),IF($J$14>0,J7/$J$14,"No aplica"),"Cotizar") -> No aplica
A8: ='PPTO Vtas Servicios'!A10 -> Enterprise mensual desde | B8: ='PPTO Vtas Servicios'!O10 -> 0 | C8: ='PPTO Vtas Servicios'!B10 -> 70000 | D8: ='PPTO Vtas Servicios'!B32 -> 17250 | E8: =C8-D8 -> 52750 | F8: ='PPTO Vtas Servicios'!O19 -> 0 | G8: =IF(F$14>0,F8/F$14,0) -> 0 | H8: ='PPTO Vtas Servicios'!O32 -> 0 | I8: =IF(H$14>0,H8/H$14,0) -> 0 | J8: =F8-H8 -> 0 | K8: =IF(F8>0,J8/F8,"No aplica") -> No aplica | L8: =IF(ISNUMBER($J$14),IF($J$14>0,J8/$J$14,"No aplica"),"Cotizar") -> No aplica
A9: ='PPTO Vtas Servicios'!A11 -> Instalación básica | B9: ='PPTO Vtas Servicios'!O11 -> 4 | C9: ='PPTO Vtas Servicios'!B11 -> 0 | D9: ='PPTO Vtas Servicios'!B33 -> 40000 | E9: =C9-D9 -> -40000 | F9: ='PPTO Vtas Servicios'!O20 -> 0 | G9: =IF(F$14>0,F9/F$14,0) -> 0 | H9: ='PPTO Vtas Servicios'!O33 -> 160000 | I9: =IF(H$14>0,H9/H$14,0) -> 0.14266607 | J9: =F9-H9 -> -160000 | K9: =IF(F9>0,J9/F9,"No aplica") -> No aplica | L9: =IF(ISNUMBER($J$14),IF($J$14>0,J9/$J$14,"No aplica"),"Cotizar") -> No aplica
A10: ='PPTO Vtas Servicios'!A12 -> Instalación Premium cotizada | B10: ='PPTO Vtas Servicios'!O12 -> 0 | C10: ='PPTO Vtas Servicios'!B12 -> 0 | D10: ='PPTO Vtas Servicios'!B34 -> 90000 | E10: =C10-D10 -> -90000 | F10: ='PPTO Vtas Servicios'!O21 -> 0 | G10: =IF(F$14>0,F10/F$14,0) -> 0 | H10: ='PPTO Vtas Servicios'!O34 -> 0 | I10: =IF(H$14>0,H10/H$14,0) -> 0 | J10: =F10-H10 -> 0 | K10: =IF(F10>0,J10/F10,"No aplica") -> No aplica | L10: =IF(ISNUMBER($J$14),IF($J$14>0,J10/$J$14,"No aplica"),"Cotizar") -> No aplica
A11: ='PPTO Vtas Servicios'!A13 -> Operación fija plataforma | B11: ='PPTO Vtas Servicios'!O13 -> 12 | C11: ='PPTO Vtas Servicios'!B13 -> 0 | D11: ='PPTO Vtas Servicios'!B35 -> 61125 | E11: =C11-D11 -> -61125 | F11: ='PPTO Vtas Servicios'!O22 -> 0 | G11: =IF(F$14>0,F11/F$14,0) -> 0 | H11: ='PPTO Vtas Servicios'!O35 -> 733500 | I11: =IF(H$14>0,H11/H$14,0) -> 0.65403477 | J11: =F11-H11 -> -733500 | K11: =IF(F11>0,J11/F11,"No aplica") -> No aplica | L11: =IF(ISNUMBER($J$14),IF($J$14>0,J11/$J$14,"No aplica"),"Cotizar") -> No aplica
A12: ='PPTO Vtas Servicios'!A14 -> Instalación Enterprise cotizada | B12: ='PPTO Vtas Servicios'!O14 -> 0 | C12: ='PPTO Vtas Servicios'!B14 -> 0 | D12: ='PPTO Vtas Servicios'!B36 -> 90000 | E12: =C12-D12 -> -90000 | F12: ='PPTO Vtas Servicios'!O23 -> 0 | G12: =IF(F$14>0,F12/F$14,0) -> 0 | H12: ='PPTO Vtas Servicios'!O36 -> 0 | I12: =IF(H$14>0,H12/H$14,0) -> 0 | J12: =F12-H12 -> 0 | K12: =IF(F12>0,J12/F12,"No aplica") -> No aplica | L12: =IF(ISNUMBER($J$14),IF($J$14>0,J12/$J$14,"No aplica"),"Cotizar") -> No aplica
A13: TOTAL ESCENARIO AÑO 1 | F13: =SUM(F5:F12) -> 1080000 | G13: =IF(F$14>0,F13/F$14,0) -> 1 | H13: =SUM(H5:H12) -> 1121500 | I13: =IF(H$14>0,H13/H$14,0) -> 1 | J13: =IF(OR(AND('PPTO Vtas Servicios'!O12>0,'PPTO Vtas Servicios'!B12<=0),AND('PPTO Vtas Servicios'!O14>0,'PPTO Vtas Servicios'!B14<=0)),"Cotizar instalaciones",SUM(J5:J12)) -> -41500 | K13: =IF(ISNUMBER(J13),IF(F13>0,J13/F13,""),"Cotizar instalaciones") -> -0.038425926
A14: RESULTADO ANUAL ANTES DE IMPUESTOS | F14: =F13 -> 1080000 | G14: =G13 -> 1 | H14: =H13 -> 1121500 | I14: =I13 -> 1 | J14: =J13 -> -41500 | K14: =IF(ISNUMBER(J14),IF(F14>0,J14/F14,""),"Cotizar instalaciones") -> -0.038425926
