Workbook

Sheet VENTAS
B7: DETALLE VENTAS
B9: Días Laborables | D9: 1 | F9: Incremento | H9: 0 | I9: 0 | J9: 0 | K9: 0 | L9: 0 | M9: 0 | N9: 0 | O9: 0 | P9: 0 | Q9: 0 | R9: 0 | S9: 0
B11: PRODUCTOS | D11: Q Venta al mes | F11: Lista Precios | H11: Mes 1 | I11: Mes 2 | J11: Mes 3 | K11: Mes 4 | L11: Mes 5 | M11: Mes 6 | N11: Mes 7 | O11: Mes 8 | P11: Mes 9 | Q11: Mes 10 | R11: Mes 11 | S11: Mes 12 | T11: AÑO 1 | U11: AÑO 2 | V11: AÑO 3 | W11: AÑO 4 | X11: AÑO 5
B13: Producto 1 | D13: 0 | F13: 0 | H13: =ROUND($D13*$F13*$D$9*(1+H$9),0) -> 0 | I13: =ROUND($D13*$F13*$D$9*(1+I$9),0) -> 0 | J13: =ROUND($D13*$F13*$D$9*(1+J$9),0) -> 0 | K13: =ROUND($D13*$F13*$D$9*(1+K$9),0) -> 0 | L13: =ROUND($D13*$F13*$D$9*(1+L$9),0) -> 0 | M13: =ROUND($D13*$F13*$D$9*(1+M$9),0) -> 0 | N13: =ROUND($D13*$F13*$D$9*(1+N$9),0) -> 0 | O13: =ROUND($D13*$F13*$D$9*(1+O$9),0) -> 0 | ... S13: =ROUND($D13*$F13*$D$9*(1+S$9),0) -> 0 | T13: =SUM(H13:S13) -> 0 | U13: =T13*(1+PRESUPUESTO!Q$7) -> 0 | V13: =U13*(1+PRESUPUESTO!R$7) -> 0 | W13: =V13*(1+PRESUPUESTO!S$7) -> 0 | X13: =W13*(1+PRESUPUESTO!T$7) -> 0
B14: Producto 2 | D14: 0 | F14: 0 | H14: =ROUND($D14*$F14*$D$9*(1+H$9),0) -> 0 | I14: =ROUND($D14*$F14*$D$9*(1+I$9),0) -> 0 | J14: =ROUND($D14*$F14*$D$9*(1+J$9),0) -> 0 | K14: =ROUND($D14*$F14*$D$9*(1+K$9),0) -> 0 | L14: =ROUND($D14*$F14*$D$9*(1+L$9),0) -> 0 | M14: =ROUND($D14*$F14*$D$9*(1+M$9),0) -> 0 | N14: =ROUND($D14*$F14*$D$9*(1+N$9),0) -> 0 | O14: =ROUND($D14*$F14*$D$9*(1+O$9),0) -> 0 | ... S14: =ROUND($D14*$F14*$D$9*(1+S$9),0) -> 0 | T14: =SUM(H14:S14) -> 0 | U14: =T14*(1+PRESUPUESTO!Q$7) -> 0 | V14: =U14*(1+PRESUPUESTO!R$7) -> 0 | W14: =V14*(1+PRESUPUESTO!S$7) -> 0 | X14: =W14*(1+PRESUPUESTO!T$7) -> 0
B15: Producto 3 | D15: 0 | F15: 0 | H15: =ROUND($D15*$F15*$D$9*(1+H$9),0) -> 0 | I15: =ROUND($D15*$F15*$D$9*(1+I$9),0) -> 0 | J15: =ROUND($D15*$F15*$D$9*(1+J$9),0) -> 0 | K15: =ROUND($D15*$F15*$D$9*(1+K$9),0) -> 0 | L15: =ROUND($D15*$F15*$D$9*(1+L$9),0) -> 0 | M15: =ROUND($D15*$F15*$D$9*(1+M$9),0) -> 0 | N15: =ROUND($D15*$F15*$D$9*(1+N$9),0) -> 0 | O15: =ROUND($D15*$F15*$D$9*(1+O$9),0) -> 0 | ... S15: =ROUND($D15*$F15*$D$9*(1+S$9),0) -> 0 | T15: =SUM(H15:S15) -> 0 | U15: =T15*(1+PRESUPUESTO!Q$7) -> 0 | V15: =U15*(1+PRESUPUESTO!R$7) -> 0 | W15: =V15*(1+PRESUPUESTO!S$7) -> 0 | X15: =W15*(1+PRESUPUESTO!T$7) -> 0
B16: Producto 4 | D16: 0 | F16: 0 | H16: =ROUND($D16*$F16*$D$9*(1+H$9),0) -> 0 | I16: =ROUND($D16*$F16*$D$9*(1+I$9),0) -> 0 | J16: =ROUND($D16*$F16*$D$9*(1+J$9),0) -> 0 | K16: =ROUND($D16*$F16*$D$9*(1+K$9),0) -> 0 | L16: =ROUND($D16*$F16*$D$9*(1+L$9),0) -> 0 | M16: =ROUND($D16*$F16*$D$9*(1+M$9),0) -> 0 | N16: =ROUND($D16*$F16*$D$9*(1+N$9),0) -> 0 | O16: =ROUND($D16*$F16*$D$9*(1+O$9),0) -> 0 | ... S16: =ROUND($D16*$F16*$D$9*(1+S$9),0) -> 0 | T16: =SUM(H16:S16) -> 0 | U16: =T16*(1+PRESUPUESTO!Q$7) -> 0 | V16: =U16*(1+PRESUPUESTO!R$7) -> 0 | W16: =V16*(1+PRESUPUESTO!S$7) -> 0 | X16: =W16*(1+PRESUPUESTO!T$7) -> 0
B17: Producto 5 | D17: 0 | F17: 0 | H17: =ROUND($D17*$F17*$D$9*(1+H$9),0) -> 0 | I17: =ROUND($D17*$F17*$D$9*(1+I$9),0) -> 0 | J17: =ROUND($D17*$F17*$D$9*(1+J$9),0) -> 0 | K17: =ROUND($D17*$F17*$D$9*(1+K$9),0) -> 0 | L17: =ROUND($D17*$F17*$D$9*(1+L$9),0) -> 0 | M17: =ROUND($D17*$F17*$D$9*(1+M$9),0) -> 0 | N17: =ROUND($D17*$F17*$D$9*(1+N$9),0) -> 0 | O17: =ROUND($D17*$F17*$D$9*(1+O$9),0) -> 0 | ... S17: =ROUND($D17*$F17*$D$9*(1+S$9),0) -> 0 | T17: =SUM(H17:S17) -> 0 | U17: =T17*(1+PRESUPUESTO!Q$7) -> 0 | V17: =U17*(1+PRESUPUESTO!R$7) -> 0 | W17: =V17*(1+PRESUPUESTO!S$7) -> 0 | X17: =W17*(1+PRESUPUESTO!T$7) -> 0
B18: Producto 6 | D18: 0 | F18: 0 | H18: =ROUND($D18*$F18*$D$9*(1+H$9),0) -> 0 | I18: =ROUND($D18*$F18*$D$9*(1+I$9),0) -> 0 | J18: =ROUND($D18*$F18*$D$9*(1+J$9),0) -> 0 | K18: =ROUND($D18*$F18*$D$9*(1+K$9),0) -> 0 | L18: =ROUND($D18*$F18*$D$9*(1+L$9),0) -> 0 | M18: =ROUND($D18*$F18*$D$9*(1+M$9),0) -> 0 | N18: =ROUND($D18*$F18*$D$9*(1+N$9),0) -> 0 | O18: =ROUND($D18*$F18*$D$9*(1+O$9),0) -> 0 | ... S18: =ROUND($D18*$F18*$D$9*(1+S$9),0) -> 0 | T18: =SUM(H18:S18) -> 0 | U18: =T18*(1+PRESUPUESTO!Q$7) -> 0 | V18: =U18*(1+PRESUPUESTO!R$7) -> 0 | W18: =V18*(1+PRESUPUESTO!S$7) -> 0 | X18: =W18*(1+PRESUPUESTO!T$7) -> 0
B19: Producto 7 | D19: 0 | F19: 0 | H19: =ROUND($D19*$F19*$D$9*(1+H$9),0) -> 0 | I19: =ROUND($D19*$F19*$D$9*(1+I$9),0) -> 0 | J19: =ROUND($D19*$F19*$D$9*(1+J$9),0) -> 0 | K19: =ROUND($D19*$F19*$D$9*(1+K$9),0) -> 0 | L19: =ROUND($D19*$F19*$D$9*(1+L$9),0) -> 0 | M19: =ROUND($D19*$F19*$D$9*(1+M$9),0) -> 0 | N19: =ROUND($D19*$F19*$D$9*(1+N$9),0) -> 0 | O19: =ROUND($D19*$F19*$D$9*(1+O$9),0) -> 0 | ... S19: =ROUND($D19*$F19*$D$9*(1+S$9),0) -> 0 | T19: =SUM(H19:S19) -> 0 | U19: =T19*(1+PRESUPUESTO!Q$7) -> 0 | V19: =U19*(1+PRESUPUESTO!R$7) -> 0 | W19: =V19*(1+PRESUPUESTO!S$7) -> 0 | X19: =W19*(1+PRESUPUESTO!T$7) -> 0
B20: Producto 8 | D20: 0 | F20: 0 | H20: =ROUND($D20*$F20*$D$9*(1+H$9),0) -> 0 | I20: =ROUND($D20*$F20*$D$9*(1+I$9),0) -> 0 | J20: =ROUND($D20*$F20*$D$9*(1+J$9),0) -> 0 | K20: =ROUND($D20*$F20*$D$9*(1+K$9),0) -> 0 | L20: =ROUND($D20*$F20*$D$9*(1+L$9),0) -> 0 | M20: =ROUND($D20*$F20*$D$9*(1+M$9),0) -> 0 | N20: =ROUND($D20*$F20*$D$9*(1+N$9),0) -> 0 | O20: =ROUND($D20*$F20*$D$9*(1+O$9),0) -> 0 | ... S20: =ROUND($D20*$F20*$D$9*(1+S$9),0) -> 0 | T20: =SUM(H20:S20) -> 0 | U20: =T20*(1+PRESUPUESTO!Q$7) -> 0 | V20: =U20*(1+PRESUPUESTO!R$7) -> 0 | W20: =V20*(1+PRESUPUESTO!S$7) -> 0 | X20: =W20*(1+PRESUPUESTO!T$7) -> 0
B21: Producto 9 | D21: 0 | F21: 0 | H21: =ROUND($D21*$F21*$D$9*(1+H$9),0) -> 0 | I21: =ROUND($D21*$F21*$D$9*(1+I$9),0) -> 0 | J21: =ROUND($D21*$F21*$D$9*(1+J$9),0) -> 0 | K21: =ROUND($D21*$F21*$D$9*(1+K$9),0) -> 0 | L21: =ROUND($D21*$F21*$D$9*(1+L$9),0) -> 0 | M21: =ROUND($D21*$F21*$D$9*(1+M$9),0) -> 0 | N21: =ROUND($D21*$F21*$D$9*(1+N$9),0) -> 0 | O21: =ROUND($D21*$F21*$D$9*(1+O$9),0) -> 0 | ... S21: =ROUND($D21*$F21*$D$9*(1+S$9),0) -> 0 | T21: =SUM(H21:S21) -> 0 | U21: =T21*(1+PRESUPUESTO!Q$7) -> 0 | V21: =U21*(1+PRESUPUESTO!R$7) -> 0 | W21: =V21*(1+PRESUPUESTO!S$7) -> 0 | X21: =W21*(1+PRESUPUESTO!T$7) -> 0
B22: Producto 10 | D22: 0 | F22: 0 | H22: =ROUND($D22*$F22*$D$9*(1+H$9),0) -> 0 | I22: =ROUND($D22*$F22*$D$9*(1+I$9),0) -> 0 | J22: =ROUND($D22*$F22*$D$9*(1+J$9),0) -> 0 | K22: =ROUND($D22*$F22*$D$9*(1+K$9),0) -> 0 | L22: =ROUND($D22*$F22*$D$9*(1+L$9),0) -> 0 | M22: =ROUND($D22*$F22*$D$9*(1+M$9),0) -> 0 | N22: =ROUND($D22*$F22*$D$9*(1+N$9),0) -> 0 | O22: =ROUND($D22*$F22*$D$9*(1+O$9),0) -> 0 | ... S22: =ROUND($D22*$F22*$D$9*(1+S$9),0) -> 0 | T22: =SUM(H22:S22) -> 0 | U22: =T22*(1+PRESUPUESTO!Q$7) -> 0 | V22: =U22*(1+PRESUPUESTO!R$7) -> 0 | W22: =V22*(1+PRESUPUESTO!S$7) -> 0 | X22: =W22*(1+PRESUPUESTO!T$7) -> 0
B23: Producto 11 | D23: 0 | F23: 0 | H23: =ROUND($D23*$F23*$D$9*(1+H$9),0) -> 0 | I23: =ROUND($D23*$F23*$D$9*(1+I$9),0) -> 0 | J23: =ROUND($D23*$F23*$D$9*(1+J$9),0) -> 0 | K23: =ROUND($D23*$F23*$D$9*(1+K$9),0) -> 0 | L23: =ROUND($D23*$F23*$D$9*(1+L$9),0) -> 0 | M23: =ROUND($D23*$F23*$D$9*(1+M$9),0) -> 0 | N23: =ROUND($D23*$F23*$D$9*(1+N$9),0) -> 0 | O23: =ROUND($D23*$F23*$D$9*(1+O$9),0) -> 0 | ... S23: =ROUND($D23*$F23*$D$9*(1+S$9),0) -> 0 | T23: =SUM(H23:S23) -> 0 | U23: =T23*(1+PRESUPUESTO!Q$7) -> 0 | V23: =U23*(1+PRESUPUESTO!R$7) -> 0 | W23: =V23*(1+PRESUPUESTO!S$7) -> 0 | X23: =W23*(1+PRESUPUESTO!T$7) -> 0
B24: Producto 12 | D24: 0 | F24: 0 | H24: =ROUND($D24*$F24*$D$9*(1+H$9),0) -> 0 | I24: =ROUND($D24*$F24*$D$9*(1+I$9),0) -> 0 | J24: =ROUND($D24*$F24*$D$9*(1+J$9),0) -> 0 | K24: =ROUND($D24*$F24*$D$9*(1+K$9),0) -> 0 | L24: =ROUND($D24*$F24*$D$9*(1+L$9),0) -> 0 | M24: =ROUND($D24*$F24*$D$9*(1+M$9),0) -> 0 | N24: =ROUND($D24*$F24*$D$9*(1+N$9),0) -> 0 | O24: =ROUND($D24*$F24*$D$9*(1+O$9),0) -> 0 | ... S24: =ROUND($D24*$F24*$D$9*(1+S$9),0) -> 0 | T24: =SUM(H24:S24) -> 0 | U24: =T24*(1+PRESUPUESTO!Q$7) -> 0 | V24: =U24*(1+PRESUPUESTO!R$7) -> 0 | W24: =V24*(1+PRESUPUESTO!S$7) -> 0 | X24: =W24*(1+PRESUPUESTO!T$7) -> 0
... B32: Producto 20 | D32: 0 | F32: 0 | H32: =ROUND($D32*$F32*$D$9*(1+H$9),0) -> 0 | I32: =ROUND($D32*$F32*$D$9*(1+I$9),0) -> 0 | J32: =ROUND($D32*$F32*$D$9*(1+J$9),0) -> 0 | K32: =ROUND($D32*$F32*$D$9*(1+K$9),0) -> 0 | L32: =ROUND($D32*$F32*$D$9*(1+L$9),0) -> 0 | M32: =ROUND($D32*$F32*$D$9*(1+M$9),0) -> 0 | N32: =ROUND($D32*$F32*$D$9*(1+N$9),0) -> 0 | O32: =ROUND($D32*$F32*$D$9*(1+O$9),0) -> 0 | ... S32: =ROUND($D32*$F32*$D$9*(1+S$9),0) -> 0 | T32: =SUM(H32:S32) -> 0 | U32: =T32*(1+PRESUPUESTO!Q$7) -> 0 | V32: =U32*(1+PRESUPUESTO!R$7) -> 0 | W32: =V32*(1+PRESUPUESTO!S$7) -> 0 | X32: =W32*(1+PRESUPUESTO!T$7) -> 0
F34: TOTAL | H34: =SUM(H13:H32) -> 0 | I34: =SUM(I13:I32) -> 0 | J34: =SUM(J13:J32) -> 0 | K34: =SUM(K13:K32) -> 0 | L34: =SUM(L13:L32) -> 0 | M34: =SUM(M13:M32) -> 0 | N34: =SUM(N13:N32) -> 0 | O34: =SUM(O13:O32) -> 0 | ... X34: =SUM(X13:X32) -> 0
B37: Con tarjeta | F37: 0 | H37: =H34*$F$37 -> 0 | I37: =I34*$F$37 -> 0 | J37: =J34*$F$37 -> 0 | K37: =K34*$F$37 -> 0 | L37: =L34*$F$37 -> 0 | M37: =M34*$F$37 -> 0 | N37: =N34*$F$37 -> 0 | O37: =O34*$F$37 -> 0 | ... X37: =X34*$F$37 -> 0
B38: Efectivo | F38: 1 | H38: =H34*$F$38 -> 0 | I38: =I34*$F$38 -> 0 | J38: =J34*$F$38 -> 0 | K38: =K34*$F$38 -> 0 | L38: =L34*$F$38 -> 0 | M38: =M34*$F$38 -> 0 | N38: =N34*$F$38 -> 0 | O38: =O34*$F$38 -> 0 | ... X38: =X34*$F$38 -> 0
B39: UTILIDAD BRUTA POR SERVICIOS | F39: =IF(F47=0,100%,0) -> 1 | H39: =IF($F$47>0,0,H34-(H34*$F$39)) -> 0 | I39: =IF($F$47>0,0,I34-(I34*$F$39)) -> 0 | J39: =IF($F$47>0,0,J34-(J34*$F$39)) -> 0 | K39: =IF($F$47>0,0,K34-(K34*$F$39)) -> 0 | L39: =IF($F$47>0,0,L34-(L34*$F$39)) -> 0 | M39: =IF($F$47>0,0,M34-(M34*$F$39)) -> 0 | N39: =IF($F$47>0,0,N34-(N34*$F$39)) -> 0 | O39: =IF($F$47>0,0,O34-(O34*$F$39)) -> 0 | ... S39: =IF($F$47>0,0,S34-(S34*$F$39)) -> 0 | T39: =SUM(H39:S39) -> 0 | U39: =T39*(1+PRESUPUESTO!Q$7) -> 0 | V39: =U39*(1+PRESUPUESTO!R$7) -> 0 | W39: =V39*(1+PRESUPUESTO!S$7) -> 0 | X39: =W39*(1+PRESUPUESTO!T$7) -> 0
B40: UTILIDAD BRUTA POR COSTEO | F40: =F47 -> 0 | H40: =IF($F$47>0,H47,0) -> 0 | I40: =IF($F$47>0,I47,0) -> 0 | J40: =IF($F$47>0,J47,0) -> 0 | K40: =IF($F$47>0,K47,0) -> 0 | L40: =IF($F$47>0,L47,0) -> 0 | M40: =IF($F$47>0,M47,0) -> 0 | N40: =IF($F$47>0,N47,0) -> 0 | O40: =IF($F$47>0,O47,0) -> 0 | ... S40: =IF($F$47>0,S47,0) -> 0 | T40: =SUM(H40:S40) -> 0 | U40: =T40*(1+PRESUPUESTO!Q$7) -> 0 | V40: =U40*(1+PRESUPUESTO!R$7) -> 0 | W40: =V40*(1+PRESUPUESTO!S$7) -> 0 | X40: =W40*(1+PRESUPUESTO!T$7) -> 0
B41: UTILIDAD BRUTA DEFINIDA | F41: =IF(F47>0,F40,F39) -> 1 | H41: =IF(H39>0,H39,H40) -> 0 | I41: =IF(I39>0,I39,I40) -> 0 | J41: =IF(J39>0,J39,J40) -> 0 | K41: =IF(K39>0,K39,K40) -> 0 | L41: =IF(L39>0,L39,L40) -> 0 | M41: =IF(M39>0,M39,M40) -> 0 | N41: =IF(N39>0,N39,N40) -> 0 | O41: =IF(O39>0,O39,O40) -> 0 | ... S41: =IF(S39>0,S39,S40) -> 0 | T41: =SUM(H41:S41) -> 0 | U41: =T41*(1+PRESUPUESTO!Q$7) -> 0 | V41: =U41*(1+PRESUPUESTO!R$7) -> 0 | W41: =V41*(1+PRESUPUESTO!S$7) -> 0 | X41: =W41*(1+PRESUPUESTO!T$7) -> 0
B45: DETALLE COSTEO POR MATERIAS PRIMA
B47: TOTAL COSTOS MATERIAL PRIMAS ---> | F47: =IF(H47>0,(T34-T47)/T34,0) -> 0 | H47: =SUM(H56,H63,H70,H77,H84,H91,H98,H105,H112,H119,H126,H133,H140,H147,H154,H161,H168,H175,H182) -> 0 | I47: =SUM(I56,I63,I70,I77,I84,I91,I98,I105,I112,I119,I126,I133,I140,I147,I154,I161,I168,I175,I182) -> 0 | J47: =SUM(J56,J63,J70,J77,J84,J91,J98,J105,J112,J119,J126,J133,J140,J147,J154,J161,J168,J175,J182) -> 0 | K47: =SUM(K56,K63,K70,K77,K84,K91,K98,K105,K112,K119,K126,K133,K140,K147,K154,K161,K168,K175,K182) -> 0 | L47: =SUM(L56,L63,L70,L77,L84,L91,L98,L105,L112,L119,L126,L133,L140,L147,L154,L161,L168,L175,L182) -> 0 | M47: =SUM(M56,M63,M70,M77,M84,M91,M98,M105,M112,M119,M126,M133,M140,M147,M154,M161,M168,M175,M182) -> 0 | N47: =SUM(N56,N63,N70,N77,N84,N91,N98,N105,N112,N119,N126,N133,N140,N147,N154,N161,N168,N175,N182) -> 0 | O47: =SUM(O56,O63,O70,O77,O84,O91,O98,O105,O112,O119,O126,O133,O140,O147,O154,O161,O168,O175,O182) -> 0 | ... S47: =SUM(S56,S63,S70,S77,S84,S91,S98,S105,S112,S119,S126,S133,S140,S147,S154,S161,S168,S175,S182) -> 0 | T47: =SUM(H47:S47) -> 0
F49: Costo Materia
B50: =B13 -> Producto 1 | D50: =D13 -> 0 | F50: =F13 -> 0
B51: Materia 1 | D51: =D50 -> 0 | H51: =$F51*$D51*$D$9*(1+H$9) -> 0 | I51: =$F51*$D51*$D$9*(1+I$9) -> 0 | J51: =$F51*$D51*$D$9*(1+J$9) -> 0 | K51: =$F51*$D51*$D$9*(1+K$9) -> 0 | L51: =$F51*$D51*$D$9*(1+L$9) -> 0 | M51: =$F51*$D51*$D$9*(1+M$9) -> 0 | N51: =$F51*$D51*$D$9*(1+N$9) -> 0 | O51: =$F51*$D51*$D$9*(1+O$9) -> 0 | ... S51: =$F51*$D51*$D$9*(1+S$9) -> 0
B52: Materia 2 | D52: =D51 -> 0 | H52: =$F52*$D52*$D$9*(1+H$9) -> 0 | I52: =$F52*$D52*$D$9*(1+I$9) -> 0 | J52: =$F52*$D52*$D$9*(1+J$9) -> 0 | K52: =$F52*$D52*$D$9*(1+K$9) -> 0 | L52: =$F52*$D52*$D$9*(1+L$9) -> 0 | M52: =$F52*$D52*$D$9*(1+M$9) -> 0 | N52: =$F52*$D52*$D$9*(1+N$9) -> 0 | O52: =$F52*$D52*$D$9*(1+O$9) -> 0 | ... S52: =$F52*$D52*$D$9*(1+S$9) -> 0
B53: Materia 3 | D53: =D52 -> 0 | H53: =$F53*$D53*$D$9*(1+H$9) -> 0 | I53: =$F53*$D53*$D$9*(1+I$9) -> 0 | J53: =$F53*$D53*$D$9*(1+J$9) -> 0 | K53: =$F53*$D53*$D$9*(1+K$9) -> 0 | L53: =$F53*$D53*$D$9*(1+L$9) -> 0 | M53: =$F53*$D53*$D$9*(1+M$9) -> 0 | N53: =$F53*$D53*$D$9*(1+N$9) -> 0 | O53: =$F53*$D53*$D$9*(1+O$9) -> 0 | ... S53: =$F53*$D53*$D$9*(1+S$9) -> 0
B54: Materia 4 | D54: =D53 -> 0 | H54: =$F54*$D54*$D$9*(1+H$9) -> 0 | I54: =$F54*$D54*$D$9*(1+I$9) -> 0 | J54: =$F54*$D54*$D$9*(1+J$9) -> 0 | K54: =$F54*$D54*$D$9*(1+K$9) -> 0 | L54: =$F54*$D54*$D$9*(1+L$9) -> 0 | M54: =$F54*$D54*$D$9*(1+M$9) -> 0 | N54: =$F54*$D54*$D$9*(1+N$9) -> 0 | O54: =$F54*$D54*$D$9*(1+O$9) -> 0 | ... S54: =$F54*$D54*$D$9*(1+S$9) -> 0
B55: Materia 5 | D55: =D54 -> 0 | H55: =$F55*$D55*$D$9*(1+H$9) -> 0 | I55: =$F55*$D55*$D$9*(1+I$9) -> 0 | J55: =$F55*$D55*$D$9*(1+J$9) -> 0 | K55: =$F55*$D55*$D$9*(1+K$9) -> 0 | L55: =$F55*$D55*$D$9*(1+L$9) -> 0 | M55: =$F55*$D55*$D$9*(1+M$9) -> 0 | N55: =$F55*$D55*$D$9*(1+N$9) -> 0 | O55: =$F55*$D55*$D$9*(1+O$9) -> 0 | ... S55: =$F55*$D55*$D$9*(1+S$9) -> 0
B56: ="MARGEN TOTAL "&B50 -> MARGEN TOTAL Producto 1 | F56: =IFERROR((F50-SUM(F51:F55))/F50,0) -> 0 | H56: =SUM(H51:H55) -> 0 | I56: =SUM(I51:I55) -> 0 | J56: =SUM(J51:J55) -> 0 | K56: =SUM(K51:K55) -> 0 | L56: =SUM(L51:L55) -> 0 | M56: =SUM(M51:M55) -> 0 | N56: =SUM(N51:N55) -> 0 | O56: =SUM(O51:O55) -> 0 | ... S56: =SUM(S51:S55) -> 0
B57: =B14 -> Producto 2 | D57: =D14 -> 0 | F57: =F14 -> 0
B58: Materia 1 | D58: =D57 -> 0 | H58: =$F58*$D58*$D$9*(1+H$9) -> 0 | I58: =$F58*$D58*$D$9*(1+I$9) -> 0 | J58: =$F58*$D58*$D$9*(1+J$9) -> 0 | K58: =$F58*$D58*$D$9*(1+K$9) -> 0 | L58: =$F58*$D58*$D$9*(1+L$9) -> 0 | M58: =$F58*$D58*$D$9*(1+M$9) -> 0 | N58: =$F58*$D58*$D$9*(1+N$9) -> 0 | O58: =$F58*$D58*$D$9*(1+O$9) -> 0 | ... S58: =$F58*$D58*$D$9*(1+S$9) -> 0
B59: Materia 2 | D59: =D58 -> 0 | H59: =$F59*$D59*$D$9*(1+H$9) -> 0 | I59: =$F59*$D59*$D$9*(1+I$9) -> 0 | J59: =$F59*$D59*$D$9*(1+J$9) -> 0 | K59: =$F59*$D59*$D$9*(1+K$9) -> 0 | L59: =$F59*$D59*$D$9*(1+L$9) -> 0 | M59: =$F59*$D59*$D$9*(1+M$9) -> 0 | N59: =$F59*$D59*$D$9*(1+N$9) -> 0 | O59: =$F59*$D59*$D$9*(1+O$9) -> 0 | ... S59: =$F59*$D59*$D$9*(1+S$9) -> 0
B60: Materia 3 | D60: =D59 -> 0 | H60: =$F60*$D60*$D$9*(1+H$9) -> 0 | I60: =$F60*$D60*$D$9*(1+I$9) -> 0 | J60: =$F60*$D60*$D$9*(1+J$9) -> 0 | K60: =$F60*$D60*$D$9*(1+K$9) -> 0 | L60: =$F60*$D60*$D$9*(1+L$9) -> 0 | M60: =$F60*$D60*$D$9*(1+M$9) -> 0 | N60: =$F60*$D60*$D$9*(1+N$9) -> 0 | O60: =$F60*$D60*$D$9*(1+O$9) -> 0 | ... S60: =$F60*$D60*$D$9*(1+S$9) -> 0
B61: Materia 4 | D61: =D60 -> 0 | H61: =$F61*$D61*$D$9*(1+H$9) -> 0 | I61: =$F61*$D61*$D$9*(1+I$9) -> 0 | J61: =$F61*$D61*$D$9*(1+J$9) -> 0 | K61: =$F61*$D61*$D$9*(1+K$9) -> 0 | L61: =$F61*$D61*$D$9*(1+L$9) -> 0 | M61: =$F61*$D61*$D$9*(1+M$9) -> 0 | N61: =$F61*$D61*$D$9*(1+N$9) -> 0 | O61: =$F61*$D61*$D$9*(1+O$9) -> 0 | ... S61: =$F61*$D61*$D$9*(1+S$9) -> 0
B62: Material 5 | D62: =D61 -> 0 | H62: =$F62*$D62*$D$9*(1+H$9) -> 0 | I62: =$F62*$D62*$D$9*(1+I$9) -> 0 | J62: =$F62*$D62*$D$9*(1+J$9) -> 0 | K62: =$F62*$D62*$D$9*(1+K$9) -> 0 | L62: =$F62*$D62*$D$9*(1+L$9) -> 0 | M62: =$F62*$D62*$D$9*(1+M$9) -> 0 | N62: =$F62*$D62*$D$9*(1+N$9) -> 0 | O62: =$F62*$D62*$D$9*(1+O$9) -> 0 | ... S62: =$F62*$D62*$D$9*(1+S$9) -> 0
B63: ="MARGEN TOTAL "&B57 -> MARGEN TOTAL Producto 2 | F63: =IFERROR((F57-SUM(F58:F62))/F57,0) -> 0 | H63: =SUM(H58:H62) -> 0 | I63: =SUM(I58:I62) -> 0 | J63: =SUM(J58:J62) -> 0 | K63: =SUM(K58:K62) -> 0 | L63: =SUM(L58:L62) -> 0 | M63: =SUM(M58:M62) -> 0 | N63: =SUM(N58:N62) -> 0 | O63: =SUM(O58:O62) -> 0 | ... S63: =SUM(S58:S62) -> 0
B64: =B15 -> Producto 3 | D64: =D15 -> 0 | F64: =F15 -> 0
...

Sheet INVERSION
B7: INVERSION POR APERTURA
B9: ACTIVOS
D10: AÑO 0 | E10: AÑO 1 | F10: AÑO 2 | G10: AÑO 3 | H10: AÑO 4 | I10: AÑO 5
B11: * Remodelacion de la Unidad - Costo de obra civil | D11: 0 | E11: =D11/5 -> 0 | F11: =D11/5 -> 0 | G11: =D11/5 -> 0 | H11: =D11/5 -> 0 | I11: =D11/5 -> 0
B12: * Inversion Mesa Trabajo - proyeccion | D12: 0 | E12: =D12/5 -> 0 | F12: =D12/5 -> 0 | G12: =D12/5 -> 0 | H12: =D12/5 -> 0 | I12: =D12/5 -> 0
B13: * Inversion Mesa Fregadero proyeccion | D13: 0 | E13: =D13/5 -> 0 | F13: =D13/5 -> 0 | G13: =D13/5 -> 0 | H13: =D13/5 -> 0 | I13: =D13/5 -> 0
B14: * Inversion Horno Electrico proyeccion | D14: 0 | E14: =D14/5 -> 0 | F14: =D14/5 -> 0 | G14: =D14/5 -> 0 | H14: =D14/5 -> 0 | I14: =D14/5 -> 0
B15: * Inversion Urna Exhibidora proyeccion | D15: 0 | E15: =D15/5 -> 0 | F15: =D15/5 -> 0 | G15: =D15/5 -> 0 | H15: =D15/5 -> 0 | I15: =D15/5 -> 0
B16: * Inversion Enfriador proyeccion | D16: 0 | E16: =D16/5 -> 0 | F16: =D16/5 -> 0 | G16: =D16/5 -> 0 | H16: =D16/5 -> 0 | I16: =D16/5 -> 0
B17: * Inversion Plancha proyeccion | D17: 0 | E17: =D17/5 -> 0 | F17: =D17/5 -> 0 | G17: =D17/5 -> 0 | H17: =D17/5 -> 0 | I17: =D17/5 -> 0
B18: * Inversion Vitrina Refrigerada proyeccion | D18: 0 | E18: =D18/5 -> 0 | F18: =D18/5 -> 0 | G18: =D18/5 -> 0 | H18: =D18/5 -> 0 | I18: =D18/5 -> 0
B19: * Equipo Computo - punto de venta - COMPRA | D19: 0 | E19: =D19/5 -> 0 | F19: =D19/5 -> 0 | G19: =D19/5 -> 0 | H19: =D19/5 -> 0 | I19: =D19/5 -> 0
B20: Activo 10 | D20: 0 | E20: =D20/5 -> 0 | F20: =D20/5 -> 0 | G20: =D20/5 -> 0 | H20: =D20/5 -> 0 | I20: =D20/5 -> 0
B21: Activo 11 | D21: 0 | E21: =D21/5 -> 0 | F21: =D21/5 -> 0 | G21: =D21/5 -> 0 | H21: =D21/5 -> 0 | I21: =D21/5 -> 0
B22: Activo 12 | D22: 0 | E22: =D22/5 -> 0 | F22: =D22/5 -> 0 | G22: =D22/5 -> 0 | H22: =D22/5 -> 0 | I22: =D22/5 -> 0
B23: Activo 13 | D23: 0 | E23: =D23/5 -> 0 | F23: =D23/5 -> 0 | G23: =D23/5 -> 0 | H23: =D23/5 -> 0 | I23: =D23/5 -> 0
B24: Activo 14 | E24: =D24/5 -> 0 | F24: =D24/5 -> 0 | G24: =D24/5 -> 0 | H24: =D24/5 -> 0 | I24: =D24/5 -> 0
B25: Activo 15 | E25: =D25/5 -> 0 | F25: =D25/5 -> 0 | G25: =D25/5 -> 0 | H25: =D25/5 -> 0 | I25: =D25/5 -> 0
B26: TOTAL ACTIVOS | D26: =SUM(D11:D25) -> 0 | E26: =SUM(E11:E25) -> 0 | F26: =SUM(F11:F25) -> 0 | G26: =SUM(G11:G25) -> 0 | H26: =SUM(H11:H25) -> 0 | I26: =SUM(I11:I25) -> 0
B28: OTROS INVERSIÓN INICIAL APERTURA
B30: * Rotulacion exterior REAL | D30: 0 | E30: =D30/5 -> 0 | F30: =D30/5 -> 0 | G30: =D30/5 -> 0 | H30: =D30/5 -> 0 | I30: =D30/5 -> 0
B31: * Gastos de Apertura (Marketing) REAL | D31: 0 | E31: =D31/5 -> 0 | F31: =D31/5 -> 0 | G31: =D31/5 -> 0 | H31: =D31/5 -> 0 | I31: =D31/5 -> 0
B32: * Otros gastos de Apertura (Licencias, Permisos y Renta, Dep. Inicial) | D32: 0 | E32: =D32/5 -> 0 | F32: =D32/5 -> 0 | G32: =D32/5 -> 0 | H32: =D32/5 -> 0 | I32: =D32/5 -> 0
B33: Gasto 4 | D33: 0 | E33: =D33/5 -> 0 | F33: =D33/5 -> 0 | G33: =D33/5 -> 0 | H33: =D33/5 -> 0 | I33: =D33/5 -> 0
B34: Gasto 5 | D34: 0 | E34: =D34/5 -> 0 | F34: =D34/5 -> 0 | G34: =D34/5 -> 0 | H34: =D34/5 -> 0 | I34: =D34/5 -> 0
B35: Gasto 6 | D35: 0 | E35: =D35/5 -> 0 | F35: =D35/5 -> 0 | G35: =D35/5 -> 0 | H35: =D35/5 -> 0 | I35: =D35/5 -> 0
B36: Gasto 7 | D36: 0 | E36: =D36/5 -> 0 | F36: =D36/5 -> 0 | G36: =D36/5 -> 0 | H36: =D36/5 -> 0 | I36: =D36/5 -> 0
E37: =D37/5 -> 0 | F37: =D37/5 -> 0 | G37: =D37/5 -> 0 | H37: =D37/5 -> 0 | I37: =D37/5 -> 0
B38: TOTAL GASTOS APERTURA | D38: =SUM(D26:D36) -> 0 | E38: =SUM(E26:E36) -> 0 | F38: =SUM(F26:F36) -> 0 | G38: =SUM(G26:G36) -> 0 | H38: =SUM(H26:H36) -> 0 | I38: =SUM(I26:I36) -> 0
B40: % de Interés para financiemiento Equipo Apertura (5 años) | D40: 0.18
B41: Monto de Pago Mensual proyectado para inversión Equipo Apertura | D41: =D38*(1/((1-(1+(D40/12))^-60)/(D40/12))) -> 0
D63: =SUM(CONCLUSIONES!D36:D50) -> 0

Sheet GASTOS
B7: DETALLE GASTOS
B9: GASTOS | D9: Base | F9: Mes 1 | G9: Mes 2 | H9: Mes 3 | I9: Mes 4 | J9: Mes 5 | K9: Mes 6 | L9: Mes 7 | M9: Mes 8 | N9: Mes 9 | O9: Mes 10 | P9: Mes 11 | Q9: Mes 12 | R9: AÑO 1 | S9: AÑO 2 | T9: AÑO 3 | U9: AÑO 4 | V9: AÑO 5 | X9: % MES/VENTAS | Y9: % AÑO/VENTAS | Z9: % MES/GASTOS | AA9: % AÑO/GASTOS
B11: GASTOS OPERACION MENSUAL | F11: Mes 1 | G11: Mes 2 | H11: Mes 3 | I11: Mes 4 | J11: Mes 5 | K11: Mes 6 | L11: Mes 7 | M11: Mes 8 | N11: Mes 9 | O11: Mes 10 | P11: Mes 11 | Q11: Mes 12 | R11: AÑO 1 | S11: AÑO 2 | T11: AÑO 3 | U11: AÑO 4 | V11: AÑO 5
B13: Salarios | D13: 0 | F13: =D13 -> 0 | G13: =F13 -> 0 | H13: =G13 -> 0 | I13: =H13 -> 0 | J13: =I13 -> 0 | K13: =J13 -> 0 | L13: =K13 -> 0 | M13: =L13 -> 0 | N13: =M13 -> 0 | ... Q13: =P13 -> 0 | R13: =SUM(F13:Q13) -> 0 | S13: =R13*(1+PRESUPUESTO!$Q$8) -> 0 | T13: =S13*(1+PRESUPUESTO!$Q$8) -> 0 | U13: =T13*(1+PRESUPUESTO!$Q$8) -> 0 | V13: =U13*(1+PRESUPUESTO!$Q$8) -> 0 | X13: =F13/VENTAS!$H$34 -> #DIV/0! | Y13: =R13/VENTAS!$T$34 -> #DIV/0! | Z13: =F13/$F$60 -> #DIV/0! | AA13: =R13/$R$60 -> #DIV/0!
B14: * Cargas Sociales (28% - CCSS y INS-RT) | D14: =(D13)*0.28 -> 0 | F14: =D14 -> 0 | G14: =F14 -> 0 | H14: =G14 -> 0 | I14: =H14 -> 0 | J14: =I14 -> 0 | K14: =J14 -> 0 | L14: =K14 -> 0 | M14: =L14 -> 0 | N14: =M14 -> 0 | ... Q14: =P14 -> 0 | R14: =SUM(F14:Q14) -> 0 | S14: =R14*(1+PRESUPUESTO!$Q$8) -> 0 | T14: =S14*(1+PRESUPUESTO!$Q$8) -> 0 | U14: =T14*(1+PRESUPUESTO!$Q$8) -> 0 | V14: =U14*(1+PRESUPUESTO!$Q$8) -> 0 | X14: =F14/VENTAS!$H$34 -> #DIV/0! | Y14: =R14/VENTAS!$T$34 -> #DIV/0! | Z14: =F14/$F$60 -> #DIV/0! | AA14: =R14/$R$60 -> #DIV/0!
B15: * Aguinaldo (8.33%) | D15: =(D13)*0.0833 -> 0 | F15: =D15 -> 0 | G15: =F15 -> 0 | H15: =G15 -> 0 | I15: =H15 -> 0 | J15: =I15 -> 0 | K15: =J15 -> 0 | L15: =K15 -> 0 | M15: =L15 -> 0 | N15: =M15 -> 0 | ... Q15: =P15 -> 0 | R15: =SUM(F15:Q15) -> 0 | S15: =R15*(1+PRESUPUESTO!$Q$8) -> 0 | T15: =S15*(1+PRESUPUESTO!$Q$8) -> 0 | U15: =T15*(1+PRESUPUESTO!$Q$8) -> 0 | V15: =U15*(1+PRESUPUESTO!$Q$8) -> 0 | X15: =F15/VENTAS!$H$34 -> #DIV/0! | Y15: =R15/VENTAS!$T$34 -> #DIV/0! | Z15: =F15/$F$60 -> #DIV/0! | AA15: =R15/$R$60 -> #DIV/0!
B16: * Vacaciones (4.15%) | D16: =(D13)*0.0415 -> 0 | F16: =D16 -> 0 | G16: =F16 -> 0 | H16: =G16 -> 0 | I16: =H16 -> 0 | J16: =I16 -> 0 | K16: =J16 -> 0 | L16: =K16 -> 0 | M16: =L16 -> 0 | N16: =M16 -> 0 | ... Q16: =P16 -> 0 | R16: =SUM(F16:Q16) -> 0 | S16: =R16*(1+PRESUPUESTO!$Q$8) -> 0 | T16: =S16*(1+PRESUPUESTO!$Q$8) -> 0 | U16: =T16*(1+PRESUPUESTO!$Q$8) -> 0 | V16: =U16*(1+PRESUPUESTO!$Q$8) -> 0 | X16: =F16/VENTAS!$H$34 -> #DIV/0! | Y16: =R16/VENTAS!$T$34 -> #DIV/0! | Z16: =F16/$F$60 -> #DIV/0! | AA16: =R16/$R$60 -> #DIV/0!
B17: * Prestaciones Legales (10%) | D17: =(D13)*0.1 -> 0 | F17: =D17 -> 0 | G17: =F17 -> 0 | H17: =G17 -> 0 | I17: =H17 -> 0 | J17: =I17 -> 0 | K17: =J17 -> 0 | L17: =K17 -> 0 | M17: =L17 -> 0 | N17: =M17 -> 0 | ... Q17: =P17 -> 0 | R17: =SUM(F17:Q17) -> 0 | S17: =R17*(1+PRESUPUESTO!$Q$8) -> 0 | T17: =S17*(1+PRESUPUESTO!$Q$8) -> 0 | U17: =T17*(1+PRESUPUESTO!$Q$8) -> 0 | V17: =U17*(1+PRESUPUESTO!$Q$8) -> 0 | X17: =F17/VENTAS!$H$34 -> #DIV/0! | Y17: =R17/VENTAS!$T$34 -> #DIV/0! | Z17: =F17/$F$60 -> #DIV/0! | AA17: =R17/$R$60 -> #DIV/0!
B18: * Combustible | D18: 0 | F18: =D18 -> 0 | G18: =F18 -> 0 | H18: =G18 -> 0 | I18: =H18 -> 0 | J18: =I18 -> 0 | K18: =J18 -> 0 | L18: =K18 -> 0 | M18: =L18 -> 0 | N18: =M18 -> 0 | ... Q18: =P18 -> 0 | R18: =SUM(F18:Q18) -> 0 | S18: =R18*(1+PRESUPUESTO!$Q$8) -> 0 | T18: =S18*(1+PRESUPUESTO!$Q$8) -> 0 | U18: =T18*(1+PRESUPUESTO!$Q$8) -> 0 | V18: =U18*(1+PRESUPUESTO!$Q$8) -> 0 | X18: =F18/VENTAS!$H$34 -> #DIV/0! | Y18: =R18/VENTAS!$T$34 -> #DIV/0! | Z18: =F18/$F$60 -> #DIV/0! | AA18: =R18/$R$60 -> #DIV/0!
B19: * Mantenimiento Vehículos (Seguros/Mantenimiento/RTV/Marchamo) | D19: 0 | F19: =D19 -> 0 | G19: =F19 -> 0 | H19: =G19 -> 0 | I19: =H19 -> 0 | J19: =I19 -> 0 | K19: =J19 -> 0 | L19: =K19 -> 0 | M19: =L19 -> 0 | N19: =M19 -> 0 | ... Q19: =P19 -> 0 | R19: =SUM(F19:Q19) -> 0 | S19: =R19*(1+PRESUPUESTO!$Q$8) -> 0 | T19: =S19*(1+PRESUPUESTO!$Q$8) -> 0 | U19: =T19*(1+PRESUPUESTO!$Q$8) -> 0 | V19: =U19*(1+PRESUPUESTO!$Q$8) -> 0 | X19: =F19/VENTAS!$H$34 -> #DIV/0! | Y19: =R19/VENTAS!$T$34 -> #DIV/0! | Z19: =F19/$F$60 -> #DIV/0! | AA19: =R19/$R$60 -> #DIV/0!
B20: * Agua | D20: 0 | F20: =D20 -> 0 | G20: =F20 -> 0 | H20: =G20 -> 0 | I20: =H20 -> 0 | J20: =I20 -> 0 | K20: =J20 -> 0 | L20: =K20 -> 0 | M20: =L20 -> 0 | N20: =M20 -> 0 | ... Q20: =P20 -> 0 | R20: =SUM(F20:Q20) -> 0 | S20: =R20*(1+PRESUPUESTO!$Q$8) -> 0 | T20: =S20*(1+PRESUPUESTO!$Q$8) -> 0 | U20: =T20*(1+PRESUPUESTO!$Q$8) -> 0 | V20: =U20*(1+PRESUPUESTO!$Q$8) -> 0 | X20: =F20/VENTAS!$H$34 -> #DIV/0! | Y20: =R20/VENTAS!$T$34 -> #DIV/0! | Z20: =F20/$F$60 -> #DIV/0! | AA20: =R20/$R$60 -> #DIV/0!
B21: * Luz | D21: 0 | F21: =D21 -> 0 | G21: =F21 -> 0 | H21: =G21 -> 0 | I21: =H21 -> 0 | J21: =I21 -> 0 | K21: =J21 -> 0 | L21: =K21 -> 0 | M21: =L21 -> 0 | N21: =M21 -> 0 | ... Q21: =P21 -> 0 | R21: =SUM(F21:Q21) -> 0 | S21: =R21*(1+PRESUPUESTO!$Q$8) -> 0 | T21: =S21*(1+PRESUPUESTO!$Q$8) -> 0 | U21: =T21*(1+PRESUPUESTO!$Q$8) -> 0 | V21: =U21*(1+PRESUPUESTO!$Q$8) -> 0 | X21: =F21/VENTAS!$H$34 -> #DIV/0! | Y21: =R21/VENTAS!$T$34 -> #DIV/0! | Z21: =F21/$F$60 -> #DIV/0! | AA21: =R21/$R$60 -> #DIV/0!
B22: * Telefono | D22: 0 | F22: =D22 -> 0 | G22: =F22 -> 0 | H22: =G22 -> 0 | I22: =H22 -> 0 | J22: =I22 -> 0 | K22: =J22 -> 0 | L22: =K22 -> 0 | M22: =L22 -> 0 | N22: =M22 -> 0 | ... Q22: =P22 -> 0 | R22: =SUM(F22:Q22) -> 0 | S22: =R22*(1+PRESUPUESTO!$Q$8) -> 0 | T22: =S22*(1+PRESUPUESTO!$Q$8) -> 0 | U22: =T22*(1+PRESUPUESTO!$Q$8) -> 0 | V22: =U22*(1+PRESUPUESTO!$Q$8) -> 0 | X22: =F22/VENTAS!$H$34 -> #DIV/0! | Y22: =R22/VENTAS!$T$34 -> #DIV/0! | Z22: =F22/$F$60 -> #DIV/0! | AA22: =R22/$R$60 -> #DIV/0!
B23: * Internet | D23: 0 | F23: =D23 -> 0 | G23: =F23 -> 0 | H23: =G23 -> 0 | I23: =H23 -> 0 | J23: =I23 -> 0 | K23: =J23 -> 0 | L23: =K23 -> 0 | M23: =L23 -> 0 | N23: =M23 -> 0 | ... Q23: =P23 -> 0 | R23: =SUM(F23:Q23) -> 0 | S23: =R23*(1+PRESUPUESTO!$Q$8) -> 0 | T23: =S23*(1+PRESUPUESTO!$Q$8) -> 0 | U23: =T23*(1+PRESUPUESTO!$Q$8) -> 0 | V23: =U23*(1+PRESUPUESTO!$Q$8) -> 0 | X23: =F23/VENTAS!$H$34 -> #DIV/0! | Y23: =R23/VENTAS!$T$34 -> #DIV/0! | Z23: =F23/$F$60 -> #DIV/0! | AA23: =R23/$R$60 -> #DIV/0!
B24: * Alquiler Local | D24: 0 | F24: =D24 -> 0 | G24: =F24 -> 0 | H24: =G24 -> 0 | I24: =H24 -> 0 | J24: =I24 -> 0 | K24: =J24 -> 0 | L24: =K24 -> 0 | M24: =L24 -> 0 | N24: =M24 -> 0 | ... Q24: =P24 -> 0 | R24: =SUM(F24:Q24) -> 0 | S24: =R24*(1+PRESUPUESTO!$Q$8) -> 0 | T24: =S24*(1+PRESUPUESTO!$Q$8) -> 0 | U24: =T24*(1+PRESUPUESTO!$Q$8) -> 0 | V24: =U24*(1+PRESUPUESTO!$Q$8) -> 0 | X24: =F24/VENTAS!$H$34 -> #DIV/0! | Y24: =R24/VENTAS!$T$34 -> #DIV/0! | Z24: =F24/$F$60 -> #DIV/0! | AA24: =R24/$R$60 -> #DIV/0!
B25: * Instalación y Mant. Equipo | D25: 0 | F25: =D25 -> 0 | G25: =F25 -> 0 | H25: =G25 -> 0 | I25: =H25 -> 0 | J25: =I25 -> 0 | K25: =J25 -> 0 | L25: =K25 -> 0 | M25: =L25 -> 0 | N25: =M25 -> 0 | ... Q25: =P25 -> 0 | R25: =SUM(F25:Q25) -> 0 | S25: =R25*(1+PRESUPUESTO!$Q$8) -> 0 | T25: =S25*(1+PRESUPUESTO!$Q$8) -> 0 | U25: =T25*(1+PRESUPUESTO!$Q$8) -> 0 | V25: =U25*(1+PRESUPUESTO!$Q$8) -> 0 | X25: =F25/VENTAS!$H$34 -> #DIV/0! | Y25: =R25/VENTAS!$T$34 -> #DIV/0! | Z25: =F25/$F$60 -> #DIV/0! | AA25: =R25/$R$60 -> #DIV/0!
B26: * Instalación y Mant. Local | D26: 0 | F26: =D26 -> 0 | G26: =F26 -> 0 | H26: =G26 -> 0 | I26: =H26 -> 0 | J26: =I26 -> 0 | K26: =J26 -> 0 | L26: =K26 -> 0 | M26: =L26 -> 0 | N26: =M26 -> 0 | ... Q26: =P26 -> 0 | R26: =SUM(F26:Q26) -> 0 | S26: =R26*(1+PRESUPUESTO!$Q$8) -> 0 | T26: =S26*(1+PRESUPUESTO!$Q$8) -> 0 | U26: =T26*(1+PRESUPUESTO!$Q$8) -> 0 | V26: =U26*(1+PRESUPUESTO!$Q$8) -> 0 | X26: =F26/VENTAS!$H$34 -> #DIV/0! | Y26: =R26/VENTAS!$T$34 -> #DIV/0! | Z26: =F26/$F$60 -> #DIV/0! | AA26: =R26/$R$60 -> #DIV/0!
B27: * Servicios Contables | D27: 0 | F27: =D27 -> 0 | G27: =F27 -> 0 | H27: =G27 -> 0 | I27: =H27 -> 0 | J27: =I27 -> 0 | K27: =J27 -> 0 | L27: =K27 -> 0 | M27: =L27 -> 0 | N27: =M27 -> 0 | ... Q27: =P27 -> 0 | R27: =SUM(F27:Q27) -> 0 | S27: =R27*(1+PRESUPUESTO!$Q$8) -> 0 | T27: =S27*(1+PRESUPUESTO!$Q$8) -> 0 | U27: =T27*(1+PRESUPUESTO!$Q$8) -> 0 | V27: =U27*(1+PRESUPUESTO!$Q$8) -> 0 | X27: =F27/VENTAS!$H$34 -> #DIV/0! | Y27: =R27/VENTAS!$T$34 -> #DIV/0! | Z27: =F27/$F$60 -> #DIV/0! | AA27: =R27/$R$60 -> #DIV/0!
B28: * Seguridad - Alarmas | D28: 0 | F28: =D28 -> 0 | G28: =F28 -> 0 | H28: =G28 -> 0 | I28: =H28 -> 0 | J28: =I28 -> 0 | K28: =J28 -> 0 | L28: =K28 -> 0 | M28: =L28 -> 0 | N28: =M28 -> 0 | ... Q28: =P28 -> 0 | R28: =SUM(F28:Q28) -> 0 | S28: =R28*(1+PRESUPUESTO!$Q$8) -> 0 | T28: =S28*(1+PRESUPUESTO!$Q$8) -> 0 | U28: =T28*(1+PRESUPUESTO!$Q$8) -> 0 | V28: =U28*(1+PRESUPUESTO!$Q$8) -> 0 | X28: =F28/VENTAS!$H$34 -> #DIV/0! | Y28: =R28/VENTAS!$T$34 -> #DIV/0! | Z28: =F28/$F$60 -> #DIV/0! | AA28: =R28/$R$60 -> #DIV/0!
B29: * Equipo Software ERP - CRM | D29: 0 | F29: =D29 -> 0 | G29: =F29 -> 0 | H29: =G29 -> 0 | I29: =H29 -> 0 | J29: =I29 -> 0 | K29: =J29 -> 0 | L29: =K29 -> 0 | M29: =L29 -> 0 | N29: =M29 -> 0 | ... Q29: =P29 -> 0 | R29: =SUM(F29:Q29) -> 0 | S29: =R29*(1+PRESUPUESTO!$Q$8) -> 0 | T29: =S29*(1+PRESUPUESTO!$Q$8) -> 0 | U29: =T29*(1+PRESUPUESTO!$Q$8) -> 0 | V29: =U29*(1+PRESUPUESTO!$Q$8) -> 0 | X29: =F29/VENTAS!$H$34 -> #DIV/0! | Y29: =R29/VENTAS!$T$34 -> #DIV/0! | Z29: =F29/$F$60 -> #DIV/0! | AA29: =R29/$R$60 -> #DIV/0!
... B37: * Otros Gastos | D37: 0 | F37: =D37 -> 0 | G37: =F37 -> 0 | H37: =G37 -> 0 | I37: =H37 -> 0 | J37: =I37 -> 0 | K37: =J37 -> 0 | L37: =K37 -> 0 | M37: =L37 -> 0 | N37: =M37 -> 0 | ... Q37: =P37 -> 0 | R37: =SUM(F37:Q37) -> 0 | S37: =R37*(1+PRESUPUESTO!$Q$8) -> 0 | T37: =S37*(1+PRESUPUESTO!$Q$8) -> 0 | U37: =T37*(1+PRESUPUESTO!$Q$8) -> 0 | V37: =U37*(1+PRESUPUESTO!$Q$8) -> 0 | X37: =F37/VENTAS!$H$34 -> #DIV/0! | Y37: =R37/VENTAS!$T$34 -> #DIV/0! | Z37: =F37/$F$60 -> #DIV/0! | AA37: =R37/$R$60 -> #DIV/0!
B38: TOTAL OPERACIÓN MENSUAL | D38: =SUM(D13:D37) -> 0 | F38: =SUM(F13:F37) -> 0 | G38: =SUM(G13:G37) -> 0 | H38: =SUM(H13:H37) -> 0 | I38: =SUM(I13:I37) -> 0 | J38: =SUM(J13:J37) -> 0 | K38: =SUM(K13:K37) -> 0 | L38: =SUM(L13:L37) -> 0 | M38: =SUM(M13:M37) -> 0 | ... V38: =SUM(V13:V37) -> 0 | X38: =F38/VENTAS!$H$34 -> #DIV/0! | Y38: =R38/VENTAS!$T$34 -> #DIV/0! | Z38: =F38/$F$60 -> #DIV/0! | AA38: =R38/$R$60 -> #DIV/0!
B41: OTROS GASTOS | F41: Mes 1 | G41: Mes 2 | H41: Mes 3 | I41: Mes 4 | J41: Mes 5 | K41: Mes 6 | L41: Mes 7 | M41: Mes 8 | N41: Mes 9 | O41: Mes 10 | P41: Mes 11 | Q41: Mes 12 | R41: AÑO 1 | S41: AÑO 2 | T41: AÑO 3 | U41: AÑO 4 | V41: AÑO 5
B43: * Gastos por Publicidad y Mercadeo (1% s/vtas) | D43: 0.01 | F43: =VENTAS!H$34*$D$43 -> 0 | G43: =VENTAS!I$34*$D$43 -> 0 | H43: =VENTAS!J$34*$D$43 -> 0 | I43: =VENTAS!K$34*$D$43 -> 0 | J43: =VENTAS!L$34*$D$43 -> 0 | K43: =VENTAS!M$34*$D$43 -> 0 | L43: =VENTAS!N$34*$D$43 -> 0 | M43: =VENTAS!O$34*$D$43 -> 0 | ... Q43: =VENTAS!S$34*$D$43 -> 0 | R43: =SUM(F43:Q43) -> 0 | S43: =R43*(1+PRESUPUESTO!$Q$8) -> 0 | T43: =S43*(1+PRESUPUESTO!$Q$8) -> 0 | U43: =T43*(1+PRESUPUESTO!$Q$8) -> 0 | V43: =U43*(1+PRESUPUESTO!$Q$8) -> 0
B44: * Gastos Imprevistos de Operación (1% s/Vtas)(Taxis, Viaticos y Gastos Menores) | D44: 0.01 | F44: =VENTAS!H$34*$D$44 -> 0 | G44: =VENTAS!I$34*$D$44 -> 0 | H44: =VENTAS!J$34*$D$44 -> 0 | I44: =VENTAS!K$34*$D$44 -> 0 | J44: =VENTAS!L$34*$D$44 -> 0 | K44: =VENTAS!M$34*$D$44 -> 0 | L44: =VENTAS!N$34*$D$44 -> 0 | M44: =VENTAS!O$34*$D$44 -> 0 | ... Q44: =VENTAS!S$34*$D$44 -> 0 | R44: =SUM(F44:Q44) -> 0 | S44: =R44*(1+PRESUPUESTO!$Q$8) -> 0 | T44: =S44*(1+PRESUPUESTO!$Q$8) -> 0 | U44: =T44*(1+PRESUPUESTO!$Q$8) -> 0 | V44: =U44*(1+PRESUPUESTO!$Q$8) -> 0
B45: * Estimación de Gtos x Empaque (5%) s/Vtas | D45: 0.05 | F45: =VENTAS!H$34*$D$45 -> 0 | G45: =VENTAS!I$34*$D$45 -> 0 | H45: =VENTAS!J$34*$D$45 -> 0 | I45: =VENTAS!K$34*$D$45 -> 0 | J45: =VENTAS!L$34*$D$45 -> 0 | K45: =VENTAS!M$34*$D$45 -> 0 | L45: =VENTAS!N$34*$D$45 -> 0 | M45: =VENTAS!O$34*$D$45 -> 0 | ... Q45: =VENTAS!S$34*$D$45 -> 0 | R45: =SUM(F45:Q45) -> 0 | S45: =R45*(1+PRESUPUESTO!$Q$8) -> 0 | T45: =S45*(1+PRESUPUESTO!$Q$8) -> 0 | U45: =T45*(1+PRESUPUESTO!$Q$8) -> 0 | V45: =U45*(1+PRESUPUESTO!$Q$8) -> 0
B46: * Otros Gastos | F46: =VENTAS!H$34*$D$46 -> 0 | G46: =VENTAS!I$34*$D$46 -> 0 | H46: =VENTAS!J$34*$D$46 -> 0 | I46: =VENTAS!K$34*$D$46 -> 0 | J46: =VENTAS!L$34*$D$46 -> 0 | K46: =VENTAS!M$34*$D$46 -> 0 | L46: =VENTAS!N$34*$D$46 -> 0 | M46: =VENTAS!O$34*$D$46 -> 0 | ... Q46: =VENTAS!S$34*$D$46 -> 0 | R46: =SUM(F46:Q46) -> 0 | S46: =R46*(1+PRESUPUESTO!$Q$8) -> 0 | T46: =S46*(1+PRESUPUESTO!$Q$8) -> 0 | U46: =T46*(1+PRESUPUESTO!$Q$8) -> 0 | V46: =U46*(1+PRESUPUESTO!$Q$8) -> 0
B47: * Otros Gastos | F47: =VENTAS!H$34*$D$47 -> 0 | G47: =VENTAS!I$34*$D$47 -> 0 | H47: =VENTAS!J$34*$D$47 -> 0 | I47: =VENTAS!K$34*$D$47 -> 0 | J47: =VENTAS!L$34*$D$47 -> 0 | K47: =VENTAS!M$34*$D$47 -> 0 | L47: =VENTAS!N$34*$D$47 -> 0 | M47: =VENTAS!O$34*$D$47 -> 0 | ... Q47: =VENTAS!S$34*$D$47 -> 0 | R47: =SUM(F47:Q47) -> 0 | S47: =R47*(1+PRESUPUESTO!$Q$8) -> 0 | T47: =S47*(1+PRESUPUESTO!$Q$8) -> 0 | U47: =T47*(1+PRESUPUESTO!$Q$8) -> 0 | V47: =U47*(1+PRESUPUESTO!$Q$8) -> 0
B48: TOTAL OTROS GASTOS | F48: =SUM(F43:F47) -> 0 | G48: =SUM(G43:G47) -> 0 | H48: =SUM(H43:H47) -> 0 | I48: =SUM(I43:I47) -> 0 | J48: =SUM(J43:J47) -> 0 | K48: =SUM(K43:K47) -> 0 | L48: =SUM(L43:L47) -> 0 | M48: =SUM(M43:M47) -> 0 | ... V48: =SUM(V43:V47) -> 0 | X48: =F48/VENTAS!$H$34 -> #DIV/0! | Y48: =R48/VENTAS!$T$34 -> #DIV/0! | Z48: =F48/$F$60 -> #DIV/0! | AA48: =R48/$R$60 -> #DIV/0!
B51: GASTOS FINANCIEROS | F51: Mes 1 | G51: Mes 2 | H51: Mes 3 | I51: Mes 4 | J51: Mes 5 | K51: Mes 6 | L51: Mes 7 | M51: Mes 8 | N51: Mes 9 | O51: Mes 10 | P51: Mes 11 | Q51: Mes 12 | R51: AÑO 1 | S51: AÑO 2 | T51: AÑO 3 | U51: AÑO 4 | V51: AÑO 5
B53: Créditos / Comisiones | D53: =INVERSION!D41 -> 0 | F53: =D53 -> 0 | G53: =F53 -> 0 | H53: =G53 -> 0 | I53: =H53 -> 0 | J53: =I53 -> 0 | K53: =J53 -> 0 | L53: =K53 -> 0 | M53: =L53 -> 0 | N53: =M53 -> 0 | ... Q53: =P53 -> 0 | R53: =SUM(F53:Q53) -> 0 | S53: =R53*(1+PRESUPUESTO!$Q$8) -> 0 | T53: =S53*(1+PRESUPUESTO!$Q$8) -> 0 | U53: =T53*(1+PRESUPUESTO!$Q$8) -> 0 | V53: =U53*(1+PRESUPUESTO!$Q$8) -> 0
B54: Otros Financieros | D54: 0 | F54: =D54 -> 0 | G54: =+F54 -> 0 | H54: =+G54 -> 0 | I54: =+H54 -> 0 | J54: =+I54 -> 0 | K54: =+J54 -> 0 | L54: =+K54 -> 0 | M54: =+L54 -> 0 | N54: =+M54 -> 0 | ... Q54: =+P54 -> 0 | R54: =SUM(F54:Q54) -> 0 | S54: =R54*(1+PRESUPUESTO!$Q$8) -> 0 | T54: =S54*(1+PRESUPUESTO!$Q$8) -> 0 | U54: =T54*(1+PRESUPUESTO!$Q$8) -> 0 | V54: =U54*(1+PRESUPUESTO!$Q$8) -> 0
B55: Caja Chica | D55: 0 | F55: =D55 -> 0 | G55: =F55 -> 0 | H55: =G55 -> 0 | I55: =H55 -> 0 | J55: =I55 -> 0 | K55: =J55 -> 0 | L55: =K55 -> 0 | M55: =L55 -> 0 | N55: =M55 -> 0 | ... Q55: =P55 -> 0 | R55: =SUM(F55:Q55) -> 0 | S55: =R55*(1+PRESUPUESTO!$Q$8) -> 0 | T55: =S55*(1+PRESUPUESTO!$Q$8) -> 0 | U55: =T55*(1+PRESUPUESTO!$Q$8) -> 0 | V55: =U55*(1+PRESUPUESTO!$Q$8) -> 0
B56: Gastos Tarjetas ( 5% ) Comisión estimada del % de las ventas | D56: 0.05 | F56: =VENTAS!H37*$D$56 -> 0 | G56: =VENTAS!I37*$D$56 -> 0 | H56: =VENTAS!J37*$D$56 -> 0 | I56: =VENTAS!K37*$D$56 -> 0 | J56: =VENTAS!L37*$D$56 -> 0 | K56: =VENTAS!M37*$D$56 -> 0 | L56: =VENTAS!N37*$D$56 -> 0 | M56: =VENTAS!O37*$D$56 -> 0 | ... Q56: =VENTAS!S37*$D$56 -> 0 | R56: =SUM(F56:Q56) -> 0 | S56: =R56*(1+PRESUPUESTO!$Q$8) -> 0 | T56: =S56*(1+PRESUPUESTO!$Q$8) -> 0 | U56: =T56*(1+PRESUPUESTO!$Q$8) -> 0 | V56: =U56*(1+PRESUPUESTO!$Q$8) -> 0
B57: Otros Gastos Financieros | F57: =D57 -> 0 | G57: =F57 -> 0 | H57: =G57 -> 0 | I57: =H57 -> 0 | J57: =I57 -> 0 | K57: =J57 -> 0 | L57: =K57 -> 0 | M57: =L57 -> 0 | N57: =M57 -> 0 | ... Q57: =P57 -> 0 | R57: =SUM(F57:Q57) -> 0 | S57: =R57*(1+PRESUPUESTO!$Q$8) -> 0 | T57: =S57*(1+PRESUPUESTO!$Q$8) -> 0 | U57: =T57*(1+PRESUPUESTO!$Q$8) -> 0 | V57: =U57*(1+PRESUPUESTO!$Q$8) -> 0
B58: GASTOS FINANCIEROS | F58: =SUM(F53:F57) -> 0 | G58: =SUM(G53:G57) -> 0 | H58: =SUM(H53:H57) -> 0 | I58: =SUM(I53:I57) -> 0 | J58: =SUM(J53:J57) -> 0 | K58: =SUM(K53:K57) -> 0 | L58: =SUM(L53:L57) -> 0 | M58: =SUM(M53:M57) -> 0 | ... V58: =SUM(V53:V57) -> 0 | X58: =F58/VENTAS!$H$34 -> #DIV/0! | Y58: =R58/VENTAS!$T$34 -> #DIV/0! | Z58: =F58/$F$60 -> #DIV/0! | AA58: =R58/$R$60 -> #DIV/0!
B60: TOTAL GASTOS | F60: =F58+F48+F38 -> 0 | G60: =G58+G48+G38 -> 0 | H60: =H58+H48+H38 -> 0 | I60: =I58+I48+I38 -> 0 | J60: =J58+J48+J38 -> 0 | K60: =K58+K48+K38 -> 0 | L60: =L58+L48+L38 -> 0 | M60: =M58+M48+M38 -> 0 | ... V60: =V58+V48+V38 -> 0

Sheet PRESUPUESTO
B7: DETALLE PRESUPUESTO | O7: Incremento Ventas Anual | Q7: 0.11 | R7: 0.15 | S7: 0.17 | T7: 0.18
O8: Inflación | Q8: 0.1
B10: INGRESOS | D10: Mes 1 | E10: Mes 2 | F10: Mes 3 | G10: Mes 4 | H10: Mes 5 | I10: Mes 6 | J10: Mes 7 | K10: Mes 8 | L10: Mes 9 | M10: Mes 10 | N10: Mes 11 | O10: Mes 12 | P10: AÑO 1 | Q10: AÑO 2 | R10: AÑO 3 | S10: AÑO 4 | T10: AÑO 5
B12: =VENTAS!B13 -> Producto 1 | D12: =VENTAS!H13 -> 0 | E12: =VENTAS!I13 -> 0 | F12: =VENTAS!J13 -> 0 | G12: =VENTAS!K13 -> 0 | H12: =VENTAS!L13 -> 0 | I12: =VENTAS!M13 -> 0 | J12: =VENTAS!N13 -> 0 | K12: =VENTAS!O13 -> 0 | ... O12: =VENTAS!S13 -> 0 | P12: =SUM(D12:O12) -> 0 | Q12: =P12*(1+Q$7) -> 0 | R12: =Q12*(1+R$7) -> 0 | S12: =R12*(1+S$7) -> 0 | T12: =S12*(1+T$7) -> 0
B13: =VENTAS!B14 -> Producto 2 | D13: =VENTAS!H14 -> 0 | E13: =VENTAS!I14 -> 0 | F13: =VENTAS!J14 -> 0 | G13: =VENTAS!K14 -> 0 | H13: =VENTAS!L14 -> 0 | I13: =VENTAS!M14 -> 0 | J13: =VENTAS!N14 -> 0 | K13: =VENTAS!O14 -> 0 | ... O13: =VENTAS!S14 -> 0 | P13: =SUM(D13:O13) -> 0 | Q13: =P13*(1+Q$7) -> 0 | R13: =Q13*(1+R$7) -> 0 | S13: =R13*(1+S$7) -> 0 | T13: =S13*(1+T$7) -> 0
B14: =VENTAS!B15 -> Producto 3 | D14: =VENTAS!H15 -> 0 | E14: =VENTAS!I15 -> 0 | F14: =VENTAS!J15 -> 0 | G14: =VENTAS!K15 -> 0 | H14: =VENTAS!L15 -> 0 | I14: =VENTAS!M15 -> 0 | J14: =VENTAS!N15 -> 0 | K14: =VENTAS!O15 -> 0 | ... O14: =VENTAS!S15 -> 0 | P14: =SUM(D14:O14) -> 0 | Q14: =P14*(1+Q$7) -> 0 | R14: =Q14*(1+R$7) -> 0 | S14: =R14*(1+S$7) -> 0 | T14: =S14*(1+T$7) -> 0
B15: =VENTAS!B16 -> Producto 4 | D15: =VENTAS!H16 -> 0 | E15: =VENTAS!I16 -> 0 | F15: =VENTAS!J16 -> 0 | G15: =VENTAS!K16 -> 0 | H15: =VENTAS!L16 -> 0 | I15: =VENTAS!M16 -> 0 | J15: =VENTAS!N16 -> 0 | K15: =VENTAS!O16 -> 0 | ... O15: =VENTAS!S16 -> 0 | P15: =SUM(D15:O15) -> 0 | Q15: =P15*(1+Q$7) -> 0 | R15: =Q15*(1+R$7) -> 0 | S15: =R15*(1+S$7) -> 0 | T15: =S15*(1+T$7) -> 0
B16: =VENTAS!B17 -> Producto 5 | D16: =VENTAS!H17 -> 0 | E16: =VENTAS!I17 -> 0 | F16: =VENTAS!J17 -> 0 | G16: =VENTAS!K17 -> 0 | H16: =VENTAS!L17 -> 0 | I16: =VENTAS!M17 -> 0 | J16: =VENTAS!N17 -> 0 | K16: =VENTAS!O17 -> 0 | ... O16: =VENTAS!S17 -> 0 | P16: =SUM(D16:O16) -> 0 | Q16: =P16*(1+Q$7) -> 0 | R16: =Q16*(1+R$7) -> 0 | S16: =R16*(1+S$7) -> 0 | T16: =S16*(1+T$7) -> 0
B17: =VENTAS!B18 -> Producto 6 | D17: =VENTAS!H18 -> 0 | E17: =VENTAS!I18 -> 0 | F17: =VENTAS!J18 -> 0 | G17: =VENTAS!K18 -> 0 | H17: =VENTAS!L18 -> 0 | I17: =VENTAS!M18 -> 0 | J17: =VENTAS!N18 -> 0 | K17: =VENTAS!O18 -> 0 | ... O17: =VENTAS!S18 -> 0 | P17: =SUM(D17:O17) -> 0 | Q17: =P17*(1+Q$7) -> 0 | R17: =Q17*(1+R$7) -> 0 | S17: =R17*(1+S$7) -> 0 | T17: =S17*(1+T$7) -> 0
B18: =VENTAS!B19 -> Producto 7 | D18: =VENTAS!H19 -> 0 | E18: =VENTAS!I19 -> 0 | F18: =VENTAS!J19 -> 0 | G18: =VENTAS!K19 -> 0 | H18: =VENTAS!L19 -> 0 | I18: =VENTAS!M19 -> 0 | J18: =VENTAS!N19 -> 0 | K18: =VENTAS!O19 -> 0 | ... O18: =VENTAS!S19 -> 0 | P18: =SUM(D18:O18) -> 0 | Q18: =P18*(1+Q$7) -> 0 | R18: =Q18*(1+R$7) -> 0 | S18: =R18*(1+S$7) -> 0 | T18: =S18*(1+T$7) -> 0
B19: =VENTAS!B20 -> Producto 8 | D19: =VENTAS!H20 -> 0 | E19: =VENTAS!I20 -> 0 | F19: =VENTAS!J20 -> 0 | G19: =VENTAS!K20 -> 0 | H19: =VENTAS!L20 -> 0 | I19: =VENTAS!M20 -> 0 | J19: =VENTAS!N20 -> 0 | K19: =VENTAS!O20 -> 0 | ... O19: =VENTAS!S20 -> 0 | P19: =SUM(D19:O19) -> 0 | Q19: =P19*(1+Q$7) -> 0 | R19: =Q19*(1+R$7) -> 0 | S19: =R19*(1+S$7) -> 0 | T19: =S19*(1+T$7) -> 0
B20: =VENTAS!B21 -> Producto 9 | D20: =VENTAS!H21 -> 0 | E20: =VENTAS!I21 -> 0 | F20: =VENTAS!J21 -> 0 | G20: =VENTAS!K21 -> 0 | H20: =VENTAS!L21 -> 0 | I20: =VENTAS!M21 -> 0 | J20: =VENTAS!N21 -> 0 | K20: =VENTAS!O21 -> 0 | ... O20: =VENTAS!S21 -> 0 | P20: =SUM(D20:O20) -> 0 | Q20: =P20*(1+Q$7) -> 0 | R20: =Q20*(1+R$7) -> 0 | S20: =R20*(1+S$7) -> 0 | T20: =S20*(1+T$7) -> 0
B21: =VENTAS!B22 -> Producto 10 | D21: =VENTAS!H22 -> 0 | E21: =VENTAS!I22 -> 0 | F21: =VENTAS!J22 -> 0 | G21: =VENTAS!K22 -> 0 | H21: =VENTAS!L22 -> 0 | I21: =VENTAS!M22 -> 0 | J21: =VENTAS!N22 -> 0 | K21: =VENTAS!O22 -> 0 | ... O21: =VENTAS!S22 -> 0 | P21: =SUM(D21:O21) -> 0 | Q21: =P21*(1+Q$7) -> 0 | R21: =Q21*(1+R$7) -> 0 | S21: =R21*(1+S$7) -> 0 | T21: =S21*(1+T$7) -> 0
B22: =VENTAS!B23 -> Producto 11 | D22: =VENTAS!H23 -> 0 | E22: =VENTAS!I23 -> 0 | F22: =VENTAS!J23 -> 0 | G22: =VENTAS!K23 -> 0 | H22: =VENTAS!L23 -> 0 | I22: =VENTAS!M23 -> 0 | J22: =VENTAS!N23 -> 0 | K22: =VENTAS!O23 -> 0 | ... O22: =VENTAS!S23 -> 0 | P22: =SUM(D22:O22) -> 0 | Q22: =P22*(1+Q$7) -> 0 | R22: =Q22*(1+R$7) -> 0 | S22: =R22*(1+S$7) -> 0 | T22: =S22*(1+T$7) -> 0
B23: =VENTAS!B24 -> Producto 12 | D23: =VENTAS!H24 -> 0 | E23: =VENTAS!I24 -> 0 | F23: =VENTAS!J24 -> 0 | G23: =VENTAS!K24 -> 0 | H23: =VENTAS!L24 -> 0 | I23: =VENTAS!M24 -> 0 | J23: =VENTAS!N24 -> 0 | K23: =VENTAS!O24 -> 0 | ... O23: =VENTAS!S24 -> 0 | P23: =SUM(D23:O23) -> 0 | Q23: =P23*(1+Q$7) -> 0 | R23: =Q23*(1+R$7) -> 0 | S23: =R23*(1+S$7) -> 0 | T23: =S23*(1+T$7) -> 0
... B31: =VENTAS!B32 -> Producto 20 | D31: =VENTAS!H32 -> 0 | E31: =VENTAS!I32 -> 0 | F31: =VENTAS!J32 -> 0 | G31: =VENTAS!K32 -> 0 | H31: =VENTAS!L32 -> 0 | I31: =VENTAS!M32 -> 0 | J31: =VENTAS!N32 -> 0 | K31: =VENTAS!O32 -> 0 | ... O31: =VENTAS!S32 -> 0 | P31: =SUM(D31:O31) -> 0 | Q31: =P31*(1+Q$7) -> 0 | R31: =Q31*(1+R$7) -> 0 | S31: =R31*(1+S$7) -> 0 | T31: =S31*(1+T$7) -> 0
B33: TOTAL VENTAS | D33: =SUM(D12:D31) -> 0 | E33: =SUM(E12:E31) -> 0 | F33: =SUM(F12:F31) -> 0 | G33: =SUM(G12:G31) -> 0 | H33: =SUM(H12:H31) -> 0 | I33: =SUM(I12:I31) -> 0 | J33: =SUM(J12:J31) -> 0 | K33: =SUM(K12:K31) -> 0 | ... T33: =SUM(T12:T31) -> 0
B35: Con tarjeta | D35: =VENTAS!H37 -> 0 | E35: =VENTAS!I37 -> 0 | F35: =VENTAS!J37 -> 0 | G35: =VENTAS!K37 -> 0 | H35: =VENTAS!L37 -> 0 | I35: =VENTAS!M37 -> 0 | J35: =VENTAS!N37 -> 0 | K35: =VENTAS!O37 -> 0 | ... T35: =VENTAS!X37 -> 0
B36: Efectivo | D36: =VENTAS!H38 -> 0 | E36: =VENTAS!I38 -> 0 | F36: =VENTAS!J38 -> 0 | G36: =VENTAS!K38 -> 0 | H36: =VENTAS!L38 -> 0 | I36: =VENTAS!M38 -> 0 | J36: =VENTAS!N38 -> 0 | K36: =VENTAS!O38 -> 0 | ... T36: =VENTAS!X38 -> 0
B38: TOTAL COSTO MERCADERIA | D38: =VENTAS!H41 -> 0 | E38: =VENTAS!I41 -> 0 | F38: =VENTAS!J41 -> 0 | G38: =VENTAS!K41 -> 0 | H38: =VENTAS!L41 -> 0 | I38: =VENTAS!M41 -> 0 | J38: =VENTAS!N41 -> 0 | K38: =VENTAS!O41 -> 0 | ... T38: =VENTAS!X41 -> 0
B40: UTILIDAD BRUTO EN VENTAS | D40: =+D33-D38 -> 0 | E40: =+E33-E38 -> 0 | F40: =+F33-F38 -> 0 | G40: =+G33-G38 -> 0 | H40: =+H33-H38 -> 0 | I40: =+I33-I38 -> 0 | J40: =+J33-J38 -> 0 | K40: =+K33-K38 -> 0 | ... T40: =+T33-T38 -> 0
B41: MARGEN BRUTO SOBRE VENTAS | D41: =D40/D33 -> #DIV/0! | E41: =E40/E33 -> #DIV/0! | F41: =F40/F33 -> #DIV/0! | G41: =G40/G33 -> #DIV/0! | H41: =H40/H33 -> #DIV/0! | I41: =I40/I33 -> #DIV/0! | J41: =J40/J33 -> #DIV/0! | K41: =K40/K33 -> #DIV/0! | ... T41: =T40/T33 -> #DIV/0!
B44: GASTOS | D44: Mes 1 | E44: Mes 2 | F44: Mes 3 | G44: Mes 4 | H44: Mes 5 | I44: Mes 6 | J44: Mes 7 | K44: Mes 8 | L44: Mes 9 | M44: Mes 10 | N44: Mes 11 | O44: Mes 12 | P44: AÑO 1 | Q44: AÑO 2 | R44: AÑO 3 | S44: AÑO 4 | T44: AÑO 5
B46: GASTOS ADMINISTRATIVOS | D46: =GASTOS!F38 -> 0 | E46: =GASTOS!G38 -> 0 | F46: =GASTOS!H38 -> 0 | G46: =GASTOS!I38 -> 0 | H46: =GASTOS!J38 -> 0 | I46: =GASTOS!K38 -> 0 | J46: =GASTOS!L38 -> 0 | K46: =GASTOS!M38 -> 0 | ... O46: =GASTOS!Q38 -> 0 | P46: =SUM(D46:O46) -> 0 | Q46: =INVERSION!Q38+GASTOS!S38 -> 0 | R46: =INVERSION!R38+GASTOS!T38 -> 0 | S46: =INVERSION!S38+GASTOS!U38 -> 0 | T46: =INVERSION!T38+GASTOS!V38 -> 0
B47: OTROS | D47: =GASTOS!F48 -> 0 | E47: =GASTOS!G48 -> 0 | F47: =GASTOS!H48 -> 0 | G47: =GASTOS!I48 -> 0 | H47: =GASTOS!J48 -> 0 | I47: =GASTOS!K48 -> 0 | J47: =GASTOS!L48 -> 0 | K47: =GASTOS!M48 -> 0 | ... O47: =GASTOS!Q48 -> 0 | P47: =SUM(D47:O47) -> 0 | Q47: =GASTOS!S48 -> 0 | R47: =GASTOS!T48 -> 0 | S47: =GASTOS!U48 -> 0 | T47: =GASTOS!V48 -> 0
B48: GASTOS FINANCIEROS Y OTROS | D48: =GASTOS!F58 -> 0 | E48: =GASTOS!G58 -> 0 | F48: =GASTOS!H58 -> 0 | G48: =GASTOS!I58 -> 0 | H48: =GASTOS!J58 -> 0 | I48: =GASTOS!K58 -> 0 | J48: =GASTOS!L58 -> 0 | K48: =GASTOS!M58 -> 0 | ... O48: =GASTOS!Q58 -> 0 | P48: =SUM(D48:O48) -> 0 | Q48: =GASTOS!S58 -> 0 | R48: =GASTOS!T58 -> 0 | S48: =GASTOS!U58 -> 0 | T48: =GASTOS!V58 -> 0
B50: TOTAL GASTOS | D50: =SUM(D46:D48) -> 0 | E50: =SUM(E46:E48) -> 0 | F50: =SUM(F46:F48) -> 0 | G50: =SUM(G46:G48) -> 0 | H50: =SUM(H46:H48) -> 0 | I50: =SUM(I46:I48) -> 0 | J50: =SUM(J46:J48) -> 0 | K50: =SUM(K46:K48) -> 0 | ... O50: =SUM(O46:O48) -> 0 | P50: =SUM(D50:O50) -> 0 | Q50: =SUM(Q46:Q48) -> 0 | R50: =SUM(R46:R48) -> 0 | S50: =SUM(S46:S48) -> 0 | T50: =SUM(T46:T48) -> 0
B52: UTILIDAD NETA ANTES DE IMPUESTOS | D52: =+D40-D50 -> 0 | E52: =+E40-E50 -> 0 | F52: =+F40-F50 -> 0 | G52: =+G40-G50 -> 0 | H52: =+H40-H50 -> 0 | I52: =+I40-I50 -> 0 | J52: =+J40-J50 -> 0 | K52: =+K40-K50 -> 0 | ... O52: =+O40-O50 -> 0 | P52: =SUM(D52:O52) -> 0 | Q52: =+Q40-Q50 -> 0 | R52: =+R40-R50 -> 0 | S52: =+S40-S50 -> 0 | T52: =+T40-T50 -> 0
B53: IMPUESTO SOBRE LA RENTA | D53: ='FLUJO DE CAJA'!F29 -> 0 | E53: ='FLUJO DE CAJA'!G29 -> 0 | F53: ='FLUJO DE CAJA'!H29 -> 0 | G53: ='FLUJO DE CAJA'!I29 -> 0 | H53: ='FLUJO DE CAJA'!J29 -> 0 | I53: ='FLUJO DE CAJA'!K29 -> 0 | J53: ='FLUJO DE CAJA'!L29 -> 0 | K53: ='FLUJO DE CAJA'!M29 -> 0 | ... O53: ='FLUJO DE CAJA'!Q29 -> 0 | P53: =SUM(D53:O53) -> 0 | Q53: =P53*(1+Q8) -> 0 | R53: =Q53*(1+R8) -> 0 | S53: =R53*(1+S8) -> 0 | T53: =S53*(1+T8) -> 0
B55: UTILIIDAD DESPUES DE IMPUESTOS | D55: =+D52-D53 -> 0 | E55: =+E52-E53 -> 0 | F55: =+F52-F53 -> 0 | G55: =+G52-G53 -> 0 | H55: =+H52-H53 -> 0 | I55: =+I52-I53 -> 0 | J55: =+J52-J53 -> 0 | K55: =+K52-K53 -> 0 | ... T55: =+T52-T53 -> 0
I56: .. | P56: =P55/P33 -> #DIV/0! | Q56: =Q55/Q33 -> #DIV/0! | R56: =R55/R33 -> #DIV/0! | S56: =S55/S33 -> #DIV/0! | T56: =T55/T33 -> #DIV/0!
B58: MARGEN BRUTO | D58: UB/VB | E58: =P40/P33 -> #DIV/0!
B59: MARGEN DE LA OPERACIÓN | D59: UO/VB | E59: =P52/P33 -> #DIV/0!
B60: MARGEN NETO | D60: UN/VB | E60: =P55/P33 -> #DIV/0!

Sheet FLUJO DE CAJA
B7: FLUJO DE CAJA
B9: INGRESOS | D9: Base | F9: Mes 1 | G9: Mes 2 | H9: Mes 3 | I9: Mes 4 | J9: Mes 5 | K9: Mes 6 | L9: Mes 7 | M9: Mes 8 | N9: Mes 9 | O9: Mes 10 | P9: Mes 11 | Q9: Mes 12 | R9: AÑO 1 | S9: AÑO 2 | T9: AÑO 3 | U9: AÑO 4 | V9: AÑO 5
B11: SALDO DE FLUJO INICIAL | F11: 0 | G11: =F35 -> 0 | H11: =G35 -> 0 | I11: =H35 -> 0 | J11: =I35 -> 0 | K11: =J35 -> 0 | L11: =K35 -> 0 | M11: =L35 -> 0 | N11: =M35 -> 0 | ... Q11: =P35 -> 0
B13: VENTAS NETAS | F13: =PRESUPUESTO!D33 -> 0 | G13: =PRESUPUESTO!E33 -> 0 | H13: =PRESUPUESTO!F33 -> 0 | I13: =PRESUPUESTO!G33 -> 0 | J13: =PRESUPUESTO!H33 -> 0 | K13: =PRESUPUESTO!I33 -> 0 | L13: =PRESUPUESTO!J33 -> 0 | M13: =PRESUPUESTO!K33 -> 0 | ... Q13: =PRESUPUESTO!O33 -> 0 | R13: =SUM(F13:Q13) -> 0 | S13: =PRESUPUESTO!Q33 -> 0 | T13: =PRESUPUESTO!R33 -> 0 | U13: =PRESUPUESTO!S33 -> 0 | V13: =PRESUPUESTO!T33 -> 0
B14: COMPRAS | F14: =PRESUPUESTO!D38 -> 0 | G14: =PRESUPUESTO!E38 -> 0 | H14: =PRESUPUESTO!F38 -> 0 | I14: =PRESUPUESTO!G38 -> 0 | J14: =PRESUPUESTO!H38 -> 0 | K14: =PRESUPUESTO!I38 -> 0 | L14: =PRESUPUESTO!J38 -> 0 | M14: =PRESUPUESTO!K38 -> 0 | ... Q14: =PRESUPUESTO!O38 -> 0 | R14: =SUM(F14:Q14) -> 0 | S14: =PRESUPUESTO!Q38 -> 0 | T14: =PRESUPUESTO!R38 -> 0 | U14: =PRESUPUESTO!S38 -> 0 | V14: =PRESUPUESTO!T38 -> 0
B16: FLUJO NETO OPERATIVO | F16: =F13-F14 -> 0 | G16: =G13-G14 -> 0 | H16: =H13-H14 -> 0 | I16: =I13-I14 -> 0 | J16: =J13-J14 -> 0 | K16: =K13-K14 -> 0 | L16: =L13-L14 -> 0 | M16: =M13-M14 -> 0 | ... V16: =V13-V14 -> 0
B20: EGRESOS | D20: Base | F20: Mes 1 | G20: Mes 2 | H20: Mes 3 | I20: Mes 4 | J20: Mes 5 | K20: Mes 6 | L20: Mes 7 | M20: Mes 8 | N20: Mes 9 | O20: Mes 10 | P20: Mes 11 | Q20: Mes 12 | R20: AÑO 1 | S20: AÑO 2 | T20: AÑO 3 | U20: AÑO 4 | V20: AÑO 5
B22: GASTOS ADMINISTRATIVOS | F22: =PRESUPUESTO!D46 -> 0 | G22: =PRESUPUESTO!E46 -> 0 | H22: =PRESUPUESTO!F46 -> 0 | I22: =PRESUPUESTO!G46 -> 0 | J22: =PRESUPUESTO!H46 -> 0 | K22: =PRESUPUESTO!I46 -> 0 | L22: =PRESUPUESTO!J46 -> 0 | M22: =PRESUPUESTO!K46 -> 0 | ... Q22: =PRESUPUESTO!O46 -> 0 | R22: =SUM(F22:Q22) -> 0 | S22: =PRESUPUESTO!Q46 -> 0 | T22: =PRESUPUESTO!R46 -> 0 | U22: =PRESUPUESTO!S46 -> 0 | V22: =PRESUPUESTO!T46 -> 0
B23: OTROS | F23: =PRESUPUESTO!D47 -> 0 | G23: =PRESUPUESTO!E47 -> 0 | H23: =PRESUPUESTO!F47 -> 0 | I23: =PRESUPUESTO!G47 -> 0 | J23: =PRESUPUESTO!H47 -> 0 | K23: =PRESUPUESTO!I47 -> 0 | L23: =PRESUPUESTO!J47 -> 0 | M23: =PRESUPUESTO!K47 -> 0 | ... Q23: =PRESUPUESTO!O47 -> 0 | R23: =SUM(F23:Q23) -> 0 | S23: =PRESUPUESTO!Q47 -> 0 | T23: =PRESUPUESTO!R47 -> 0 | U23: =PRESUPUESTO!S47 -> 0 | V23: =PRESUPUESTO!T47 -> 0
B24: GASTOS FINANCIEROS Y OTROS | F24: =PRESUPUESTO!D48 -> 0 | G24: =PRESUPUESTO!E48 -> 0 | H24: =PRESUPUESTO!F48 -> 0 | I24: =PRESUPUESTO!G48 -> 0 | J24: =PRESUPUESTO!H48 -> 0 | K24: =PRESUPUESTO!I48 -> 0 | L24: =PRESUPUESTO!J48 -> 0 | M24: =PRESUPUESTO!K48 -> 0 | ... Q24: =PRESUPUESTO!O48 -> 0 | R24: =SUM(F24:Q24) -> 0 | S24: =PRESUPUESTO!Q48 -> 0 | T24: =PRESUPUESTO!R48 -> 0 | U24: =PRESUPUESTO!S48 -> 0 | V24: =PRESUPUESTO!T48 -> 0
B25: TOTAL EGRESOS | F25: =SUM(F22:F24) -> 0 | G25: =SUM(G22:G24) -> 0 | H25: =SUM(H22:H24) -> 0 | I25: =SUM(I22:I24) -> 0 | J25: =SUM(J22:J24) -> 0 | K25: =SUM(K22:K24) -> 0 | L25: =SUM(L22:L24) -> 0 | M25: =SUM(M22:M24) -> 0 | ... V25: =SUM(V22:V24) -> 0
B27: UTILIDAD ANTES DE IMPUESTOS | F27: =F13-F14-F25 -> 0 | G27: =G16-G25 -> 0 | H27: =H16-H25 -> 0 | I27: =I16-I25 -> 0 | J27: =J16-J25 -> 0 | K27: =K16-K25 -> 0 | L27: =L16-L25 -> 0 | M27: =M16-M25 -> 0 | N27: =N16-N25 -> 0 | ... V27: =V16-V25 -> 0
B29: IMPUESTO S/RENTA | F29: =SUM(F47:F63) -> 0 | G29: =SUM(G47:G63) -> 0 | H29: =SUM(H47:H63) -> 0 | I29: =SUM(I47:I63) -> 0 | J29: =SUM(J47:J63) -> 0 | K29: =SUM(K47:K63) -> 0 | L29: =SUM(L47:L63) -> 0 | M29: =SUM(M47:M63) -> 0 | ... V29: =SUM(V47:V63) -> 0
B32: FLUJO NETO DESPUÉS DE IMPUESTOS | F32: =F27-F29 -> 0 | G32: =G27-G29 -> 0 | H32: =H27-H29 -> 0 | I32: =I27-I29 -> 0 | J32: =J27-J29 -> 0 | K32: =K27-K29 -> 0 | L32: =L27-L29 -> 0 | M32: =M27-M29 -> 0 | ... V32: =V27-V29 -> 0
B33: APORTES Y/O FINANC CAP TRAB | F33: 0 | G33: 0 | H33: 0 | I33: 0 | J33: 0 | K33: 0 | L33: 0 | M33: 0 | N33: 0 | O33: 0 | P33: 0 | Q33: 0 | R33: 0 | S33: 0 | T33: 0 | U33: 0 | V33: 0
B35: FLUJO ACUMULADOS | F35: =F11+F32+F33 -> 0 | G35: =G11+G32+G33 -> 0 | H35: =H11+H32+H33 -> 0 | I35: =I11+I32+I33 -> 0 | J35: =J11+J32+J33 -> 0 | K35: =K11+K32+K33 -> 0 | L35: =L11+L32+L33 -> 0 | M35: =M11+M32+M33 -> 0 | ... R35: =R11+R32+R33 -> 0 | S35: =S32+S33 -> 0 | T35: =T32+T33 -> 0 | U35: =U32+U33 -> 0 | V35: =V32+V33 -> 0
K36: ..
B45: Escalas Impuesto de Renta | F45: Mes 1 | G45: Mes 2 | H45: Mes 3 | I45: Mes 4 | J45: Mes 5 | K45: Mes 6 | L45: Mes 7 | M45: Mes 8 | N45: Mes 9 | O45: Mes 10 | P45: Mes 11 | Q45: Mes 12 | R45: AÑO 1 | S45: AÑO 2 | T45: AÑO 3 | U45: AÑO 4 | V45: AÑO 5
B46: Utilidades Escala 1 | C46: De | D46: 0
C47: A | D47: 3742000 | F47: =$R47/12 -> 0 | G47: =$R47/12 -> 0 | H47: =$R47/12 -> 0 | I47: =$R47/12 -> 0 | J47: =$R47/12 -> 0 | K47: =$R47/12 -> 0 | L47: =$R47/12 -> 0 | M47: =$R47/12 -> 0 | ... Q47: =$R47/12 -> 0 | R47: =IF(R$27<0,0,IF(AND(R$27>$D46,R$27<=$D47),R$27*$D48,IF(R$27>$D47,$D47*$D48))) -> FALSE | S47: =IF(S$27<0,0,IF(AND(S$27>$D46,S$27<=$D47),S$27*$D48,IF(S$27>$D47,$D47*$D48))) -> FALSE | T47: =IF(T$27<0,0,IF(AND(T$27>$D46,T$27<=$D47),T$27*$D48,IF(T$27>$D47,$D47*$D48))) -> FALSE | U47: =IF(U$27<0,0,IF(AND(U$27>$D46,U$27<=$D47),U$27*$D48,IF(U$27>$D47,$D47*$D48))) -> FALSE | V47: =IF(V$27<0,0,IF(AND(V$27>$D46,V$27<=$D47),V$27*$D48,IF(V$27>$D47,$D47*$D48))) -> FALSE
B48: Impuesto Renta Escala 1 | D48: 0
B50: Utilidades Escala 2 | C50: De | D50: =D47 -> 3742000
C51: A | D51: 5589000 | F51: =$R51/12 -> 0 | G51: =$R51/12 -> 0 | H51: =$R51/12 -> 0 | I51: =$R51/12 -> 0 | J51: =$R51/12 -> 0 | K51: =$R51/12 -> 0 | L51: =$R51/12 -> 0 | M51: =$R51/12 -> 0 | ... Q51: =$R51/12 -> 0 | R51: =IF(R$27<0,0,IF(AND(R$27>$D50,R$27<=$D51),(R$27-$D50)*$D52,IF(R$27>$D51,($D51-$D50)*$D52,0))) -> 0 | S51: =IF(S$27<0,0,IF(AND(S$27>$D50,S$27<=$D51),(S$27-$D50)*$D52,IF(S$27>$D51,($D51-$D50)*$D52,0))) -> 0 | T51: =IF(T$27<0,0,IF(AND(T$27>$D50,T$27<=$D51),(T$27-$D50)*$D52,IF(T$27>$D51,($D51-$D50)*$D52,0))) -> 0 | U51: =IF(U$27<0,0,IF(AND(U$27>$D50,U$27<=$D51),(U$27-$D50)*$D52,IF(U$27>$D51,($D51-$D50)*$D52,0))) -> 0 | V51: =IF(V$27<0,0,IF(AND(V$27>$D50,V$27<=$D51),(V$27-$D50)*$D52,IF(V$27>$D51,($D51-$D50)*$D52,0))) -> 0
B52: Impuesto Renta Escala 2 | D52: 0.1
B54: Utilidades Escala 3 | C54: De | D54: =D51 -> 5589000
C55: A | D55: 9322000 | F55: =$R55/12 -> 0 | G55: =$R55/12 -> 0 | H55: =$R55/12 -> 0 | I55: =$R55/12 -> 0 | J55: =$R55/12 -> 0 | K55: =$R55/12 -> 0 | L55: =$R55/12 -> 0 | M55: =$R55/12 -> 0 | ... Q55: =$R55/12 -> 0 | R55: =IF(R$27<0,0,IF(AND(R$27>$D54,R$27<=$D55),(R$27-$D54)*$D56,IF(R$27>$D55,($D55-$D54)*$D56,0))) -> 0 | S55: =IF(S$27<0,0,IF(AND(S$27>$D54,S$27<=$D55),(S$27-$D54)*$D56,IF(S$27>$D55,($D55-$D54)*$D56,0))) -> 0 | T55: =IF(T$27<0,0,IF(AND(T$27>$D54,T$27<=$D55),(T$27-$D54)*$D56,IF(T$27>$D55,($D55-$D54)*$D56,0))) -> 0 | U55: =IF(U$27<0,0,IF(AND(U$27>$D54,U$27<=$D55),(U$27-$D54)*$D56,IF(U$27>$D55,($D55-$D54)*$D56,0))) -> 0 | V55: =IF(V$27<0,0,IF(AND(V$27>$D54,V$27<=$D55),(V$27-$D54)*$D56,IF(V$27>$D55,($D55-$D54)*$D56,0))) -> 0
B56: Impuesto Renta Escala 3 | D56: 0.15
B58: Utilidades Escala 4 | C58: De | D58: =D55 -> 9322000
C59: A | D59: 18683000 | F59: =$R59/12 -> 0 | G59: =$R59/12 -> 0 | H59: =$R59/12 -> 0 | I59: =$R59/12 -> 0 | J59: =$R59/12 -> 0 | K59: =$R59/12 -> 0 | L59: =$R59/12 -> 0 | M59: =$R59/12 -> 0 | ... Q59: =$R59/12 -> 0 | R59: =IF(R$27<0,0,IF(AND(R$27>$D58,R$27<=$D59),(R$27-$D58)*$D60,IF(R$27>$D59,($D59-$D58)*$D60,0))) -> 0 | S59: =IF(S$27<0,0,IF(AND(S$27>$D58,S$27<=$D59),(S$27-$D58)*$D60,IF(S$27>$D59,($D59-$D58)*$D60,0))) -> 0 | T59: =IF(T$27<0,0,IF(AND(T$27>$D58,T$27<=$D59),(T$27-$D58)*$D60,IF(T$27>$D59,($D59-$D58)*$D60,0))) -> 0 | U59: =IF(U$27<0,0,IF(AND(U$27>$D58,U$27<=$D59),(U$27-$D58)*$D60,IF(U$27>$D59,($D59-$D58)*$D60,0))) -> 0 | V59: =IF(V$27<0,0,IF(AND(V$27>$D58,V$27<=$D59),(V$27-$D58)*$D60,IF(V$27>$D59,($D59-$D58)*$D60,0))) -> 0
B60: Impuesto Renta Escala 4 | D60: 0.2
B62: Utilidades Escala 5 | C62: De | D62: =D59 -> 18683000
C63: A | D63: 999999999 | F63: =$R63/12 -> 0 | G63: =$R63/12 -> 0 | H63: =$R63/12 -> 0 | I63: =$R63/12 -> 0 | J63: =$R63/12 -> 0 | K63: =$R63/12 -> 0 | L63: =$R63/12 -> 0 | M63: =$R63/12 -> 0 | ... Q63: =$R63/12 -> 0 | R63: =IF(R$27<0,0,IF(AND(R$27>$D62,R$27<=$D63),(R$27-$D62)*$D64,IF(R$27>$D63,($D63-$D62)*$D64,0))) -> 0 | S63: =IF(S$27<0,0,IF(AND(S$27>$D62,S$27<=$D63),(S$27-$D62)*$D64,IF(S$27>$D63,($D63-$D62)*$D64,0))) -> 0 | T63: =IF(T$27<0,0,IF(AND(T$27>$D62,T$27<=$D63),(T$27-$D62)*$D64,IF(T$27>$D63,($D63-$D62)*$D64,0))) -> 0 | U63: =IF(U$27<0,0,IF(AND(U$27>$D62,U$27<=$D63),(U$27-$D62)*$D64,IF(U$27>$D63,($D63-$D62)*$D64,0))) -> 0 | V63: =IF(V$27<0,0,IF(AND(V$27>$D62,V$27<=$D63),(V$27-$D62)*$D64,IF(V$27>$D63,($D63-$D62)*$D64,0))) -> 0
B64: Impuesto Renta Escala 5 | D64: 0.25
B67: PARA INFORMACION
B69: Escalas Impuesto de Renta | D69: FISICO | F69: JURIDICO
B70: Utilidades Escala 1 | C70: De | D70: 0 | F70: 0
C71: A | D71: 3742000 | F71: 5157000
B72: Impuesto Renta Escala 1 | D72: 0 | F72: 0.05
B74: Utilidades Escala 2 | C74: De | D74: =D71 -> 3742000 | F74: =F71 -> 5157000
C75: A | D75: 5589000 | F75: 7737000
...

Sheet CONCLUSIONES
B7: CONCLUSIONES
B9: RESUMEN ESTADO DE RESULTADOS | E9: Año 1 | F9: Año 2 | G9: Año 3 | H9: Año 4 | I9: Año 5
B11: VENTAS | E11: =PRESUPUESTO!P33 -> 0 | F11: =PRESUPUESTO!Q33 -> 0 | G11: =PRESUPUESTO!R33 -> 0 | H11: =PRESUPUESTO!S33 -> 0 | I11: =PRESUPUESTO!T33 -> 0
B12: COSTO DE VENTAS | E12: =PRESUPUESTO!P38 -> 0 | F12: =PRESUPUESTO!Q38 -> 0 | G12: =PRESUPUESTO!R38 -> 0 | H12: =PRESUPUESTO!S38 -> 0 | I12: =PRESUPUESTO!T38 -> 0
B13: UTILIDAD BRUTA | E13: =E11-E12 -> 0 | F13: =F11-F12 -> 0 | G13: =G11-G12 -> 0 | H13: =H11-H12 -> 0 | I13: =I11-I12 -> 0
B14: MARGEN BRUTO S/VENTAS | E14: =IFERROR(E13/E11,0) -> 0 | F14: =IFERROR(F13/F11,0) -> 0 | G14: =IFERROR(G13/G11,0) -> 0 | H14: =IFERROR(H13/H11,0) -> 0 | I14: =IFERROR(I13/I11,0) -> 0
B16: GASTOS ADMINISTRATIVOS | E16: =PRESUPUESTO!P46 -> 0 | F16: =PRESUPUESTO!Q46 -> 0 | G16: =PRESUPUESTO!R46 -> 0 | H16: =PRESUPUESTO!S46 -> 0 | I16: =PRESUPUESTO!T46 -> 0
B17: OTROS | E17: =PRESUPUESTO!P47 -> 0 | F17: =PRESUPUESTO!Q47 -> 0 | G17: =PRESUPUESTO!R47 -> 0 | H17: =PRESUPUESTO!S47 -> 0 | I17: =PRESUPUESTO!T47 -> 0
B18: GASTOS FINANCIEROS Y OTROS | E18: =PRESUPUESTO!P48 -> 0 | F18: =PRESUPUESTO!Q48 -> 0 | G18: =PRESUPUESTO!R48 -> 0 | H18: =PRESUPUESTO!S48 -> 0 | I18: =PRESUPUESTO!T48 -> 0
B19: TOTAL GASTOS | E19: =SUM(E16:E18) -> 0 | F19: =SUM(F16:F18) -> 0 | G19: =SUM(G16:G18) -> 0 | H19: =SUM(H16:H18) -> 0 | I19: =SUM(I16:I18) -> 0
B21: UTILIDAD DE LA OPERACIÓN | E21: =E13-E19 -> 0 | F21: =F13-F19 -> 0 | G21: =G13-G19 -> 0 | H21: =H13-H19 -> 0 | I21: =I13-I19 -> 0
B22: MARGEN OPERACIÓN | E22: =IFERROR(E21/E11,0) -> 0 | F22: =IFERROR(F21/F11,0) -> 0 | G22: =IFERROR(G21/G11,0) -> 0 | H22: =IFERROR(H21/H11,0) -> 0 | I22: =IFERROR(I21/I11,0) -> 0
B24: Impuesto sobre la renta | E24: ='FLUJO DE CAJA'!R29 -> 0 | F24: ='FLUJO DE CAJA'!S29 -> 0 | G24: ='FLUJO DE CAJA'!T29 -> 0 | H24: ='FLUJO DE CAJA'!U29 -> 0 | I24: ='FLUJO DE CAJA'!V29 -> 0
B26: UTILIDAD NETA DESPUES DE IMPUESTOS | E26: =E21-E24 -> 0 | F26: =F21-F24 -> 0 | G26: =G21-G24 -> 0 | H26: =H21-H24 -> 0 | I26: =I21-I24 -> 0
B27: MARGEN NETO DESPUÉS DE IMPUESTOS | E27: =IFERROR(E26/E11,0) -> 0 | F27: =IFERROR(F26/F11,0) -> 0 | G27: =IFERROR(G26/G11,0) -> 0 | H27: =IFERROR(H26/H11,0) -> 0 | I27: =IFERROR(I26/I11,0) -> 0
B32: DEPRECIACIÓN | D32: Año 0 | E32: Año 1 | F32: Año 2 | G32: Año 3 | H32: Año 4 | I32: Año 5 | J32: Vida Util | K32: Valor Final
B34: Depreciación Activos | E34: Meses | F34: Meses | G34: Meses | H34: Meses | I34: Meses
E35: 12 | F35: 12 | G35: 12 | H35: 12 | I35: 12
B36: =INVERSION!B11 -> * Remodelacion de la Unidad - Costo de obra civil | D36: =INVERSION!D11 -> 0 | E36: =($D36/$J36)*E35 -> 0 | F36: =($D36/$J36)*12 -> 0 | G36: =($D36/$J36)*12 -> 0 | H36: =($D36/$J36)*12 -> 0 | I36: =($D36/$J36)*12 -> 0 | J36: 60 | K36: =D36 -> 0
B37: =INVERSION!B12 -> * Inversion Mesa Trabajo - proyeccion | D37: =INVERSION!D12 -> 0 | E37: =($D37/$J37)*E35 -> 0 | F37: =($D37/$J37)*12 -> 0 | G37: =($D37/$J37)*12 -> 0 | H37: =($D37/$J37)*12 -> 0 | I37: =($D37/$J37)*12 -> 0 | J37: 60 | K37: =D37 -> 0
B38: =INVERSION!B13 -> * Inversion Mesa Fregadero proyeccion | D38: =INVERSION!D13 -> 0 | E38: =($D38/$J38)*E35 -> 0 | F38: =($D38/$J38)*12 -> 0 | G38: =($D38/$J38)*12 -> 0 | H38: =($D38/$J38)*12 -> 0 | I38: =($D38/$J38)*12 -> 0 | J38: 60 | K38: =D38 -> 0
B39: =INVERSION!B14 -> * Inversion Horno Electrico proyeccion | D39: =INVERSION!D14 -> 0 | E39: =($D39/$J39)*E35 -> 0 | F39: =($D39/$J39)*E35 -> 0 | G39: =($D39/$J39)*E35 -> 0 | H39: =($D39/$J39)*H35 -> 0 | I39: =($D39/$J39)*I35 -> 0 | J39: 60 | K39: =D39 -> 0
B40: =INVERSION!B15 -> * Inversion Urna Exhibidora proyeccion | D40: =INVERSION!D15 -> 0 | E40: =($D40/$J40)*E35 -> 0 | F40: =($D40/$J40)*F35 -> 0 | G40: =($D40/$J40)*G35 -> 0 | H40: =($D40/$J40)*H35 -> 0 | I40: =($D40/$J40)*I35 -> 0 | J40: 60 | K40: =D40 -> 0
